Workbook

Sheet Resultados Financeiros ->

Sheet Bridge Faturamento
A1: PY | D1: PY | G1: FY | I1: Budget | J1: Variação | K1: Variação
C2: Budget | F2: Budget | I2: Variação % | J2: =BASE!$AQ$3-1 | K2: M. Anterior
A3: Inicio 24 | B3: 0 | D3: Inicio 25 | E3: 0 | G3: Inicio 26 | H3: 0
A4: Jan | B4: =BASE!$E$3/1000 | C4: =B4*(1+BASE!$AQ$5) | D4: Jan | E4: ='Faturamento FY'!G5 | F4: =E4*(1+BASE!$AQ$4) | G4: Jan | H4: ='Faturamento FY'!G17 | I4: =IF(H4="","",IFERROR(H4/E4-1,"")) | J4: =IF(H4="","",H4-E4) | K4: =IF(H4="","",H4-E15)
A5: Fev | B5: =BASE!$E$4/1000 | C5: =B5*(1+BASE!$AQ$5) | D5: Fev | E5: ='Faturamento FY'!G6 | F5: =E5*(1+BASE!$AQ$4) | G5: Fev | H5: ='Faturamento FY'!G18 | I5: =IF(H5="","",IFERROR(H5/E5-1,"")) | J5: =IF(H5="","",H5-E5) | K5: =IF(H5="","",H5-H4)
A6: Mar | B6: =BASE!$E$5/1000 | C6: =B6*(1+BASE!$AQ$5) | D6: Mar | E6: ='Faturamento FY'!G7 | F6: =E6*(1+BASE!$AQ$4) | G6: Mar | H6: ='Faturamento FY'!G19 | I6: =IF(H6="","",IFERROR(H6/E6-1,"")) | J6: =IF(H6="","",H6-E6) | K6: =IF(H6="","",H6-H5)
A7: Abr | B7: =BASE!$E$6/1000 | C7: =B7*(1+BASE!$AQ$5) | D7: Abr | E7: ='Faturamento FY'!G8 | F7: =E7*(1+BASE!$AQ$4) | G7: Abr | H7: ='Faturamento FY'!G20 | I7: =IF(H7="","",IFERROR(H7/E7-1,"")) | J7: =IF(H7="","",H7-E7) | K7: =IF(H7="","",H7-H6)
A8: Mai | B8: =BASE!$E$7/1000 | C8: =B8*(1+BASE!$AQ$5) | D8: Mai | E8: ='Faturamento FY'!G9 | F8: =E8*(1+BASE!$AQ$4) | G8: Mai | H8: ='Faturamento FY'!G21 | I8: =IF(H8="","",IFERROR(H8/E8-1,"")) | J8: =IF(H8="","",H8-E8) | K8: =IF(H8="","",H8-H7)
A9: Jun | B9: =BASE!$E$8/1000 | C9: =B9*(1+BASE!$AQ$5) | D9: Jun | E9: ='Faturamento FY'!G10 | F9: =E9*(1+BASE!$AQ$4) | G9: Jun | H9: ='Faturamento FY'!G22 | I9: =IF(H9="","",IFERROR(H9/E9-1,"")) | J9: =IF(H9="","",H9-E9) | K9: =IF(H9="","",H9-H8)
A10: Jul | B10: =BASE!$E$9/1000 | C10: =B10*(1+BASE!$AQ$5) | D10: Jul | E10: ='Faturamento FY'!G11 | F10: =E10*(1+BASE!$AQ$4) | G10: Jul | H10: ='Faturamento FY'!G23 | I10: =IF(H10="","",IFERROR(H10/E10-1,"")) | J10: =IF(H10="","",H10-E10) | K10: =IF(H10="","",H10-H9)
A11: Ago | B11: =BASE!$E$10/1000 | C11: =B11*(1+BASE!$AQ$5) | D11: Ago | E11: ='Faturamento FY'!G12 | F11: =E11*(1+BASE!$AQ$4) | G11: Ago | H11: ='Faturamento FY'!G24 | I11: =IF(H11="","",IFERROR(H11/E11-1,"")) | J11: =IF(H11="","",H11-E11) | K11: =IF(H11="","",H11-H10)
A12: Set | B12: =BASE!$E$11/1000 | C12: =B12*(1+BASE!$AQ$5) | D12: Set | E12: ='Faturamento FY'!G13 | F12: =E12*(1+BASE!$AQ$4) | G12: Set | H12: ='Faturamento FY'!G25 | I12: =IF(H12="","",IFERROR(H12/E12-1,"")) | J12: =IF(H12="","",H12-E12) | K12: =IF(H12="","",H12-H11)
A13: Out | B13: =BASE!$E$12/1000 | C13: =B13*(1+BASE!$AQ$5) | D13: Out | E13: ='Faturamento FY'!G14 | F13: =E13*(1+BASE!$AQ$4) | G13: Out | H13: ='Faturamento FY'!G26 | I13: =IF(H13="","",IFERROR(H13/E13-1,"")) | J13: =IF(H13="","",H13-E13) | K13: =IF(H13="","",H13-H12)
A14: Nov | B14: =BASE!$E$13/1000 | C14: =B14*(1+BASE!$AQ$5) | D14: Nov | E14: ='Faturamento FY'!G15 | F14: =E14*(1+BASE!$AQ$4) | G14: Nov | H14: ='Faturamento FY'!G27 | I14: =IF(H14="","",IFERROR(H14/E14-1,"")) | J14: =IF(H14="","",H14-E14) | K14: =IF(H14="","",H14-H13)
A15: Dez | B15: =BASE!$E$14/1000 | C15: =B15*(1+BASE!$AQ$5) | D15: Dez | E15: ='Faturamento FY'!G16 | F15: =E15*(1+BASE!$AQ$4) | G15: Dez | H15: ='Faturamento FY'!G28 | I15: =IF(H15="","",IFERROR(H15/E15-1,"")) | J15: =IF(H15="","",H15-E15) | K15: =IF(H15="","",H15-H14)
A16: Total | B16: =SUM(B3:B15) | D16: Total (Presente) | E16: =SUM(E4:E15) | G16: Total (Presente) | H16: =SUM(H4:H15)
A17: Limite Fat. | B17: =BASE!$AQ$6/1000 | D17: Limite Fat. | E17: =BASE!$AQ$7/1000 | G17: Limite Fat. | H17: =BASE!$AQ$8/1000
E19: =E17-E16 | H19: =H17-H16

Sheet Confronto
B1: Confronto | C1: =BASE!$A$3 | D1: =BASE!$A$4 | E1: =BASE!$A$5 | F1: =BASE!$A$6 | G1: =BASE!$A$7 | H1: =BASE!$A$8 | I1: =BASE!$A$9 | J1: =BASE!$A$10 | K1: =BASE!$A$11 | L1: =BASE!$A$12 | M1: =BASE!$A$13 | N1: =BASE!$A$14 | P1: 1Q24 | Q1: 2Q24 | R1: 3Q24 | S1: 4Q24
B2: Receita 24 | C2: =IF(BASE!$B$3=1,BASE!$C$3/1000,"") | D2: =IF(BASE!$B$4=1,BASE!$C$4/1000,"") | E2: =IF(BASE!$B$5=1,BASE!$C$5/1000,"") | F2: =IF(BASE!$B$6=1,BASE!$C$6/1000,"") | G2: =IF(BASE!$B$7=1,BASE!$C$7/1000,"") | H2: =IF(BASE!$B$8=1,BASE!$C$8/1000,"") | I2: =IF(BASE!$B$9=1,BASE!$C$9/1000,"") | J2: =IF(BASE!$B$10=1,BASE!$C$10/1000,"") | K2: =IF(BASE!$B$11=1,BASE!$C$11/1000,"") | L2: =IF(BASE!$B$12=1,BASE!$C$12/1000,"") | M2: =IF(BASE!$B$13=1,BASE!$C$13/1000,"") | N2: =IF(BASE!$B$14=1,BASE!$C$14/1000,"") | P2: =SUM(C2:E2) | Q2: =SUM(F2:H2) | R2: =SUM(I2:K2) | S2: =SUM(L2:N2)
B3: Despesa 24 | C3: =IF(BASE!$B$3=1,-BASE!$D$3/1000,"") | D3: =IF(BASE!$B$4=1,-BASE!$D$4/1000,"") | E3: =IF(BASE!$B$5=1,-BASE!$D$5/1000,"") | F3: =IF(BASE!$B$6=1,-BASE!$D$6/1000,"") | G3: =IF(BASE!$B$7=1,-BASE!$D$7/1000,"") | H3: =IF(BASE!$B$8=1,-BASE!$D$8/1000,"") | I3: =IF(BASE!$B$9=1,-BASE!$D$9/1000,"") | J3: =IF(BASE!$B$10=1,-BASE!$D$10/1000,"") | K3: =IF(BASE!$B$11=1,-BASE!$D$11/1000,"") | L3: =IF(BASE!$B$12=1,-BASE!$D$12/1000,"") | M3: =IF(BASE!$B$13=1,-BASE!$D$13/1000,"") | N3: =IF(BASE!$B$14=1,-BASE!$D$14/1000,"") | P3: =SUM(C3:E3) | Q3: =SUM(F3:H3) | R3: =SUM(I3:K3) | S3: =SUM(L3:N3)
B4: RESULTADO 24 | C4: =IF(BASE!$B$3=1,SUM(C2,C3),"") | D4: =IF(BASE!$B$4=1,SUM(D2,D3),"") | E4: =IF(BASE!$B$5=1,SUM(E2,E3),"") | F4: =IF(BASE!$B$6=1,SUM(F2,F3),"") | G4: =IF(BASE!$B$7=1,SUM(G2,G3),"") | H4: =IF(BASE!$B$8=1,SUM(H2,H3),"") | I4: =IF(BASE!$B$9=1,SUM(I2,I3),"") | J4: =IF(BASE!$B$10=1,SUM(J2,J3),"") | K4: =IF(BASE!$B$11=1,SUM(K2,K3),"") | L4: =IF(BASE!$B$12=1,SUM(L2,L3),"") | M4: =IF(BASE!$B$13=1,SUM(M2,M3),"") | N4: =IF(BASE!$B$14=1,SUM(N2,N3),"") | P4: =SUM(C4:E4) | Q4: =SUM(F4:H4) | R4: =SUM(I4:K4) | S4: =SUM(L4:N4)
B6: Confronto | C6: =BASE!$A$15 | D6: =BASE!$A$16 | E6: =BASE!$A$17 | F6: =BASE!$A$18 | G6: =BASE!$A$19 | H6: =BASE!$A$20 | I6: =BASE!$A$21 | J6: =BASE!$A$22 | K6: =BASE!$A$23 | L6: =BASE!$A$24 | M6: =BASE!$A$25 | N6: =BASE!$A$26 | P6: 1Q25 | Q6: 2Q25 | R6: 3Q25 | S6: 4Q25
B7: Receita 25 | C7: =IF(BASE!$B$15=1,BASE!$C$15/1000,"") | D7: =IF(BASE!$B$16=1,BASE!$C$16/1000,"") | E7: =IF(BASE!$B$17=1,BASE!$C$17/1000,"") | F7: =IF(BASE!$B$18=1,BASE!$C$18/1000,"") | G7: =IF(BASE!$B$19=1,BASE!$C$19/1000,"") | H7: =IF(BASE!$B$20=1,BASE!$C$20/1000,"") | I7: =IF(BASE!$B$21=1,BASE!$C$21/1000,"") | J7: =IF(BASE!$B$22=1,BASE!$C$22/1000,"") | K7: =IF(BASE!$B$23=1,BASE!$C$23/1000,"") | L7: =IF(BASE!$B$24=1,BASE!$C$24/1000,"") | M7: =IF(BASE!$B$25=1,BASE!$C$25/1000,"") | N7: =IF(BASE!$B$26=1,BASE!$C$26/1000,"") | P7: =SUM(C7:E7) | Q7: =SUM(F7:H7) | R7: =SUM(I7:K7) | S7: =SUM(L7:N7)
B8: Despesa 25 | C8: =IF(BASE!$B$15=1,-BASE!$D$15/1000,"") | D8: =IF(BASE!$B$16=1,-BASE!$D$16/1000,"") | E8: =IF(BASE!$B$17=1,-BASE!$D$17/1000,"") | F8: =IF(BASE!$B$18=1,-BASE!$D$18/1000,"") | G8: =IF(BASE!$B$19=1,-BASE!$D$19/1000,"") | H8: =IF(BASE!$B$20=1,-BASE!$D$20/1000,"") | I8: =IF(BASE!$B$21=1,-BASE!$D$21/1000,"") | J8: =IF(BASE!$B$22=1,-BASE!$D$22/1000,"") | K8: =IF(BASE!$B$23=1,-BASE!$D$23/1000,"") | L8: =IF(BASE!$B$24=1,-BASE!$D$24/1000,"") | M8: =IF(BASE!$B$25=1,-BASE!$D$25/1000,"") | N8: =IF(BASE!$B$26=1,-BASE!$D$26/1000,"") | P8: =SUM(C8:E8) | Q8: =SUM(F8:H8) | R8: =SUM(I8:K8) | S8: =SUM(L8:N8)
B9: RESULTADO 25 | C9: =IF(BASE!$B$15=1,SUM(C7,C8),"") | D9: =IF(BASE!$B$16=1,SUM(D7,D8),"") | E9: =IF(BASE!$B$17=1,SUM(E7,E8),"") | F9: =IF(BASE!$B$18=1,SUM(F7,F8),"") | G9: =IF(BASE!$B$19=1,SUM(G7,G8),"") | H9: =IF(BASE!$B$20=1,SUM(H7,H8),"") | I9: =IF(BASE!$B$21=1,SUM(I7,I8),"") | J9: =IF(BASE!$B$22=1,SUM(J7,J8),"") | K9: =IF(BASE!$B$23=1,SUM(K7,K8),"") | L9: =IF(BASE!$B$24=1,SUM(L7,L8),"") | M9: =IF(BASE!$B$25=1,SUM(M7,M8),"") | N9: =IF(BASE!$B$26=1,SUM(N7,N8),"") | P9: =SUM(C9:E9) | Q9: =SUM(F9:H9) | R9: =SUM(I9:K9) | S9: =SUM(L9:N9)
B11: Confronto | C11: =BASE!$A$27 | D11: =BASE!$A$28 | E11: =BASE!$A$29 | F11: =BASE!$A$30 | G11: =BASE!$A$31 | H11: =BASE!$A$32 | I11: =BASE!$A$33 | J11: =BASE!$A$34 | K11: =BASE!$A$35 | L11: =BASE!$A$36 | M11: =BASE!$A$37 | N11: =BASE!$A$38 | P11: 1Q26 | Q11: 2Q26 | R11: 3Q26 | S11: 4Q26
B12: Receita 26 | C12: =IF(BASE!$B$27=1,BASE!$C$27/1000,"") | D12: =IF(BASE!$B$28=1,BASE!$C$28/1000,"") | E12: =IF(BASE!$B$29=1,BASE!$C$29/1000,"") | F12: =IF(BASE!$B$30=1,BASE!$C$30/1000,"") | G12: =IF(BASE!$B$31=1,BASE!$C$31/1000,"") | H12: =IF(BASE!$B$32=1,BASE!$C$32/1000,"") | I12: =IF(BASE!$B$33=1,BASE!$C$33/1000,"") | J12: =IF(BASE!$B$34=1,BASE!$C$34/1000,"") | K12: =IF(BASE!$B$35=1,BASE!$C$35/1000,"") | L12: =IF(BASE!$B$36=1,BASE!$C$36/1000,"") | M12: =IF(BASE!$B$37=1,BASE!$C$37/1000,"") | N12: =IF(BASE!$B$38=1,BASE!$C$38/1000,"") | P12: =SUM(C12:E12) | Q12: =SUM(F12:H12) | R12: =SUM(I12:K12) | S12: =SUM(L12:N12)
B13: Despesa 26 | C13: =IF(BASE!$B$27=1,-BASE!$D$27/1000,"") | D13: =IF(BASE!$B$28=1,-BASE!$D$28/1000,"") | E13: =IF(BASE!$B$29=1,-BASE!$D$29/1000,"") | F13: =IF(BASE!$B$30=1,-BASE!$D$30/1000,"") | G13: =IF(BASE!$B$31=1,-BASE!$D$31/1000,"") | H13: =IF(BASE!$B$32=1,-BASE!$D$32/1000,"") | I13: =IF(BASE!$B$33=1,-BASE!$D$33/1000,"") | J13: =IF(BASE!$B$34=1,-BASE!$D$34/1000,"") | K13: =IF(BASE!$B$35=1,-BASE!$D$35/1000,"") | L13: =IF(BASE!$B$36=1,-BASE!$D$36/1000,"") | M13: =IF(BASE!$B$37=1,-BASE!$D$37/1000,"") | N13: =IF(BASE!$B$38=1,-BASE!$D$38/1000,"") | P13: =SUM(C13:E13) | Q13: =SUM(F13:H13) | R13: =SUM(I13:K13) | S13: =SUM(L13:N13)
B14: RESULTADO 26 | C14: =IF(BASE!$B$27=1,SUM(C12,C13),"") | D14: =IF(BASE!$B$28=1,SUM(D12,D13),"") | E14: =IF(BASE!$B$29=1,SUM(E12,E13),"") | F14: =IF(BASE!$B$30=1,SUM(F12,F13),"") | G14: =IF(BASE!$B$31=1,SUM(G12,G13),"") | H14: =IF(BASE!$B$32=1,SUM(H12,H13),"") | I14: =IF(BASE!$B$33=1,SUM(I12,I13),"") | J14: =IF(BASE!$B$34=1,SUM(J12,J13),"") | K14: =IF(BASE!$B$35=1,SUM(K12,K13),"") | L14: =IF(BASE!$B$36=1,SUM(L12,L13),"") | M14: =IF(BASE!$B$37=1,SUM(M12,M13),"") | N14: =IF(BASE!$B$38=1,SUM(N12,N13),"") | P14: =SUM(C14:E14) | Q14: =SUM(F14:H14) | R14: =SUM(I14:K14) | S14: =SUM(L14:N14)

Sheet Caixa Livre
B1: 1000000 | K1: Variação
G2: Caixa - Atual | K2: Caixa Livre
D3: Mês | E3: Ano | F3: Data | G3: Disponivel | H3: Bloqueado | I3: Total Inicial | J3: Total Final
C4: =EOMONTH(BASE!$A$14,0) | D4: =VLOOKUP(MONTH(C4),$AE$16:$AF$27,2,0) | E4: =YEAR(C4) | F4: =EOMONTH(BASE!$A$14,0) | G4: =IF(BASE!$B$14=1,J4-H4,"") | H4: =IF(BASE!$B$14=1,BASE!$F$14/1000,"") | I4: =Receita!M3 | J4: =Receita!N3 | L4: =IF(BASE!$B$14=1,J4-I4,"")
C5: =EOMONTH(BASE!$A$15,0) | D5: =VLOOKUP(MONTH(C5),$AE$16:$AF$27,2,0) | E5: =YEAR(C5) | F5: =EOMONTH(BASE!$A$15,0) | G5: =IF(BASE!$B$15=1,J5-H5,"") | H5: =IF(BASE!$B$15=1,BASE!$F$15/1000,"") | I5: =IF(BASE!$B$15=1,J4,"") | J5: =Receita!C8 | L5: =IF(BASE!$B$15=1,J5-I5,"")
C6: =EOMONTH(BASE!$A$16,0) | D6: =VLOOKUP(MONTH(C6),$AE$16:$AF$27,2,0) | E6: =YEAR(C6) | F6: =EOMONTH(BASE!$A$16,0) | G6: =IF(BASE!$B$16=1,J6-H6,"") | H6: =IF(BASE!$B$16=1,BASE!$F$16/1000,"") | I6: =IF(BASE!$B$16=1,J5,"") | J6: =Receita!D8 | L6: =IF(BASE!$B$16=1,J6-I6,"")
C7: =EOMONTH(BASE!$A$17,0) | D7: =VLOOKUP(MONTH(C7),$AE$16:$AF$27,2,0) | E7: =YEAR(C7) | F7: =EOMONTH(BASE!$A$17,0) | G7: =IF(BASE!$B$17=1,J7-H7,"") | H7: =IF(BASE!$B$17=1,BASE!$F$17/1000,"") | I7: =IF(BASE!$B$17=1,J6,"") | J7: =Receita!E8 | L7: =IF(BASE!$B$17=1,J7-I7,"")
C8: =EOMONTH(BASE!$A$18,0) | D8: =VLOOKUP(MONTH(C8),$AE$16:$AF$27,2,0) | E8: =YEAR(C8) | F8: =EOMONTH(BASE!$A$18,0) | G8: =IF(BASE!$B$18=1,J8-H8,"") | H8: =IF(BASE!$B$18=1,BASE!$F$18/1000,"") | I8: =IF(BASE!$B$18=1,J7,"") | J8: =Receita!F8 | L8: =IF(BASE!$B$18=1,J8-I8,"")
C9: =EOMONTH(BASE!$A$19,0) | D9: =VLOOKUP(MONTH(C9),$AE$16:$AF$27,2,0) | E9: =YEAR(C9) | F9: =EOMONTH(BASE!$A$19,0) | G9: =IF(BASE!$B$19=1,J9-H9,"") | H9: =IF(BASE!$B$19=1,BASE!$F$19/1000,"") | I9: =IF(BASE!$B$19=1,J8,"") | J9: =Receita!G8 | L9: =IF(BASE!$B$19=1,J9-I9,"")
C10: =EOMONTH(BASE!$A$20,0) | D10: =VLOOKUP(MONTH(C10),$AE$16:$AF$27,2,0) | E10: =YEAR(C10) | F10: =EOMONTH(BASE!$A$20,0) | G10: =IF(BASE!$B$20=1,J10-H10,"") | H10: =IF(BASE!$B$20=1,BASE!$F$20/1000,"") | I10: =IF(BASE!$B$20=1,J9,"") | J10: =Receita!H8 | L10: =IF(BASE!$B$20=1,J10-I10,"")
C11: =EOMONTH(BASE!$A$21,0) | D11: =VLOOKUP(MONTH(C11),$AE$16:$AF$27,2,0) | E11: =YEAR(C11) | F11: =EOMONTH(BASE!$A$21,0) | G11: =IF(BASE!$B$21=1,J11-H11,"") | H11: =IF(BASE!$B$21=1,BASE!$F$21/1000,"") | I11: =IF(BASE!$B$21=1,J10,"") | J11: =Receita!I8 | L11: =IF(BASE!$B$21=1,J11-I11,"")
C12: =EOMONTH(BASE!$A$22,0) | D12: =VLOOKUP(MONTH(C12),$AE$16:$AF$27,2,0) | E12: =YEAR(C12) | F12: =EOMONTH(BASE!$A$22,0) | G12: =IF(BASE!$B$22=1,J12-H12,"") | H12: =IF(BASE!$B$22=1,BASE!$F$22/1000,"") | I12: =IF(BASE!$B$22=1,J11,"") | J12: =Receita!J8 | L12: =IF(BASE!$B$22=1,J12-I12,"")
C13: =EOMONTH(BASE!$A$23,0) | D13: =VLOOKUP(MONTH(C13),$AE$16:$AF$27,2,0) | E13: =YEAR(C13) | F13: =EOMONTH(BASE!$A$23,0) | G13: =IF(BASE!$B$23=1,J13-H13,"") | H13: =IF(BASE!$B$23=1,BASE!$F$23/1000,"") | I13: =IF(BASE!$B$23=1,J12,"") | J13: =Receita!K8 | L13: =IF(BASE!$B$23=1,J13-I13,"")
C14: =EOMONTH(BASE!$A$24,0) | D14: =VLOOKUP(MONTH(C14),$AE$16:$AF$27,2,0) | E14: =YEAR(C14) | F14: =EOMONTH(BASE!$A$24,0) | G14: =IF(BASE!$B$24=1,J14-H14,"") | H14: =IF(BASE!$B$24=1,BASE!$F$24/1000,"") | I14: =IF(BASE!$B$24=1,J13,"") | J14: =Receita!L8 | L14: =IF(BASE!$B$24=1,J14-I14,"")
C15: =EOMONTH(BASE!$A$25,0) | D15: =VLOOKUP(MONTH(C15),$AE$16:$AF$27,2,0) | E15: =YEAR(C15) | F15: =EOMONTH(BASE!$A$25,0) | G15: =IF(BASE!$B$25=1,J15-H15,"") | H15: =IF(BASE!$B$25=1,BASE!$F$25/1000,"") | I15: =IF(BASE!$B$25=1,J14,"") | J15: =Receita!M8 | L15: =IF(BASE!$B$25=1,J15-I15,"")
C16: =EOMONTH(BASE!$A$26,0) | D16: =VLOOKUP(MONTH(C16),$AE$16:$AF$27,2,0) | E16: =YEAR(C16) | F16: =EOMONTH(BASE!$A$26,0) | G16: =IF(BASE!$B$26=1,J16-H16,"") | H16: =IF(BASE!$B$26=1,BASE!$F$26/1000,"") | I16: =IF(BASE!$B$26=1,J15,"") | J16: =Receita!N8 | L16: =IF(BASE!$B$26=1,J16-I16,"") | AE16: 1 | AF16: Jan
C17: =EOMONTH(BASE!$A$27,0) | D17: =VLOOKUP(MONTH(C17),$AE$16:$AF$27,2,0) | E17: =YEAR(C17) | F17: =EOMONTH(BASE!$A$27,0) | G17: =IF(BASE!$B$27=1,J17-H17,"") | H17: =IF(BASE!$B$27=1,BASE!$F$27/1000,"") | I17: =IF(BASE!$B$27=1,J16,"") | J17: =Receita!C13 | L17: =IF(BASE!$B$27=1,J17-I17,"") | AE17: =1+AE16 | AF17: Fev
C18: =EOMONTH(BASE!$A$28,0) | D18: =VLOOKUP(MONTH(C18),$AE$16:$AF$27,2,0) | E18: =YEAR(C18) | F18: =EOMONTH(BASE!$A$28,0) | G18: =IF(BASE!$B$28=1,J18-H18,"") | H18: =IF(BASE!$B$28=1,BASE!$F$28/1000,"") | I18: =IF(BASE!$B$28=1,J17,"") | J18: =Receita!D13 | L18: =IF(BASE!$B$28=1,J18-I18,"") | AE18: =1+AE17 | AF18: Mar
C19: =EOMONTH(BASE!$A$29,0) | D19: =VLOOKUP(MONTH(C19),$AE$16:$AF$27,2,0) | E19: =YEAR(C19) | F19: =EOMONTH(BASE!$A$29,0) | G19: =IF(BASE!$B$29=1,J19-H19,"") | H19: =IF(BASE!$B$29=1,BASE!$F$29/1000,"") | I19: =IF(BASE!$B$29=1,J18,"") | J19: =Receita!E13 | L19: =IF(BASE!$B$29=1,J19-I19,"") | AE19: =1+AE18 | AF19: Abr
C20: =EOMONTH(BASE!$A$30,0) | D20: =VLOOKUP(MONTH(C20),$AE$16:$AF$27,2,0) | E20: =YEAR(C20) | F20: =EOMONTH(BASE!$A$30,0) | G20: =IF(BASE!$B$30=1,J20-H20,"") | H20: =IF(BASE!$B$30=1,BASE!$F$30/1000,"") | I20: =IF(BASE!$B$30=1,J19,"") | J20: =Receita!F13 | L20: =IF(BASE!$B$30=1,J20-I20,"") | AE20: =1+AE19 | AF20: Mai
C21: =EOMONTH(BASE!$A$31,0) | D21: =VLOOKUP(MONTH(C21),$AE$16:$AF$27,2,0) | E21: =YEAR(C21) | F21: =EOMONTH(BASE!$A$31,0) | G21: =IF(BASE!$B$31=1,J21-H21,"") | H21: =IF(BASE!$B$31=1,BASE!$F$31/1000,"") | I21: =IF(BASE!$B$31=1,J20,"") | J21: =Receita!G13 | L21: =IF(BASE!$B$31=1,J21-I21,"") | AE21: =1+AE20 | AF21: Jun
C22: =EOMONTH(BASE!$A$32,0) | D22: =VLOOKUP(MONTH(C22),$AE$16:$AF$27,2,0) | E22: =YEAR(C22) | F22: =EOMONTH(BASE!$A$32,0) | G22: =IF(BASE!$B$32=1,J22-H22,"") | H22: =IF(BASE!$B$32=1,BASE!$F$32/1000,"") | I22: =IF(BASE!$B$32=1,J21,"") | J22: =Receita!H13 | L22: =IF(BASE!$B$32=1,J22-I22,"") | AE22: =1+AE21 | AF22: Jul
C23: =EOMONTH(BASE!$A$33,0) | D23: =VLOOKUP(MONTH(C23),$AE$16:$AF$27,2,0) | E23: =YEAR(C23) | F23: =EOMONTH(BASE!$A$33,0) | G23: =IF(BASE!$B$33=1,J23-H23,"") | H23: =IF(BASE!$B$33=1,BASE!$F$33/1000,"") | I23: =IF(BASE!$B$33=1,J22,"") | J23: =Receita!I13 | L23: =IF(BASE!$B$33=1,J23-I23,"") | AE23: =1+AE22 | AF23: Ago
C24: =EOMONTH(BASE!$A$34,0) | D24: =VLOOKUP(MONTH(C24),$AE$16:$AF$27,2,0) | E24: =YEAR(C24) | F24: =EOMONTH(BASE!$A$34,0) | G24: =IF(BASE!$B$34=1,J24-H24,"") | H24: =IF(BASE!$B$34=1,BASE!$F$34/1000,"") | I24: =IF(BASE!$B$34=1,J23,"") | J24: =Receita!J13 | L24: =IF(BASE!$B$34=1,J24-I24,"") | AE24: =1+AE23 | AF24: Set
C25: =EOMONTH(BASE!$A$35,0) | D25: =VLOOKUP(MONTH(C25),$AE$16:$AF$27,2,0) | E25: =YEAR(C25) | F25: =EOMONTH(BASE!$A$35,0) | G25: =IF(BASE!$B$35=1,J25-H25,"") | H25: =IF(BASE!$B$35=1,BASE!$F$35/1000,"") | I25: =IF(BASE!$B$35=1,J24,"") | J25: =Receita!K13 | L25: =IF(BASE!$B$35=1,J25-I25,"") | AE25: =1+AE24 | AF25: Out
C26: =EOMONTH(BASE!$A$36,0) | D26: =VLOOKUP(MONTH(C26),$AE$16:$AF$27,2,0) | E26: =YEAR(C26) | F26: =EOMONTH(BASE!$A$36,0) | G26: =IF(BASE!$B$36=1,J26-H26,"") | H26: =IF(BASE!$B$36=1,BASE!$F$36/1000,"") | I26: =IF(BASE!$B$36=1,J25,"") | J26: =Receita!L13 | L26: =IF(BASE!$B$36=1,J26-I26,"") | AE26: =1+AE25 | AF26: Nov
C27: =EOMONTH(BASE!$A$37,0) | D27: =VLOOKUP(MONTH(C27),$AE$16:$AF$27,2,0) | E27: =YEAR(C27) | F27: =EOMONTH(BASE!$A$37,0) | G27: =IF(BASE!$B$37=1,J27-H27,"") | H27: =IF(BASE!$B$37=1,BASE!$F$37/1000,"") | I27: =IF(BASE!$B$37=1,J26,"") | J27: =Receita!M13 | L27: =IF(BASE!$B$37=1,J27-I27,"") | AE27: =1+AE26 | AF27: Dez
C28: =EOMONTH(BASE!$A$38,0) | D28: =VLOOKUP(MONTH(C28),$AE$16:$AF$27,2,0) | E28: =YEAR(C28) | F28: =EOMONTH(BASE!$A$38,0) | G28: =IF(BASE!$B$38=1,J28-H28,"") | H28: =IF(BASE!$B$38=1,BASE!$F$38/1000,"") | I28: =IF(BASE!$B$38=1,J27,"") | J28: =Receita!N13 | L28: =IF(BASE!$B$38=1,J28-I28,"")

Sheet Receita
B1: Total | C1: =BASE!$A$3 | D1: =BASE!$A$4 | E1: =BASE!$A$5 | F1: =BASE!$A$6 | G1: =BASE!$A$7 | H1: =BASE!$A$8 | I1: =BASE!$A$9 | J1: =BASE!$A$10 | K1: =BASE!$A$11 | L1: =BASE!$A$12 | M1: =BASE!$A$13 | N1: =BASE!$A$14
B2: Receita 24 | C2: =Confronto!C2 | D2: =Confronto!D2 | E2: =Confronto!E2 | F2: =Confronto!F2 | G2: =Confronto!G2 | H2: =Confronto!H2 | I2: =Confronto!I2 | J2: =Confronto!J2 | ... N2: =Confronto!N2
B3: Caixa 24 | C3: =IF(BASE!$B$3=1,BASE!$AQ$9/1000+SUM(Confronto!$C$4:C4)+SUM(BASE!$AO$3:$AO$3)/1000,"") | D3: =IF(BASE!$B$4=1,BASE!$AQ$9/1000+SUM(Confronto!$C$4:D4)+SUM(BASE!$AO$3:$AO$4)/1000,"") | E3: =IF(BASE!$B$5=1,BASE!$AQ$9/1000+SUM(Confronto!$C$4:E4)+SUM(BASE!$AO$3:$AO$5)/1000,"") | F3: =IF(BASE!$B$6=1,BASE!$AQ$9/1000+SUM(Confronto!$C$4:F4)+SUM(BASE!$AO$3:$AO$6)/1000,"") | G3: =IF(BASE!$B$7=1,BASE!$AQ$9/1000+SUM(Confronto!$C$4:G4)+SUM(BASE!$AO$3:$AO$7)/1000,"") | H3: =IF(BASE!$B$8=1,BASE!$AQ$9/1000+SUM(Confronto!$C$4:H4)+SUM(BASE!$AO$3:$AO$8)/1000,"") | I3: =IF(BASE!$B$9=1,BASE!$AQ$9/1000+SUM(Confronto!$C$4:I4)+SUM(BASE!$AO$3:$AO$9)/1000,"") | J3: =IF(BASE!$B$10=1,BASE!$AQ$9/1000+SUM(Confronto!$C$4:J4)+SUM(BASE!$AO$3:$AO$10)/1000,"") | K3: =IF(BASE!$B$11=1,BASE!$AQ$9/1000+SUM(Confronto!$C$4:K4)+SUM(BASE!$AO$3:$AO$11)/1000,"") | L3: =IF(BASE!$B$12=1,BASE!$AQ$9/1000+SUM(Confronto!$C$4:L4)+SUM(BASE!$AO$3:$AO$12)/1000,"") | M3: =IF(BASE!$B$13=1,BASE!$AQ$9/1000+SUM(Confronto!$C$4:M4)+SUM(BASE!$AO$3:$AO$13)/1000,"") | N3: =IF(BASE!$B$14=1,BASE!$AQ$9/1000+SUM(Confronto!$C$4:N4)+SUM(BASE!$AO$3:$AO$14)/1000,"")
B4: Var. Caixa | C4: =IF(BASE!$B$3=1,C3-BASE!$AQ$9/1000,"") | D4: =IF(BASE!$B$4=1,D3-C3,"") | E4: =IF(BASE!$B$5=1,E3-D3,"") | F4: =IF(BASE!$B$6=1,F3-E3,"") | G4: =IF(BASE!$B$7=1,G3-F3,"") | H4: =IF(BASE!$B$8=1,H3-G3,"") | I4: =IF(BASE!$B$9=1,I3-H3,"") | J4: =IF(BASE!$B$10=1,J3-I3,"") | K4: =IF(BASE!$B$11=1,K3-J3,"") | L4: =IF(BASE!$B$12=1,L3-K3,"") | M4: =IF(BASE!$B$13=1,M3-L3,"") | N4: =IF(BASE!$B$14=1,N3-M3,"")
B6: Total | C6: =BASE!$A$15 | D6: =BASE!$A$16 | E6: =BASE!$A$17 | F6: =BASE!$A$18 | G6: =BASE!$A$19 | H6: =BASE!$A$20 | I6: =BASE!$A$21 | J6: =BASE!$A$22 | K6: =BASE!$A$23 | L6: =BASE!$A$24 | M6: =BASE!$A$25 | N6: =BASE!$A$26
B7: Receita 25 | C7: =Confronto!C7 | D7: =Confronto!D7 | E7: =Confronto!E7 | F7: =Confronto!F7 | G7: =Confronto!G7 | H7: =Confronto!H7 | I7: =Confronto!I7 | J7: =Confronto!J7 | ... N7: =Confronto!N7
B8: Caixa 25 | C8: =IF(BASE!$B$15=1,BASE!$AQ$9/1000+SUM(Confronto!$C$4:$N$4,Confronto!$C$9:C9)+SUM(BASE!$AO$3:$AO$15)/1000,"") | D8: =IF(BASE!$B$16=1,BASE!$AQ$9/1000+SUM(Confronto!$C$4:$N$4,Confronto!$C$9:D9)+SUM(BASE!$AO$3:$AO$16)/1000,"") | E8: =IF(BASE!$B$17=1,BASE!$AQ$9/1000+SUM(Confronto!$C$4:$N$4,Confronto!$C$9:E9)+SUM(BASE!$AO$3:$AO$17)/1000,"") | F8: =IF(BASE!$B$18=1,BASE!$AQ$9/1000+SUM(Confronto!$C$4:$N$4,Confronto!$C$9:F9)+SUM(BASE!$AO$3:$AO$18)/1000,"") | G8: =IF(BASE!$B$19=1,BASE!$AQ$9/1000+SUM(Confronto!$C$4:$N$4,Confronto!$C$9:G9)+SUM(BASE!$AO$3:$AO$19)/1000,"") | H8: =IF(BASE!$B$20=1,BASE!$AQ$9/1000+SUM(Confronto!$C$4:$N$4,Confronto!$C$9:H9)+SUM(BASE!$AO$3:$AO$20)/1000,"") | I8: =IF(BASE!$B$21=1,BASE!$AQ$9/1000+SUM(Confronto!$C$4:$N$4,Confronto!$C$9:I9)+SUM(BASE!$AO$3:$AO$21)/1000,"") | J8: =IF(BASE!$B$22=1,BASE!$AQ$9/1000+SUM(Confronto!$C$4:$N$4,Confronto!$C$9:J9)+SUM(BASE!$AO$3:$AO$22)/1000,"") | K8: =IF(BASE!$B$23=1,BASE!$AQ$9/1000+SUM(Confronto!$C$4:$N$4,Confronto!$C$9:K9)+SUM(BASE!$AO$3:$AO$23)/1000,"") | L8: =IF(BASE!$B$24=1,BASE!$AQ$9/1000+SUM(Confronto!$C$4:$N$4,Confronto!$C$9:L9)+SUM(BASE!$AO$3:$AO$24)/1000,"") | M8: =IF(BASE!$B$25=1,BASE!$AQ$9/1000+SUM(Confronto!$C$4:$N$4,Confronto!$C$9:M9)+SUM(BASE!$AO$3:$AO$25)/1000,"") | N8: =IF(BASE!$B$26=1,BASE!$AQ$9/1000+SUM(Confronto!$C$4:$N$4,Confronto!$C$9:N9)+SUM(BASE!$AO$3:$AO$26)/1000,"")
B9: Var. Caixa | C9: =IF(BASE!$B$15=1,C8-N3,"") | D9: =IF(BASE!$B$16=1,D8-C8,"") | E9: =IF(BASE!$B$17=1,E8-D8,"") | F9: =IF(BASE!$B$18=1,F8-E8,"") | G9: =IF(BASE!$B$19=1,G8-F8,"") | H9: =IF(BASE!$B$20=1,H8-G8,"") | I9: =IF(BASE!$B$21=1,I8-H8,"") | J9: =IF(BASE!$B$22=1,J8-I8,"") | K9: =IF(BASE!$B$23=1,K8-J8,"") | L9: =IF(BASE!$B$24=1,L8-K8,"") | M9: =IF(BASE!$B$25=1,M8-L8,"") | N9: =IF(BASE!$B$26=1,N8-M8,"")
B11: Total | C11: =BASE!$A$27 | D11: =BASE!$A$28 | E11: =BASE!$A$29 | F11: =BASE!$A$30 | G11: =BASE!$A$31 | H11: =BASE!$A$32 | I11: =BASE!$A$33 | J11: =BASE!$A$34 | K11: =BASE!$A$35 | L11: =BASE!$A$36 | M11: =BASE!$A$37 | N11: =BASE!$A$38
B12: Receita 26 | C12: =Confronto!C12 | D12: =Confronto!D12 | E12: =Confronto!E12 | F12: =Confronto!F12 | G12: =Confronto!G12 | H12: =Confronto!H12 | I12: =Confronto!I12 | J12: =Confronto!J12 | ... N12: =Confronto!N12
B13: Caixa 26 | C13: =IF(BASE!$B$27=1,BASE!$AQ$9/1000+SUM(Confronto!$C$4:$N$4,Confronto!$C$9:$N$9,Confronto!$C$14:C14)+SUM(BASE!$AO$3:$AO$27)/1000,"") | D13: =IF(BASE!$B$28=1,BASE!$AQ$9/1000+SUM(Confronto!$C$4:$N$4,Confronto!$C$9:$N$9,Confronto!$C$14:D14)+SUM(BASE!$AO$3:$AO$28)/1000,"") | E13: =IF(BASE!$B$29=1,BASE!$AQ$9/1000+SUM(Confronto!$C$4:$N$4,Confronto!$C$9:$N$9,Confronto!$C$14:E14)+SUM(BASE!$AO$3:$AO$29)/1000,"") | F13: =IF(BASE!$B$30=1,BASE!$AQ$9/1000+SUM(Confronto!$C$4:$N$4,Confronto!$C$9:$N$9,Confronto!$C$14:F14)+SUM(BASE!$AO$3:$AO$30)/1000,"") | G13: =IF(BASE!$B$31=1,BASE!$AQ$9/1000+SUM(Confronto!$C$4:$N$4,Confronto!$C$9:$N$9,Confronto!$C$14:G14)+SUM(BASE!$AO$3:$AO$31)/1000,"") | H13: =IF(BASE!$B$32=1,BASE!$AQ$9/1000+SUM(Confronto!$C$4:$N$4,Confronto!$C$9:$N$9,Confronto!$C$14:H14)+SUM(BASE!$AO$3:$AO$32)/1000,"") | I13: =IF(BASE!$B$33=1,BASE!$AQ$9/1000+SUM(Confronto!$C$4:$N$4,Confronto!$C$9:$N$9,Confronto!$C$14:I14)+SUM(BASE!$AO$3:$AO$33)/1000,"") | J13: =IF(BASE!$B$34=1,BASE!$AQ$9/1000+SUM(Confronto!$C$4:$N$4,Confronto!$C$9:$N$9,Confronto!$C$14:J14)+SUM(BASE!$AO$3:$AO$34)/1000,"") | K13: =IF(BASE!$B$35=1,BASE!$AQ$9/1000+SUM(Confronto!$C$4:$N$4,Confronto!$C$9:$N$9,Confronto!$C$14:K14)+SUM(BASE!$AO$3:$AO$35)/1000,"") | L13: =IF(BASE!$B$36=1,BASE!$AQ$9/1000+SUM(Confronto!$C$4:$N$4,Confronto!$C$9:$N$9,Confronto!$C$14:L14)+SUM(BASE!$AO$3:$AO$36)/1000,"") | M13: =IF(BASE!$B$37=1,BASE!$AQ$9/1000+SUM(Confronto!$C$4:$N$4,Confronto!$C$9:$N$9,Confronto!$C$14:M14)+SUM(BASE!$AO$3:$AO$37)/1000,"") | N13: =IF(BASE!$B$38=1,BASE!$AQ$9/1000+SUM(Confronto!$C$4:$N$4,Confronto!$C$9:$N$9,Confronto!$C$14:N14)+SUM(BASE!$AO$3:$AO$38)/1000,"")
B14: Var. Caixa | C14: =IF(BASE!$B$27=1,C13-N8,"") | D14: =IF(BASE!$B$28=1,D13-C13,"") | E14: =IF(BASE!$B$29=1,E13-D13,"") | F14: =IF(BASE!$B$30=1,F13-E13,"") | G14: =IF(BASE!$B$31=1,G13-F13,"") | H14: =IF(BASE!$B$32=1,H13-G13,"") | I14: =IF(BASE!$B$33=1,I13-H13,"") | J14: =IF(BASE!$B$34=1,J13-I13,"") | K14: =IF(BASE!$B$35=1,K13-J13,"") | L14: =IF(BASE!$B$36=1,L13-K13,"") | M14: =IF(BASE!$B$37=1,M13-L13,"") | N14: =IF(BASE!$B$38=1,N13-M13,"")

Sheet Despesa
B1: Despesa | C1: =BASE!$A$3 | D1: =BASE!$A$4 | E1: =BASE!$A$5 | F1: =BASE!$A$6 | G1: =BASE!$A$7 | H1: =BASE!$A$8 | I1: =BASE!$A$9 | J1: =BASE!$A$10 | K1: =BASE!$A$11 | L1: =BASE!$A$12 | M1: =BASE!$A$13 | N1: =BASE!$A$14
B2: Total (Acum.) | C2: =IF(BASE!$B$3=1,SUM(Confronto!$C$3:C3),"") | D2: =IF(BASE!$B$4=1,SUM(Confronto!$C$3:D3),"") | E2: =IF(BASE!$B$5=1,SUM(Confronto!$C$3:E3),"") | F2: =IF(BASE!$B$6=1,SUM(Confronto!$C$3:F3),"") | G2: =IF(BASE!$B$7=1,SUM(Confronto!$C$3:G3),"") | H2: =IF(BASE!$B$8=1,SUM(Confronto!$C$3:H3),"") | I2: =IF(BASE!$B$9=1,SUM(Confronto!$C$3:I3),"") | J2: =IF(BASE!$B$10=1,SUM(Confronto!$C$3:J3),"") | K2: =IF(BASE!$B$11=1,SUM(Confronto!$C$3:K3),"") | L2: =IF(BASE!$B$12=1,SUM(Confronto!$C$3:L3),"") | M2: =IF(BASE!$B$13=1,SUM(Confronto!$C$3:M3),"") | N2: =IF(BASE!$B$14=1,SUM(Confronto!$C$3:N3),"")
B3: Despesa | C3: =IF(BASE!$B$3=1,C2,"") | D3: =IF(BASE!$B$4=1,D2-C2,"") | E3: =IF(BASE!$B$5=1,E2-D2,"") | F3: =IF(BASE!$B$6=1,F2-E2,"") | G3: =IF(BASE!$B$7=1,G2-F2,"") | H3: =IF(BASE!$B$8=1,H2-G2,"") | I3: =IF(BASE!$B$9=1,I2-H2,"") | J3: =IF(BASE!$B$10=1,J2-I2,"") | K3: =IF(BASE!$B$11=1,K2-J2,"") | L3: =IF(BASE!$B$12=1,L2-K2,"") | M3: =IF(BASE!$B$13=1,M2-L2,"") | N3: =IF(BASE!$B$14=1,N2-M2,"")
B4: Variação | C4: - | D4: =IF(BASE!$B$4=1,D3-C3,"") | E4: =IF(BASE!$B$5=1,E3-D3,"") | F4: =IF(BASE!$B$6=1,F3-E3,"") | G4: =IF(BASE!$B$7=1,G3-F3,"") | H4: =IF(BASE!$B$8=1,H3-G3,"") | I4: =IF(BASE!$B$9=1,I3-H3,"") | J4: =IF(BASE!$B$10=1,J3-I3,"") | K4: =IF(BASE!$B$11=1,K3-J3,"") | L4: =IF(BASE!$B$12=1,L3-K3,"") | M4: =IF(BASE!$B$13=1,M3-L3,"") | N4: =IF(BASE!$B$14=1,N3-M3,"")
B6: Despesa | C6: =BASE!$A$15 | D6: =BASE!$A$16 | E6: =BASE!$A$17 | F6: =BASE!$A$18 | G6: =BASE!$A$19 | H6: =BASE!$A$20 | I6: =BASE!$A$21 | J6: =BASE!$A$22 | K6: =BASE!$A$23 | L6: =BASE!$A$24 | M6: =BASE!$A$25 | N6: =BASE!$A$26
B7: Total (Acum.) | C7: =IF(BASE!$B$15=1,SUM(Confronto!$C$8:C8),"") | D7: =IF(BASE!$B$16=1,SUM(Confronto!$C$8:D8),"") | E7: =IF(BASE!$B$17=1,SUM(Confronto!$C$8:E8),"") | F7: =IF(BASE!$B$18=1,SUM(Confronto!$C$8:F8),"") | G7: =IF(BASE!$B$19=1,SUM(Confronto!$C$8:G8),"") | H7: =IF(BASE!$B$20=1,SUM(Confronto!$C$8:H8),"") | I7: =IF(BASE!$B$21=1,SUM(Confronto!$C$8:I8),"") | J7: =IF(BASE!$B$22=1,SUM(Confronto!$C$8:J8),"") | K7: =IF(BASE!$B$23=1,SUM(Confronto!$C$8:K8),"") | L7: =IF(BASE!$B$24=1,SUM(Confronto!$C$8:L8),"") | M7: =IF(BASE!$B$25=1,SUM(Confronto!$C$8:M8),"") | N7: =IF(BASE!$B$26=1,SUM(Confronto!$C$8:N8),"")
B8: Despesa | C8: =IF(BASE!$B$15=1,C7,"") | D8: =IF(BASE!$B$16=1,D7-C7,"") | E8: =IF(BASE!$B$17=1,E7-D7,"") | F8: =IF(BASE!$B$18=1,F7-E7,"") | G8: =IF(BASE!$B$19=1,G7-F7,"") | H8: =IF(BASE!$B$20=1,H7-G7,"") | I8: =IF(BASE!$B$21=1,I7-H7,"") | J8: =IF(BASE!$B$22=1,J7-I7,"") | K8: =IF(BASE!$B$23=1,K7-J7,"") | L8: =IF(BASE!$B$24=1,L7-K7,"") | M8: =IF(BASE!$B$25=1,M7-L7,"") | N8: =IF(BASE!$B$26=1,N7-M7,"")
B9: Variação | C9: =IF(BASE!$B$15=1,C8-N3,"") | D9: =IF(BASE!$B$16=1,D8-C8,"") | E9: =IF(BASE!$B$17=1,E8-D8,"") | F9: =IF(BASE!$B$18=1,F8-E8,"") | G9: =IF(BASE!$B$19=1,G8-F8,"") | H9: =IF(BASE!$B$20=1,H8-G8,"") | I9: =IF(BASE!$B$21=1,I8-H8,"") | J9: =IF(BASE!$B$22=1,J8-I8,"") | K9: =IF(BASE!$B$23=1,K8-J8,"") | L9: =IF(BASE!$B$24=1,L8-K8,"") | M9: =IF(BASE!$B$25=1,M8-L8,"") | N9: =IF(BASE!$B$26=1,N8-M8,"")
B11: Despesa | C11: =BASE!$A$27 | D11: =BASE!$A$28 | E11: =BASE!$A$29 | F11: =BASE!$A$30 | G11: =BASE!$A$31 | H11: =BASE!$A$32 | I11: =BASE!$A$33 | J11: =BASE!$A$34 | K11: =BASE!$A$35 | L11: =BASE!$A$36 | M11: =BASE!$A$37 | N11: =BASE!$A$38
B12: Total (Acum.) | C12: =IF(BASE!$B$27=1,SUM(Confronto!$C$13:C13),"") | D12: =IF(BASE!$B$28=1,SUM(Confronto!$C$13:D13),"") | E12: =IF(BASE!$B$29=1,SUM(Confronto!$C$13:E13),"") | F12: =IF(BASE!$B$30=1,SUM(Confronto!$C$13:F13),"") | G12: =IF(BASE!$B$31=1,SUM(Confronto!$C$13:G13),"") | H12: =IF(BASE!$B$32=1,SUM(Confronto!$C$13:H13),"") | I12: =IF(BASE!$B$33=1,SUM(Confronto!$C$13:I13),"") | J12: =IF(BASE!$B$34=1,SUM(Confronto!$C$13:J13),"") | K12: =IF(BASE!$B$35=1,SUM(Confronto!$C$13:K13),"") | L12: =IF(BASE!$B$36=1,SUM(Confronto!$C$13:L13),"") | M12: =IF(BASE!$B$37=1,SUM(Confronto!$C$13:M13),"") | N12: =IF(BASE!$B$38=1,SUM(Confronto!$C$13:N13),"")
B13: Despesa | C13: =IF(BASE!$B$27=1,C12,"") | D13: =IF(BASE!$B$28=1,D12-C12,"") | E13: =IF(BASE!$B$29=1,E12-D12,"") | F13: =IF(BASE!$B$30=1,F12-E12,"") | G13: =IF(BASE!$B$31=1,G12-F12,"") | H13: =IF(BASE!$B$32=1,H12-G12,"") | I13: =IF(BASE!$B$33=1,I12-H12,"") | J13: =IF(BASE!$B$34=1,J12-I12,"") | K13: =IF(BASE!$B$35=1,K12-J12,"") | L13: =IF(BASE!$B$36=1,L12-K12,"") | M13: =IF(BASE!$B$37=1,M12-L12,"") | N13: =IF(BASE!$B$38=1,N12-M12,"")
B14: Variação | C14: =IF(BASE!$B$27=1,C13-N8,"") | D14: =IF(BASE!$B$28=1,D13-C13,"") | E14: =IF(BASE!$B$29=1,E13-D13,"") | F14: =IF(BASE!$B$30=1,F13-E13,"") | G14: =IF(BASE!$B$31=1,G13-F13,"") | H14: =IF(BASE!$B$32=1,H13-G13,"") | I14: =IF(BASE!$B$33=1,I13-H13,"") | J14: =IF(BASE!$B$34=1,J13-I13,"") | K14: =IF(BASE!$B$35=1,K13-J13,"") | L14: =IF(BASE!$B$36=1,L13-K13,"") | M14: =IF(BASE!$B$37=1,M13-L13,"") | N14: =IF(BASE!$B$38=1,N13-M13,"")

Sheet FOPAG
D2: FOPAG | E2: jan-25 | F2: fev-25 | G2: mar-25 | H2: abr-25 | I2: mai-25 | J2: jun-25 | K2: jul-25 | L2: ago-25 | M2: set-25 | N2: out-25 | O2: nov-25 | P2: dez-25 | Q2: Saldo25
D3: =BASE!$AP$12 | E3: =IF(BASE!$B$15=1,BASE!$AG$15/1000,"") | F3: =IF(BASE!$B$16=1,BASE!$AG$16/1000,"") | G3: =IF(BASE!$B$17=1,BASE!$AG$17/1000,"") | H3: =IF(BASE!$B$18=1,BASE!$AG$18/1000,"") | I3: =IF(BASE!$B$19=1,BASE!$AG$19/1000,"") | J3: =IF(BASE!$B$20=1,BASE!$AG$20/1000,"") | K3: =IF(BASE!$B$21=1,BASE!$AG$21/1000,"") | L3: =IF(BASE!$B$22=1,BASE!$AG$22/1000,"") | M3: =IF(BASE!$B$23=1,BASE!$AG$23/1000,"") | N3: =IF(BASE!$B$24=1,BASE!$AG$24/1000,"") | O3: =IF(BASE!$B$25=1,BASE!$AG$25/1000,"") | P3: =IF(BASE!$B$26=1,BASE!$AG$26/1000,"") | Q3: =IFERROR(LOOKUP(2,1/(ISNUMBER(E3:P3)*(E3:P3<>0)),E3:P3),0)
D4: =BASE!$AP$13 | E4: =IF(BASE!$B$15=1,BASE!$AH$15/1000,"") | F4: =IF(BASE!$B$16=1,BASE!$AH$16/1000,"") | G4: =IF(BASE!$B$17=1,BASE!$AH$17/1000,"") | H4: =IF(BASE!$B$18=1,BASE!$AH$18/1000,"") | I4: =IF(BASE!$B$19=1,BASE!$AH$19/1000,"") | J4: =IF(BASE!$B$20=1,BASE!$AH$20/1000,"") | K4: =IF(BASE!$B$21=1,BASE!$AH$21/1000,"") | L4: =IF(BASE!$B$22=1,BASE!$AH$22/1000,"") | M4: =IF(BASE!$B$23=1,BASE!$AH$23/1000,"") | N4: =IF(BASE!$B$24=1,BASE!$AH$24/1000,"") | O4: =IF(BASE!$B$25=1,BASE!$AH$25/1000,"") | P4: =IF(BASE!$B$26=1,BASE!$AH$26/1000,"") | Q4: =IFERROR(LOOKUP(2,1/(ISNUMBER(E4:P4)*(E4:P4<>0)),E4:P4),0)
D5: =BASE!$AP$14 | E5: =IF(BASE!$B$15=1,BASE!$AI$15/1000,"") | F5: =IF(BASE!$B$16=1,BASE!$AI$16/1000,"") | G5: =IF(BASE!$B$17=1,BASE!$AI$17/1000,"") | H5: =IF(BASE!$B$18=1,BASE!$AI$18/1000,"") | I5: =IF(BASE!$B$19=1,BASE!$AI$19/1000,"") | J5: =IF(BASE!$B$20=1,BASE!$AI$20/1000,"") | K5: =IF(BASE!$B$21=1,BASE!$AI$21/1000,"") | L5: =IF(BASE!$B$22=1,BASE!$AI$22/1000,"") | M5: =IF(BASE!$B$23=1,BASE!$AI$23/1000,"") | N5: =IF(BASE!$B$24=1,BASE!$AI$24/1000,"") | O5: =IF(BASE!$B$25=1,BASE!$AI$25/1000,"") | P5: =IF(BASE!$B$26=1,BASE!$AI$26/1000,"") | Q5: =IFERROR(LOOKUP(2,1/(ISNUMBER(E5:P5)*(E5:P5<>0)),E5:P5),0)
D6: =BASE!$AP$15 | E6: =IF(BASE!$B$15=1,BASE!$AJ$15/1000,"") | F6: =IF(BASE!$B$16=1,BASE!$AJ$16/1000,"") | G6: =IF(BASE!$B$17=1,BASE!$AJ$17/1000,"") | H6: =IF(BASE!$B$18=1,BASE!$AJ$18/1000,"") | I6: =IF(BASE!$B$19=1,BASE!$AJ$19/1000,"") | J6: =IF(BASE!$B$20=1,BASE!$AJ$20/1000,"") | K6: =IF(BASE!$B$21=1,BASE!$AJ$21/1000,"") | L6: =IF(BASE!$B$22=1,BASE!$AJ$22/1000,"") | M6: =IF(BASE!$B$23=1,BASE!$AJ$23/1000,"") | N6: =IF(BASE!$B$24=1,BASE!$AJ$24/1000,"") | O6: =IF(BASE!$B$25=1,BASE!$AJ$25/1000,"") | P6: =IF(BASE!$B$26=1,BASE!$AJ$26/1000,"") | Q6: =IFERROR(LOOKUP(2,1/(ISNUMBER(E6:P6)*(E6:P6<>0)),E6:P6),0)
D7: Total | E7: =SUM(E3:E6) | F7: =SUM(F3:F6) | G7: =SUM(G3:G6) | H7: =SUM(H3:H6) | I7: =SUM(I3:I6) | J7: =SUM(J3:J6) | K7: =SUM(K3:K6) | L7: =SUM(L3:L6) | ... Q7: =SUM(Q3:Q6)
D10: FOPAG | E10: jan-25 | F10: fev-25 | G10: mar-25 | H10: abr-25 | I10: mai-25 | J10: jun-25 | K10: jul-25 | L10: ago-25 | M10: set-25 | N10: out-25 | O10: nov-25 | P10: dez-25 | Q10: Retirada25
A11: 3.1.1.04.002 | B11: Retirada Sócio - Elber Medeiros | D11: =BASE!$AP$12 | E11: =IF(BASE!$B$15=1,BASE!$AK$15/1000,"") | F11: =IF(BASE!$B$16=1,BASE!$AK$16/1000,"") | G11: =IF(BASE!$B$17=1,BASE!$AK$17/1000,"") | H11: =IF(BASE!$B$18=1,BASE!$AK$18/1000,"") | I11: =IF(BASE!$B$19=1,BASE!$AK$19/1000,"") | J11: =IF(BASE!$B$20=1,BASE!$AK$20/1000,"") | K11: =IF(BASE!$B$21=1,BASE!$AK$21/1000,"") | L11: =IF(BASE!$B$22=1,BASE!$AK$22/1000,"") | M11: =IF(BASE!$B$23=1,BASE!$AK$23/1000,"") | N11: =IF(BASE!$B$24=1,BASE!$AK$24/1000,"") | O11: =IF(BASE!$B$25=1,BASE!$AK$25/1000,"") | P11: =IF(BASE!$B$26=1,BASE!$AK$26/1000,"") | Q11: =SUM(E11:P11)
D12: =BASE!$AP$13 | E12: =IF(BASE!$B$15=1,BASE!$AL$15/1000,"") | F12: =IF(BASE!$B$16=1,BASE!$AL$16/1000,"") | G12: =IF(BASE!$B$17=1,BASE!$AL$17/1000,"") | H12: =IF(BASE!$B$18=1,BASE!$AL$18/1000,"") | I12: =IF(BASE!$B$19=1,BASE!$AL$19/1000,"") | J12: =IF(BASE!$B$20=1,BASE!$AL$20/1000,"") | K12: =IF(BASE!$B$21=1,BASE!$AL$21/1000,"") | L12: =IF(BASE!$B$22=1,BASE!$AL$22/1000,"") | M12: =IF(BASE!$B$23=1,BASE!$AL$23/1000,"") | N12: =IF(BASE!$B$24=1,BASE!$AL$24/1000,"") | O12: =IF(BASE!$B$25=1,BASE!$AL$25/1000,"") | P12: =IF(BASE!$B$26=1,BASE!$AL$26/1000,"") | Q12: =SUM(E12:P12)
D13: =BASE!$AP$14 | E13: =IF(BASE!$B$15=1,BASE!$AM$15/1000,"") | F13: =IF(BASE!$B$16=1,BASE!$AM$16/1000,"") | G13: =IF(BASE!$B$17=1,BASE!$AM$17/1000,"") | H13: =IF(BASE!$B$18=1,BASE!$AM$18/1000,"") | I13: =IF(BASE!$B$19=1,BASE!$AM$19/1000,"") | J13: =IF(BASE!$B$20=1,BASE!$AM$20/1000,"") | K13: =IF(BASE!$B$21=1,BASE!$AM$21/1000,"") | L13: =IF(BASE!$B$22=1,BASE!$AM$22/1000,"") | M13: =IF(BASE!$B$23=1,BASE!$AM$23/1000,"") | N13: =IF(BASE!$B$24=1,BASE!$AM$24/1000,"") | O13: =IF(BASE!$B$25=1,BASE!$AM$25/1000,"") | P13: =IF(BASE!$B$26=1,BASE!$AM$26/1000,"") | Q13: =SUM(E13:P13)
D14: =BASE!$AP$15 | E14: =IF(BASE!$B$15=1,BASE!$AN$15/1000,"") | F14: =IF(BASE!$B$16=1,BASE!$AN$16/1000,"") | G14: =IF(BASE!$B$17=1,BASE!$AN$17/1000,"") | H14: =IF(BASE!$B$18=1,BASE!$AN$18/1000,"") | I14: =IF(BASE!$B$19=1,BASE!$AN$19/1000,"") | J14: =IF(BASE!$B$20=1,BASE!$AN$20/1000,"") | K14: =IF(BASE!$B$21=1,BASE!$AN$21/1000,"") | L14: =IF(BASE!$B$22=1,BASE!$AN$22/1000,"") | M14: =IF(BASE!$B$23=1,BASE!$AN$23/1000,"") | N14: =IF(BASE!$B$24=1,BASE!$AN$24/1000,"") | O14: =IF(BASE!$B$25=1,BASE!$AN$25/1000,"") | P14: =IF(BASE!$B$26=1,BASE!$AN$26/1000,"") | Q14: =SUM(E14:P14)
D15: Total | E15: =SUM(E11:E14) | F15: =SUM(F11:F14) | G15: =SUM(G11:G14) | H15: =SUM(H11:H14) | I15: =SUM(I11:I14) | J15: =SUM(J11:J14) | K15: =SUM(K11:K14) | L15: =SUM(L11:L14) | ... Q15: =SUM(Q11:Q14)
D18: FOPAG | E18: jan-25 | F18: fev-25 | G18: mar-25 | H18: abr-25 | I18: mai-25 | J18: jun-25 | K18: jul-25 | L18: ago-25 | M18: set-25 | N18: out-25 | O18: nov-25 | P18: dez-25 | Q18: Variação
D19: =BASE!$AP$12 | E19: =IF(BASE!$B$15=1,E3,"") | F19: =IF(BASE!$B$16=1,F3-E3,"") | G19: =IF(BASE!$B$17=1,G3-F3,"") | H19: =IF(BASE!$B$18=1,H3-G3,"") | I19: =IF(BASE!$B$19=1,I3-H3,"") | J19: =IF(BASE!$B$20=1,J3-I3,"") | K19: =IF(BASE!$B$21=1,K3-J3,"") | L19: =IF(BASE!$B$22=1,L3-K3,"") | M19: =IF(BASE!$B$23=1,M3-L3,"") | N19: =IF(BASE!$B$24=1,N3-M3,"") | O19: =IF(BASE!$B$25=1,O3-N3,"") | P19: =IF(BASE!$B$26=1,P3-O3,"") | Q19: =IFERROR(LOOKUP(2,1/(ISNUMBER(E19:P19)*(E19:P19<>0)),E19:P19),0)
D20: =BASE!$AP$13 | E20: =IF(BASE!$B$15=1,E4,"") | F20: =IF(BASE!$B$16=1,F4-E4,"") | G20: =IF(BASE!$B$17=1,G4-F4,"") | H20: =IF(BASE!$B$18=1,H4-G4,"") | I20: =IF(BASE!$B$19=1,I4-H4,"") | J20: =IF(BASE!$B$20=1,J4-I4,"") | K20: =IF(BASE!$B$21=1,K4-J4,"") | L20: =IF(BASE!$B$22=1,L4-K4,"") | M20: =IF(BASE!$B$23=1,M4-L4,"") | N20: =IF(BASE!$B$24=1,N4-M4,"") | O20: =IF(BASE!$B$25=1,O4-N4,"") | P20: =IF(BASE!$B$26=1,P4-O4,"") | Q20: =IFERROR(LOOKUP(2,1/(ISNUMBER(E20:P20)*(E20:P20<>0)),E20:P20),0)
D21: =BASE!$AP$14 | E21: =IF(BASE!$B$15=1,E5,"") | F21: =IF(BASE!$B$16=1,F5-E5,"") | G21: =IF(BASE!$B$17=1,G5-F5,"") | H21: =IF(BASE!$B$18=1,H5-G5,"") | I21: =IF(BASE!$B$19=1,I5-H5,"") | J21: =IF(BASE!$B$20=1,J5-I5,"") | K21: =IF(BASE!$B$21=1,K5-J5,"") | L21: =IF(BASE!$B$22=1,L5-K5,"") | M21: =IF(BASE!$B$23=1,M5-L5,"") | N21: =IF(BASE!$B$24=1,N5-M5,"") | O21: =IF(BASE!$B$25=1,O5-N5,"") | P21: =IF(BASE!$B$26=1,P5-O5,"") | Q21: =IFERROR(LOOKUP(2,1/(ISNUMBER(E21:P21)*(E21:P21<>0)),E21:P21),0)
D22: =BASE!$AP$15 | E22: =IF(BASE!$B$15=1,E6,"") | F22: =IF(BASE!$B$16=1,F6-E6,"") | G22: =IF(BASE!$B$17=1,G6-F6,"") | H22: =IF(BASE!$B$18=1,H6-G6,"") | I22: =IF(BASE!$B$19=1,I6-H6,"") | J22: =IF(BASE!$B$20=1,J6-I6,"") | K22: =IF(BASE!$B$21=1,K6-J6,"") | L22: =IF(BASE!$B$22=1,L6-K6,"") | M22: =IF(BASE!$B$23=1,M6-L6,"") | N22: =IF(BASE!$B$24=1,N6-M6,"") | O22: =IF(BASE!$B$25=1,O6-N6,"") | P22: =IF(BASE!$B$26=1,P6-O6,"") | Q22: =IFERROR(LOOKUP(2,1/(ISNUMBER(E22:P22)*(E22:P22<>0)),E22:P22),0)
D23: Total | E23: =SUM(E19:E22) | F23: =SUM(F19:F22) | G23: =SUM(G19:G22) | H23: =SUM(H19:H22) | I23: =SUM(I19:I22) | J23: =SUM(J19:J22) | K23: =SUM(K19:K22) | L23: =SUM(L19:L22) | ... Q23: =SUM(Q19:Q22)
D25: FOPAG | E25: jan-26 | F25: fev-26 | G25: mar-26 | H25: abr-26 | I25: mai-26 | J25: jun-26 | K25: jul-26 | L25: ago-26 | M25: set-26 | N25: out-26 | O25: nov-26 | P25: dez-26 | Q25: Saldo26
D26: =BASE!$AP$12 | E26: =IF(BASE!$B$27=1,BASE!$AG$27/1000,"") | F26: =IF(BASE!$B$28=1,BASE!$AG$28/1000,"") | G26: =IF(BASE!$B$29=1,BASE!$AG$29/1000,"") | H26: =IF(BASE!$B$30=1,BASE!$AG$30/1000,"") | I26: =IF(BASE!$B$31=1,BASE!$AG$31/1000,"") | J26: =IF(BASE!$B$32=1,BASE!$AG$32/1000,"") | K26: =IF(BASE!$B$33=1,BASE!$AG$33/1000,"") | L26: =IF(BASE!$B$34=1,BASE!$AG$34/1000,"") | M26: =IF(BASE!$B$35=1,BASE!$AG$35/1000,"") | N26: =IF(BASE!$B$36=1,BASE!$AG$36/1000,"") | O26: =IF(BASE!$B$37=1,BASE!$AG$37/1000,"") | P26: =IF(BASE!$B$38=1,BASE!$AG$38/1000,"") | Q26: =IFERROR(LOOKUP(2,1/(ISNUMBER(E26:P26)*(E26:P26<>0)),E26:P26),0)
D27: =BASE!$AP$13 | E27: =IF(BASE!$B$27=1,BASE!$AH$27/1000,"") | F27: =IF(BASE!$B$28=1,BASE!$AH$28/1000,"") | G27: =IF(BASE!$B$29=1,BASE!$AH$29/1000,"") | H27: =IF(BASE!$B$30=1,BASE!$AH$30/1000,"") | I27: =IF(BASE!$B$31=1,BASE!$AH$31/1000,"") | J27: =IF(BASE!$B$32=1,BASE!$AH$32/1000,"") | K27: =IF(BASE!$B$33=1,BASE!$AH$33/1000,"") | L27: =IF(BASE!$B$34=1,BASE!$AH$34/1000,"") | M27: =IF(BASE!$B$35=1,BASE!$AH$35/1000,"") | N27: =IF(BASE!$B$36=1,BASE!$AH$36/1000,"") | O27: =IF(BASE!$B$37=1,BASE!$AH$37/1000,"") | P27: =IF(BASE!$B$38=1,BASE!$AH$38/1000,"") | Q27: =IFERROR(LOOKUP(2,1/(ISNUMBER(E27:P27)*(E27:P27<>0)),E27:P27),0)
D28: =BASE!$AP$14 | E28: =IF(BASE!$B$27=1,BASE!$AI$27/1000,"") | F28: =IF(BASE!$B$28=1,BASE!$AI$28/1000,"") | G28: =IF(BASE!$B$29=1,BASE!$AI$29/1000,"") | H28: =IF(BASE!$B$30=1,BASE!$AI$30/1000,"") | I28: =IF(BASE!$B$31=1,BASE!$AI$31/1000,"") | J28: =IF(BASE!$B$32=1,BASE!$AI$32/1000,"") | K28: =IF(BASE!$B$33=1,BASE!$AI$33/1000,"") | L28: =IF(BASE!$B$34=1,BASE!$AI$34/1000,"") | M28: =IF(BASE!$B$35=1,BASE!$AI$35/1000,"") | N28: =IF(BASE!$B$36=1,BASE!$AI$36/1000,"") | O28: =IF(BASE!$B$37=1,BASE!$AI$37/1000,"") | P28: =IF(BASE!$B$38=1,BASE!$AI$38/1000,"") | Q28: =IFERROR(LOOKUP(2,1/(ISNUMBER(E28:P28)*(E28:P28<>0)),E28:P28),0)
D29: =BASE!$AP$15 | E29: =IF(BASE!$B$27=1,BASE!$AJ$27/1000,"") | F29: =IF(BASE!$B$28=1,BASE!$AJ$28/1000,"") | G29: =IF(BASE!$B$29=1,BASE!$AJ$29/1000,"") | H29: =IF(BASE!$B$30=1,BASE!$AJ$30/1000,"") | I29: =IF(BASE!$B$31=1,BASE!$AJ$31/1000,"") | J29: =IF(BASE!$B$32=1,BASE!$AJ$32/1000,"") | K29: =IF(BASE!$B$33=1,BASE!$AJ$33/1000,"") | L29: =IF(BASE!$B$34=1,BASE!$AJ$34/1000,"") | M29: =IF(BASE!$B$35=1,BASE!$AJ$35/1000,"") | N29: =IF(BASE!$B$36=1,BASE!$AJ$36/1000,"") | O29: =IF(BASE!$B$37=1,BASE!$AJ$37/1000,"") | P29: =IF(BASE!$B$38=1,BASE!$AJ$38/1000,"") | Q29: =IFERROR(LOOKUP(2,1/(ISNUMBER(E29:P29)*(E29:P29<>0)),E29:P29),0)
D30: Total | E30: =SUM(E26:E29) | F30: =SUM(F26:F29) | G30: =SUM(G26:G29) | H30: =SUM(H26:H29) | I30: =SUM(I26:I29) | J30: =SUM(J26:J29) | K30: =SUM(K26:K29) | L30: =SUM(L26:L29) | ... Q30: =SUM(Q26:Q29)
D33: FOPAG | E33: jan-26 | F33: fev-26 | G33: mar-26 | H33: abr-26 | I33: mai-26 | J33: jun-26 | K33: jul-26 | L33: ago-26 | M33: set-26 | N33: out-26 | O33: nov-26 | P33: dez-26 | Q33: Retirada26
D34: =BASE!$AP$12 | E34: =IF(BASE!$B$27=1,BASE!$AK$27/1000,"") | F34: =IF(BASE!$B$28=1,BASE!$AK$28/1000,"") | G34: =IF(BASE!$B$29=1,BASE!$AK$29/1000,"") | H34: =IF(BASE!$B$30=1,BASE!$AK$30/1000,"") | I34: =IF(BASE!$B$31=1,BASE!$AK$31/1000,"") | J34: =IF(BASE!$B$32=1,BASE!$AK$32/1000,"") | K34: =IF(BASE!$B$33=1,BASE!$AK$33/1000,"") | L34: =IF(BASE!$B$34=1,BASE!$AK$34/1000,"") | M34: =IF(BASE!$B$35=1,BASE!$AK$35/1000,"") | N34: =IF(BASE!$B$36=1,BASE!$AK$36/1000,"") | O34: =IF(BASE!$B$37=1,BASE!$AK$37/1000,"") | P34: =IF(BASE!$B$38=1,BASE!$AK$38/1000,"") | Q34: =SUM(E34:P34)
D35: =BASE!$AP$13 | E35: =IF(BASE!$B$27=1,BASE!$AL$27/1000,"") | F35: =IF(BASE!$B$28=1,BASE!$AL$28/1000,"") | G35: =IF(BASE!$B$29=1,BASE!$AL$29/1000,"") | H35: =IF(BASE!$B$30=1,BASE!$AL$30/1000,"") | I35: =IF(BASE!$B$31=1,BASE!$AL$31/1000,"") | J35: =IF(BASE!$B$32=1,BASE!$AL$32/1000,"") | K35: =IF(BASE!$B$33=1,BASE!$AL$33/1000,"") | L35: =IF(BASE!$B$34=1,BASE!$AL$34/1000,"") | M35: =IF(BASE!$B$35=1,BASE!$AL$35/1000,"") | N35: =IF(BASE!$B$36=1,BASE!$AL$36/1000,"") | O35: =IF(BASE!$B$37=1,BASE!$AL$37/1000,"") | P35: =IF(BASE!$B$38=1,BASE!$AL$38/1000,"") | Q35: =SUM(E35:P35)
D36: =BASE!$AP$14 | E36: =IF(BASE!$B$27=1,BASE!$AM$27/1000,"") | F36: =IF(BASE!$B$28=1,BASE!$AM$28/1000,"") | G36: =IF(BASE!$B$29=1,BASE!$AM$29/1000,"") | H36: =IF(BASE!$B$30=1,BASE!$AM$30/1000,"") | I36: =IF(BASE!$B$31=1,BASE!$AM$31/1000,"") | J36: =IF(BASE!$B$32=1,BASE!$AM$32/1000,"") | K36: =IF(BASE!$B$33=1,BASE!$AM$33/1000,"") | L36: =IF(BASE!$B$34=1,BASE!$AM$34/1000,"") | M36: =IF(BASE!$B$35=1,BASE!$AM$35/1000,"") | N36: =IF(BASE!$B$36=1,BASE!$AM$36/1000,"") | O36: =IF(BASE!$B$37=1,BASE!$AM$37/1000,"") | P36: =IF(BASE!$B$38=1,BASE!$AM$38/1000,"") | Q36: =SUM(E36:P36)
D37: =BASE!$AP$15 | E37: =IF(BASE!$B$27=1,BASE!$AN$27/1000,"") | F37: =IF(BASE!$B$28=1,BASE!$AN$28/1000,"") | G37: =IF(BASE!$B$29=1,BASE!$AN$29/1000,"") | H37: =IF(BASE!$B$30=1,BASE!$AN$30/1000,"") | I37: =IF(BASE!$B$31=1,BASE!$AN$31/1000,"") | J37: =IF(BASE!$B$32=1,BASE!$AN$32/1000,"") | K37: =IF(BASE!$B$33=1,BASE!$AN$33/1000,"") | L37: =IF(BASE!$B$34=1,BASE!$AN$34/1000,"") | M37: =IF(BASE!$B$35=1,BASE!$AN$35/1000,"") | N37: =IF(BASE!$B$36=1,BASE!$AN$36/1000,"") | O37: =IF(BASE!$B$37=1,BASE!$AN$37/1000,"") | P37: =IF(BASE!$B$38=1,BASE!$AN$38/1000,"") | Q37: =SUM(E37:P37)
D38: Total | E38: =SUM(E34:E37) | F38: =SUM(F34:F37) | G38: =SUM(G34:G37) | H38: =SUM(H34:H37) | I38: =SUM(I34:I37) | J38: =SUM(J34:J37) | K38: =SUM(K34:K37) | L38: =SUM(L34:L37) | ... Q38: =SUM(Q34:Q37)
D41: FOPAG | E41: jan-26 | F41: fev-26 | G41: mar-26 | H41: abr-26 | I41: mai-26 | J41: jun-26 | K41: jul-26 | L41: ago-26 | M41: set-26 | N41: out-26 | O41: nov-26 | P41: dez-26 | Q41: Variação
D42: =BASE!$AP$12 | E42: =IF(BASE!$B$27=1,IF(N(P3)=0,0,E26-P3),"") | F42: =IF(BASE!$B$28=1,F26-E26,"") | G42: =IF(BASE!$B$29=1,G26-F26,"") | H42: =IF(BASE!$B$30=1,H26-G26,"") | I42: =IF(BASE!$B$31=1,I26-H26,"") | J42: =IF(BASE!$B$32=1,J26-I26,"") | K42: =IF(BASE!$B$33=1,K26-J26,"") | L42: =IF(BASE!$B$34=1,L26-K26,"") | M42: =IF(BASE!$B$35=1,M26-L26,"") | N42: =IF(BASE!$B$36=1,N26-M26,"") | O42: =IF(BASE!$B$37=1,O26-N26,"") | P42: =IF(BASE!$B$38=1,P26-O26,"") | Q42: =IFERROR(LOOKUP(2,1/(ISNUMBER(E42:P42)*(E42:P42<>0)),E42:P42),0)
D43: =BASE!$AP$13 | E43: =IF(BASE!$B$27=1,IF(N(P4)=0,0,E27-P4),"") | F43: =IF(BASE!$B$28=1,F27-E27,"") | G43: =IF(BASE!$B$29=1,G27-F27,"") | H43: =IF(BASE!$B$30=1,H27-G27,"") | I43: =IF(BASE!$B$31=1,I27-H27,"") | J43: =IF(BASE!$B$32=1,J27-I27,"") | K43: =IF(BASE!$B$33=1,K27-J27,"") | L43: =IF(BASE!$B$34=1,L27-K27,"") | M43: =IF(BASE!$B$35=1,M27-L27,"") | N43: =IF(BASE!$B$36=1,N27-M27,"") | O43: =IF(BASE!$B$37=1,O27-N27,"") | P43: =IF(BASE!$B$38=1,P27-O27,"") | Q43: =IFERROR(LOOKUP(2,1/(ISNUMBER(E43:P43)*(E43:P43<>0)),E43:P43),0)
D44: =BASE!$AP$14 | E44: =IF(BASE!$B$27=1,IF(N(P5)=0,0,E28-P5),"") | F44: =IF(BASE!$B$28=1,F28-E28,"") | G44: =IF(BASE!$B$29=1,G28-F28,"") | H44: =IF(BASE!$B$30=1,H28-G28,"") | I44: =IF(BASE!$B$31=1,I28-H28,"") | J44: =IF(BASE!$B$32=1,J28-I28,"") | K44: =IF(BASE!$B$33=1,K28-J28,"") | L44: =IF(BASE!$B$34=1,L28-K28,"") | M44: =IF(BASE!$B$35=1,M28-L28,"") | N44: =IF(BASE!$B$36=1,N28-M28,"") | O44: =IF(BASE!$B$37=1,O28-N28,"") | P44: =IF(BASE!$B$38=1,P28-O28,"") | Q44: =IFERROR(LOOKUP(2,1/(ISNUMBER(E44:P44)*(E44:P44<>0)),E44:P44),0)
D45: =BASE!$AP$15 | E45: =IF(BASE!$B$27=1,IF(N(P6)=0,0,E29-P6),"") | F45: =IF(BASE!$B$28=1,F29-E29,"") | G45: =IF(BASE!$B$29=1,G29-F29,"") | H45: =IF(BASE!$B$30=1,H29-G29,"") | I45: =IF(BASE!$B$31=1,I29-H29,"") | J45: =IF(BASE!$B$32=1,J29-I29,"") | K45: =IF(BASE!$B$33=1,K29-J29,"") | L45: =IF(BASE!$B$34=1,L29-K29,"") | M45: =IF(BASE!$B$35=1,M29-L29,"") | N45: =IF(BASE!$B$36=1,N29-M29,"") | O45: =IF(BASE!$B$37=1,O29-N29,"") | P45: =IF(BASE!$B$38=1,P29-O29,"") | Q45: =IFERROR(LOOKUP(2,1/(ISNUMBER(E45:P45)*(E45:P45<>0)),E45:P45),0)
D46: Total | E46: =SUM(E42:E45) | F46: =SUM(F42:F45) | G46: =SUM(G42:G45) | H46: =SUM(H42:H45) | I46: =SUM(I42:I45) | J46: =SUM(J42:J45) | K46: =SUM(K42:K45) | L46: =SUM(L42:L45) | ... Q46: =SUM(Q42:Q45)

Sheet Faturamento FY
B1: 1000000 | K1: Variação
G2: Faturamento - Atual | K2: Faturamento
D3: Mês | E3: Ano | F3: Data | G3: Faturado | I3: Total Faturado
C4: =EOMONTH(BASE!$A$14,0) | D4: =VLOOKUP(MONTH(C4),$AE$16:$AF$27,2,0) | E4: =YEAR(C4) | F4: =EOMONTH(BASE!$A$14,0) | G4: =IF(BASE!$B$14=1,BASE!$E$14/1000,"") | I4: =SUM(BASE!$E$3:$E$14)/1000 | K4: =IF(BASE!$B$14=1,G4,"")
C5: =EOMONTH(BASE!$A$15,0) | D5: =VLOOKUP(MONTH(C5),$AE$16:$AF$27,2,0) | E5: =YEAR(C5) | F5: =EOMONTH(BASE!$A$15,0) | G5: =IF(BASE!$B$15=1,BASE!$E$15/1000,"") | I5: =IF(BASE!$B$15=1,SUM($G$5:G5),"") | K5: =IF(BASE!$B$15=1,G5,"")
C6: =EOMONTH(BASE!$A$16,0) | D6: =VLOOKUP(MONTH(C6),$AE$16:$AF$27,2,0) | E6: =YEAR(C6) | F6: =EOMONTH(BASE!$A$16,0) | G6: =IF(BASE!$B$16=1,BASE!$E$16/1000,"") | I6: =IF(BASE!$B$16=1,SUM($G$5:G6),"") | K6: =IF(BASE!$B$16=1,G6,"")
C7: =EOMONTH(BASE!$A$17,0) | D7: =VLOOKUP(MONTH(C7),$AE$16:$AF$27,2,0) | E7: =YEAR(C7) | F7: =EOMONTH(BASE!$A$17,0) | G7: =IF(BASE!$B$17=1,BASE!$E$17/1000,"") | I7: =IF(BASE!$B$17=1,SUM($G$5:G7),"") | K7: =IF(BASE!$B$17=1,G7,"")
C8: =EOMONTH(BASE!$A$18,0) | D8: =VLOOKUP(MONTH(C8),$AE$16:$AF$27,2,0) | E8: =YEAR(C8) | F8: =EOMONTH(BASE!$A$18,0) | G8: =IF(BASE!$B$18=1,BASE!$E$18/1000,"") | I8: =IF(BASE!$B$18=1,SUM($G$5:G8),"") | K8: =IF(BASE!$B$18=1,G8,"")
C9: =EOMONTH(BASE!$A$19,0) | D9: =VLOOKUP(MONTH(C9),$AE$16:$AF$27,2,0) | E9: =YEAR(C9) | F9: =EOMONTH(BASE!$A$19,0) | G9: =IF(BASE!$B$19=1,BASE!$E$19/1000,"") | I9: =IF(BASE!$B$19=1,SUM($G$5:G9),"") | K9: =IF(BASE!$B$19=1,G9,"")
C10: =EOMONTH(BASE!$A$20,0) | D10: =VLOOKUP(MONTH(C10),$AE$16:$AF$27,2,0) | E10: =YEAR(C10) | F10: =EOMONTH(BASE!$A$20,0) | G10: =IF(BASE!$B$20=1,BASE!$E$20/1000,"") | I10: =IF(BASE!$B$20=1,SUM($G$5:G10),"") | K10: =IF(BASE!$B$20=1,G10,"")
C11: =EOMONTH(BASE!$A$21,0) | D11: =VLOOKUP(MONTH(C11),$AE$16:$AF$27,2,0) | E11: =YEAR(C11) | F11: =EOMONTH(BASE!$A$21,0) | G11: =IF(BASE!$B$21=1,BASE!$E$21/1000,"") | I11: =IF(BASE!$B$21=1,SUM($G$5:G11),"") | K11: =IF(BASE!$B$21=1,G11,"")
C12: =EOMONTH(BASE!$A$22,0) | D12: =VLOOKUP(MONTH(C12),$AE$16:$AF$27,2,0) | E12: =YEAR(C12) | F12: =EOMONTH(BASE!$A$22,0) | G12: =IF(BASE!$B$22=1,BASE!$E$22/1000,"") | I12: =IF(BASE!$B$22=1,SUM($G$5:G12),"") | K12: =IF(BASE!$B$22=1,G12,"")
C13: =EOMONTH(BASE!$A$23,0) | D13: =VLOOKUP(MONTH(C13),$AE$16:$AF$27,2,0) | E13: =YEAR(C13) | F13: =EOMONTH(BASE!$A$23,0) | G13: =IF(BASE!$B$23=1,BASE!$E$23/1000,"") | I13: =IF(BASE!$B$23=1,SUM($G$5:G13),"") | K13: =IF(BASE!$B$23=1,G13,"")
C14: =EOMONTH(BASE!$A$24,0) | D14: =VLOOKUP(MONTH(C14),$AE$16:$AF$27,2,0) | E14: =YEAR(C14) | F14: =EOMONTH(BASE!$A$24,0) | G14: =IF(BASE!$B$24=1,BASE!$E$24/1000,"") | I14: =IF(BASE!$B$24=1,SUM($G$5:G14),"") | K14: =IF(BASE!$B$24=1,G14,"")
C15: =EOMONTH(BASE!$A$25,0) | D15: =VLOOKUP(MONTH(C15),$AE$16:$AF$27,2,0) | E15: =YEAR(C15) | F15: =EOMONTH(BASE!$A$25,0) | G15: =IF(BASE!$B$25=1,BASE!$E$25/1000,"") | I15: =IF(BASE!$B$25=1,SUM($G$5:G15),"") | K15: =IF(BASE!$B$25=1,G15,"")
C16: =EOMONTH(BASE!$A$26,0) | D16: =VLOOKUP(MONTH(C16),$AE$16:$AF$27,2,0) | E16: =YEAR(C16) | F16: =EOMONTH(BASE!$A$26,0) | G16: =IF(BASE!$B$26=1,BASE!$E$26/1000,"") | I16: =IF(BASE!$B$26=1,SUM($G$5:G16),"") | K16: =IF(BASE!$B$26=1,G16,"") | AE16: 1 | AF16: Jan
C17: =EOMONTH(BASE!$A$27,0) | D17: =VLOOKUP(MONTH(C17),$AE$16:$AF$27,2,0) | E17: =YEAR(C17) | F17: =EOMONTH(BASE!$A$27,0) | G17: =IF(BASE!$B$27=1,BASE!$E$27/1000,"") | I17: =IF(BASE!$B$27=1,SUM($G$17:G17),"") | K17: =IF(BASE!$B$27=1,G17,"") | AE17: =1+AE16 | AF17: Fev
C18: =EOMONTH(BASE!$A$28,0) | D18: =VLOOKUP(MONTH(C18),$AE$16:$AF$27,2,0) | E18: =YEAR(C18) | F18: =EOMONTH(BASE!$A$28,0) | G18: =IF(BASE!$B$28=1,BASE!$E$28/1000,"") | I18: =IF(BASE!$B$28=1,SUM($G$17:G18),"") | K18: =IF(BASE!$B$28=1,G18,"") | AE18: =1+AE17 | AF18: Mar
C19: =EOMONTH(BASE!$A$29,0) | D19: =VLOOKUP(MONTH(C19),$AE$16:$AF$27,2,0) | E19: =YEAR(C19) | F19: =EOMONTH(BASE!$A$29,0) | G19: =IF(BASE!$B$29=1,BASE!$E$29/1000,"") | I19: =IF(BASE!$B$29=1,SUM($G$17:G19),"") | K19: =IF(BASE!$B$29=1,G19,"") | AE19: =1+AE18 | AF19: Abr
C20: =EOMONTH(BASE!$A$30,0) | D20: =VLOOKUP(MONTH(C20),$AE$16:$AF$27,2,0) | E20: =YEAR(C20) | F20: =EOMONTH(BASE!$A$30,0) | G20: =IF(BASE!$B$30=1,BASE!$E$30/1000,"") | I20: =IF(BASE!$B$30=1,SUM($G$17:G20),"") | K20: =IF(BASE!$B$30=1,G20,"") | AE20: =1+AE19 | AF20: Mai
C21: =EOMONTH(BASE!$A$31,0) | D21: =VLOOKUP(MONTH(C21),$AE$16:$AF$27,2,0) | E21: =YEAR(C21) | F21: =EOMONTH(BASE!$A$31,0) | G21: =IF(BASE!$B$31=1,BASE!$E$31/1000,"") | I21: =IF(BASE!$B$31=1,SUM($G$17:G21),"") | K21: =IF(BASE!$B$31=1,G21,"") | AE21: =1+AE20 | AF21: Jun
C22: =EOMONTH(BASE!$A$32,0) | D22: =VLOOKUP(MONTH(C22),$AE$16:$AF$27,2,0) | E22: =YEAR(C22) | F22: =EOMONTH(BASE!$A$32,0) | G22: =IF(BASE!$B$32=1,BASE!$E$32/1000,"") | I22: =IF(BASE!$B$32=1,SUM($G$17:G22),"") | K22: =IF(BASE!$B$32=1,G22,"") | AE22: =1+AE21 | AF22: Jul
C23: =EOMONTH(BASE!$A$33,0) | D23: =VLOOKUP(MONTH(C23),$AE$16:$AF$27,2,0) | E23: =YEAR(C23) | F23: =EOMONTH(BASE!$A$33,0) | G23: =IF(BASE!$B$33=1,BASE!$E$33/1000,"") | I23: =IF(BASE!$B$33=1,SUM($G$17:G23),"") | K23: =IF(BASE!$B$33=1,G23,"") | AE23: =1+AE22 | AF23: Ago
C24: =EOMONTH(BASE!$A$34,0) | D24: =VLOOKUP(MONTH(C24),$AE$16:$AF$27,2,0) | E24: =YEAR(C24) | F24: =EOMONTH(BASE!$A$34,0) | G24: =IF(BASE!$B$34=1,BASE!$E$34/1000,"") | I24: =IF(BASE!$B$34=1,SUM($G$17:G24),"") | K24: =IF(BASE!$B$34=1,G24,"") | AE24: =1+AE23 | AF24: Set
C25: =EOMONTH(BASE!$A$35,0) | D25: =VLOOKUP(MONTH(C25),$AE$16:$AF$27,2,0) | E25: =YEAR(C25) | F25: =EOMONTH(BASE!$A$35,0) | G25: =IF(BASE!$B$35=1,BASE!$E$35/1000,"") | I25: =IF(BASE!$B$35=1,SUM($G$17:G25),"") | K25: =IF(BASE!$B$35=1,G25,"") | AE25: =1+AE24 | AF25: Out
C26: =EOMONTH(BASE!$A$36,0) | D26: =VLOOKUP(MONTH(C26),$AE$16:$AF$27,2,0) | E26: =YEAR(C26) | F26: =EOMONTH(BASE!$A$36,0) | G26: =IF(BASE!$B$36=1,BASE!$E$36/1000,"") | I26: =IF(BASE!$B$36=1,SUM($G$17:G26),"") | K26: =IF(BASE!$B$36=1,G26,"") | AE26: =1+AE25 | AF26: Nov
C27: =EOMONTH(BASE!$A$37,0) | D27: =VLOOKUP(MONTH(C27),$AE$16:$AF$27,2,0) | E27: =YEAR(C27) | F27: =EOMONTH(BASE!$A$37,0) | G27: =IF(BASE!$B$37=1,BASE!$E$37/1000,"") | I27: =IF(BASE!$B$37=1,SUM($G$17:G27),"") | K27: =IF(BASE!$B$37=1,G27,"") | AE27: =1+AE26 | AF27: Dez
C28: =EOMONTH(BASE!$A$38,0) | D28: =VLOOKUP(MONTH(C28),$AE$16:$AF$27,2,0) | E28: =YEAR(C28) | F28: =EOMONTH(BASE!$A$38,0) | G28: =IF(BASE!$B$38=1,BASE!$E$38/1000,"") | I28: =IF(BASE!$B$38=1,SUM($G$17:G28),"") | K28: =IF(BASE!$B$38=1,G28,"")

Sheet Working Capital ->

Sheet Estoque - Ativo
B1: Saldo | D1: Variação | F1: Estoque
B2: Materiais | C2: Produtos | D2: Materiais | E2: Produtos | F2: Estoque Total | G2: Total Var. (%)
A3: =BASE!$A$14 | B3: =IF(BASE!$B$14=1,BASE!$G$14/1000,"") | C3: =IF(BASE!$B$14=1,BASE!$H$14/1000,"") | D3: =B3 | E3: =C3 | F3: =IF(BASE!$B$14=1,SUM(B3:C3),"") | G3: 0
A4: =BASE!$A$15 | B4: =IF(BASE!$B$15=1,BASE!$G$15/1000,"") | C4: =IF(BASE!$B$15=1,BASE!$H$15/1000,"") | D4: =IF(BASE!$B$15=1,B4-B3,"") | E4: =IF(BASE!$B$15=1,C4-C3,"") | F4: =IF(BASE!$B$15=1,SUM(B4:C4),"") | G4: =IF(BASE!$B$15=1,IFERROR(F4/F3-1,0),"")
A5: =BASE!$A$16 | B5: =IF(BASE!$B$16=1,BASE!$G$16/1000,"") | C5: =IF(BASE!$B$16=1,BASE!$H$16/1000,"") | D5: =IF(BASE!$B$16=1,B5-B4,"") | E5: =IF(BASE!$B$16=1,C5-C4,"") | F5: =IF(BASE!$B$16=1,SUM(B5:C5),"") | G5: =IF(BASE!$B$16=1,IFERROR(F5/F4-1,0),"")
A6: =BASE!$A$17 | B6: =IF(BASE!$B$17=1,BASE!$G$17/1000,"") | C6: =IF(BASE!$B$17=1,BASE!$H$17/1000,"") | D6: =IF(BASE!$B$17=1,B6-B5,"") | E6: =IF(BASE!$B$17=1,C6-C5,"") | F6: =IF(BASE!$B$17=1,SUM(B6:C6),"") | G6: =IF(BASE!$B$17=1,IFERROR(F6/F5-1,0),"")
A7: =BASE!$A$18 | B7: =IF(BASE!$B$18=1,BASE!$G$18/1000,"") | C7: =IF(BASE!$B$18=1,BASE!$H$18/1000,"") | D7: =IF(BASE!$B$18=1,B7-B6,"") | E7: =IF(BASE!$B$18=1,C7-C6,"") | F7: =IF(BASE!$B$18=1,SUM(B7:C7),"") | G7: =IF(BASE!$B$18=1,IFERROR(F7/F6-1,0),"")
A8: =BASE!$A$19 | B8: =IF(BASE!$B$19=1,BASE!$G$19/1000,"") | C8: =IF(BASE!$B$19=1,BASE!$H$19/1000,"") | D8: =IF(BASE!$B$19=1,B8-B7,"") | E8: =IF(BASE!$B$19=1,C8-C7,"") | F8: =IF(BASE!$B$19=1,SUM(B8:C8),"") | G8: =IF(BASE!$B$19=1,IFERROR(F8/F7-1,0),"")
A9: =BASE!$A$20 | B9: =IF(BASE!$B$20=1,BASE!$G$20/1000,"") | C9: =IF(BASE!$B$20=1,BASE!$H$20/1000,"") | D9: =IF(BASE!$B$20=1,B9-B8,"") | E9: =IF(BASE!$B$20=1,C9-C8,"") | F9: =IF(BASE!$B$20=1,SUM(B9:C9),"") | G9: =IF(BASE!$B$20=1,IFERROR(F9/F8-1,0),"")
A10: =BASE!$A$21 | B10: =IF(BASE!$B$21=1,BASE!$G$21/1000,"") | C10: =IF(BASE!$B$21=1,BASE!$H$21/1000,"") | D10: =IF(BASE!$B$21=1,B10-B9,"") | E10: =IF(BASE!$B$21=1,C10-C9,"") | F10: =IF(BASE!$B$21=1,SUM(B10:C10),"") | G10: =IF(BASE!$B$21=1,IFERROR(F10/F9-1,0),"")
A11: =BASE!$A$22 | B11: =IF(BASE!$B$22=1,BASE!$G$22/1000,"") | C11: =IF(BASE!$B$22=1,BASE!$H$22/1000,"") | D11: =IF(BASE!$B$22=1,B11-B10,"") | E11: =IF(BASE!$B$22=1,C11-C10,"") | F11: =IF(BASE!$B$22=1,SUM(B11:C11),"") | G11: =IF(BASE!$B$22=1,IFERROR(F11/F10-1,0),"")
A12: =BASE!$A$23 | B12: =IF(BASE!$B$23=1,BASE!$G$23/1000,"") | C12: =IF(BASE!$B$23=1,BASE!$H$23/1000,"") | D12: =IF(BASE!$B$23=1,B12-B11,"") | E12: =IF(BASE!$B$23=1,C12-C11,"") | F12: =IF(BASE!$B$23=1,SUM(B12:C12),"") | G12: =IF(BASE!$B$23=1,IFERROR(F12/F11-1,0),"")
A13: =BASE!$A$24 | B13: =IF(BASE!$B$24=1,BASE!$G$24/1000,"") | C13: =IF(BASE!$B$24=1,BASE!$H$24/1000,"") | D13: =IF(BASE!$B$24=1,B13-B12,"") | E13: =IF(BASE!$B$24=1,C13-C12,"") | F13: =IF(BASE!$B$24=1,SUM(B13:C13),"") | G13: =IF(BASE!$B$24=1,IFERROR(F13/F12-1,0),"")
A14: =BASE!$A$25 | B14: =IF(BASE!$B$25=1,BASE!$G$25/1000,"") | C14: =IF(BASE!$B$25=1,BASE!$H$25/1000,"") | D14: =IF(BASE!$B$25=1,B14-B13,"") | E14: =IF(BASE!$B$25=1,C14-C13,"") | F14: =IF(BASE!$B$25=1,SUM(B14:C14),"") | G14: =IF(BASE!$B$25=1,IFERROR(F14/F13-1,0),"")
A15: =BASE!$A$26 | B15: =IF(BASE!$B$26=1,BASE!$G$26/1000,"") | C15: =IF(BASE!$B$26=1,BASE!$H$26/1000,"") | D15: =IF(BASE!$B$26=1,B15-B14,"") | E15: =IF(BASE!$B$26=1,C15-C14,"") | F15: =IF(BASE!$B$26=1,SUM(B15:C15),"") | G15: =IF(BASE!$B$26=1,IFERROR(F15/F14-1,0),"")
A16: =BASE!$A$27 | B16: =IF(BASE!$B$27=1,BASE!$G$27/1000,"") | C16: =IF(BASE!$B$27=1,BASE!$H$27/1000,"") | D16: =IF(BASE!$B$27=1,B16-B15,"") | E16: =IF(BASE!$B$27=1,C16-C15,"") | F16: =IF(BASE!$B$27=1,SUM(B16:C16),"") | G16: =IF(BASE!$B$27=1,IFERROR(F16/F15-1,0),"")
A17: =BASE!$A$28 | B17: =IF(BASE!$B$28=1,BASE!$G$28/1000,"") | C17: =IF(BASE!$B$28=1,BASE!$H$28/1000,"") | D17: =IF(BASE!$B$28=1,B17-B16,"") | E17: =IF(BASE!$B$28=1,C17-C16,"") | F17: =IF(BASE!$B$28=1,SUM(B17:C17),"") | G17: =IF(BASE!$B$28=1,IFERROR(F17/F16-1,0),"")
A18: =BASE!$A$29 | B18: =IF(BASE!$B$29=1,BASE!$G$29/1000,"") | C18: =IF(BASE!$B$29=1,BASE!$H$29/1000,"") | D18: =IF(BASE!$B$29=1,B18-B17,"") | E18: =IF(BASE!$B$29=1,C18-C17,"") | F18: =IF(BASE!$B$29=1,SUM(B18:C18),"") | G18: =IF(BASE!$B$29=1,IFERROR(F18/F17-1,0),"")
A19: =BASE!$A$30 | B19: =IF(BASE!$B$30=1,BASE!$G$30/1000,"") | C19: =IF(BASE!$B$30=1,BASE!$H$30/1000,"") | D19: =IF(BASE!$B$30=1,B19-B18,"") | E19: =IF(BASE!$B$30=1,C19-C18,"") | F19: =IF(BASE!$B$30=1,SUM(B19:C19),"") | G19: =IF(BASE!$B$30=1,IFERROR(F19/F18-1,0),"")
A20: =BASE!$A$31 | B20: =IF(BASE!$B$31=1,BASE!$G$31/1000,"") | C20: =IF(BASE!$B$31=1,BASE!$H$31/1000,"") | D20: =IF(BASE!$B$31=1,B20-B19,"") | E20: =IF(BASE!$B$31=1,C20-C19,"") | F20: =IF(BASE!$B$31=1,SUM(B20:C20),"") | G20: =IF(BASE!$B$31=1,IFERROR(F20/F19-1,0),"")
A21: =BASE!$A$32 | B21: =IF(BASE!$B$32=1,BASE!$G$32/1000,"") | C21: =IF(BASE!$B$32=1,BASE!$H$32/1000,"") | D21: =IF(BASE!$B$32=1,B21-B20,"") | E21: =IF(BASE!$B$32=1,C21-C20,"") | F21: =IF(BASE!$B$32=1,SUM(B21:C21),"") | G21: =IF(BASE!$B$32=1,IFERROR(F21/F20-1,0),"")
A22: =BASE!$A$33 | B22: =IF(BASE!$B$33=1,BASE!$G$33/1000,"") | C22: =IF(BASE!$B$33=1,BASE!$H$33/1000,"") | D22: =IF(BASE!$B$33=1,B22-B21,"") | E22: =IF(BASE!$B$33=1,C22-C21,"") | F22: =IF(BASE!$B$33=1,SUM(B22:C22),"") | G22: =IF(BASE!$B$33=1,IFERROR(F22/F21-1,0),"")
A23: =BASE!$A$34 | B23: =IF(BASE!$B$34=1,BASE!$G$34/1000,"") | C23: =IF(BASE!$B$34=1,BASE!$H$34/1000,"") | D23: =IF(BASE!$B$34=1,B23-B22,"") | E23: =IF(BASE!$B$34=1,C23-C22,"") | F23: =IF(BASE!$B$34=1,SUM(B23:C23),"") | G23: =IF(BASE!$B$34=1,IFERROR(F23/F22-1,0),"")
A24: =BASE!$A$35 | B24: =IF(BASE!$B$35=1,BASE!$G$35/1000,"") | C24: =IF(BASE!$B$35=1,BASE!$H$35/1000,"") | D24: =IF(BASE!$B$35=1,B24-B23,"") | E24: =IF(BASE!$B$35=1,C24-C23,"") | F24: =IF(BASE!$B$35=1,SUM(B24:C24),"") | G24: =IF(BASE!$B$35=1,IFERROR(F24/F23-1,0),"")
A25: =BASE!$A$36 | B25: =IF(BASE!$B$36=1,BASE!$G$36/1000,"") | C25: =IF(BASE!$B$36=1,BASE!$H$36/1000,"") | D25: =IF(BASE!$B$36=1,B25-B24,"") | E25: =IF(BASE!$B$36=1,C25-C24,"") | F25: =IF(BASE!$B$36=1,SUM(B25:C25),"") | G25: =IF(BASE!$B$36=1,IFERROR(F25/F24-1,0),"")
A26: =BASE!$A$37 | B26: =IF(BASE!$B$37=1,BASE!$G$37/1000,"") | C26: =IF(BASE!$B$37=1,BASE!$H$37/1000,"") | D26: =IF(BASE!$B$37=1,B26-B25,"") | E26: =IF(BASE!$B$37=1,C26-C25,"") | F26: =IF(BASE!$B$37=1,SUM(B26:C26),"") | G26: =IF(BASE!$B$37=1,IFERROR(F26/F25-1,0),"")
A27: =BASE!$A$38 | B27: =IF(BASE!$B$38=1,BASE!$G$38/1000,"") | C27: =IF(BASE!$B$38=1,BASE!$H$38/1000,"") | D27: =IF(BASE!$B$38=1,B27-B26,"") | E27: =IF(BASE!$B$38=1,C27-C26,"") | F27: =IF(BASE!$B$38=1,SUM(B27:C27),"") | G27: =IF(BASE!$B$38=1,IFERROR(F27/F26-1,0),"")

Sheet Aging CR
B2: Clientes | N2: =BASE!$A$27 | O2: =BASE!$A$28 | P2: =BASE!$A$29 | Q2: 1Q26 | R2: =BASE!$A$30 | S2: =BASE!$A$31 | T2: =BASE!$A$32 | U2: 2Q26 | V2: =BASE!$A$33 | W2: =BASE!$A$34 | X2: =BASE!$A$35 | Y2: 3Q26 | Z2: =BASE!$A$36 | AA2: =BASE!$A$37 | AB2: =BASE!$A$38 | AC2: 4Q26
B3: R$ | N3: Saldo | O3: Saldo | P3: Saldo | Q3: Saldo | R3: Saldo | S3: Saldo | T3: Saldo | U3: Saldo | V3: Saldo | W3: Saldo | X3: Saldo | Y3: Saldo | Z3: Saldo | AA3: Saldo | AB3: Saldo | AC3: Saldo
B4: A vencer | C4: =SUM(C5:C8) | D4: =SUM(D5:D8) | N4: =IF(BASE!$B$27=1,SUM(N5:N8),"") | O4: =IF(BASE!$B$28=1,SUM(O5:O8),"") | P4: =IF(BASE!$B$29=1,SUM(P5:P8),"") | Q4: =IFERROR(AVERAGE(N4:P4),"") | R4: =IF(BASE!$B$30=1,SUM(R5:R8),"") | S4: =IF(BASE!$B$31=1,SUM(S5:S8),"") | T4: =IF(BASE!$B$32=1,SUM(T5:T8),"") | U4: =IFERROR(AVERAGE(R4:T4),"") | V4: =IF(BASE!$B$33=1,SUM(V5:V8),"") | W4: =IF(BASE!$B$34=1,SUM(W5:W8),"") | X4: =IF(BASE!$B$35=1,SUM(X5:X8),"") | Y4: =IFERROR(AVERAGE(V4:X4),"") | Z4: =IF(BASE!$B$36=1,SUM(Z5:Z8),"") | AA4: =IF(BASE!$B$37=1,SUM(AA5:AA8),"") | AB4: =IF(BASE!$B$38=1,SUM(AB5:AB8),"") | AC4: =IFERROR(AVERAGE(Z4:AB4),"")
