Workbook

Sheet Resumo
E1: Workbook de Fechamento
E2: ="Fechamento de "&Dados!$AI$8
E3: Data-base | F3: =Dados!$AI$9 | G3: Gerado em | H3: =Dados!$AI$10 | I3: Valores em R$
B5: FATURAMENTO DO MÊS | D5: FATURAMENTO NO ANO | F5: RESULTADO DE CAIXA DO MÊS | H5: RESULTADO DE CAIXA NO ANO
B6: =VLOOKUP(Dados!$AI$5,Dados!$A$5:$AF$41,6,FALSE) | D6: =SUM(Dados!$F$30:$F$41) | F6: =VLOOKUP(Dados!$AI$5,Dados!$A$5:$AF$41,4,FALSE)-VLOOKUP(Dados!$AI$5,Dados!$A$5:$AF$41,5,FALSE) | H6: =SUM(Dados!$D$30:$D$41)-SUM(Dados!$E$30:$E$41)
B7: vs mês anterior | C7: =IFERROR(VLOOKUP(Dados!$AI$5,Dados!$A$5:$AF$41,6,FALSE)/VLOOKUP(EOMONTH(Dados!$AI$5,-2)+1,Dados!$A$5:$AF$41,6,FALSE)-1,"") | D7: do limite do ano | E7: =IFERROR(SUM(Dados!$F$30:$F$41)/Dados!$AI$15,"") | F7: recebido | G7: =VLOOKUP(Dados!$AI$5,Dados!$A$5:$AF$41,4,FALSE) | H7: mesmo período ano ant. | I7: =SUMIFS(Dados!$D$18:$D$29,Dados!$A$18:$A$29,"<="&EOMONTH(Dados!$AI$5,-12))-SUMIFS(Dados!$E$18:$E$29,Dados!$A$18:$A$29,"<="&EOMONTH(Dados!$AI$5,-12))
B8: notas de saída | C8: =Dados!$AI$18 | D8: vs mesmo período | E8: =IFERROR(SUM(Dados!$F$30:$F$41)/SUMIFS(Dados!$F$18:$F$29,Dados!$A$18:$A$29,"<="&EOMONTH(Dados!$AI$5,-12))-1,"") | F8: pago | G8: =VLOOKUP(Dados!$AI$5,Dados!$A$5:$AF$41,5,FALSE) | H8: margem de caixa | I8: =IFERROR((SUM(Dados!$D$30:$D$41)-SUM(Dados!$E$30:$E$41))/SUM(Dados!$D$30:$D$41),"")
B11: CAIXA NO FIM DO MÊS | D11: A RECEBER | F11: A PAGAR | H11: ESTOQUE
B12: =VLOOKUP(Dados!$AI$5,Dados!$A$5:$AF$41,7,FALSE) | D12: =VLOOKUP(Dados!$AI$5,Dados!$A$5:$AF$41,13,FALSE)+VLOOKUP(Dados!$AI$5,Dados!$A$5:$AF$41,14,FALSE)+VLOOKUP(Dados!$AI$5,Dados!$A$5:$AF$41,15,FALSE)+VLOOKUP(Dados!$AI$5,Dados!$A$5:$AF$41,16,FALSE)+VLOOKUP(Dados!$AI$5,Dados!$A$5:$AF$41,17,FALSE) | F12: =VLOOKUP(Dados!$AI$5,Dados!$A$5:$AF$41,18,FALSE)+VLOOKUP(Dados!$AI$5,Dados!$A$5:$AF$41,19,FALSE)+VLOOKUP(Dados!$AI$5,Dados!$A$5:$AF$41,20,FALSE)+VLOOKUP(Dados!$AI$5,Dados!$A$5:$AF$41,21,FALSE)+VLOOKUP(Dados!$AI$5,Dados!$A$5:$AF$41,22,FALSE) | H12: =VLOOKUP(Dados!$AI$5,Dados!$A$5:$AF$41,11,FALSE)+VLOOKUP(Dados!$AI$5,Dados!$A$5:$AF$41,12,FALSE)
B13: disponível | C13: =VLOOKUP(Dados!$AI$5,Dados!$A$5:$AF$41,7,FALSE)-VLOOKUP(Dados!$AI$5,Dados!$A$5:$AF$41,10,FALSE) | D13: vencido | E13: =VLOOKUP(Dados!$AI$5,Dados!$A$5:$AF$41,16,FALSE)+VLOOKUP(Dados!$AI$5,Dados!$A$5:$AF$41,17,FALSE) | F13: vencido | G13: =VLOOKUP(Dados!$AI$5,Dados!$A$5:$AF$41,21,FALSE)+VLOOKUP(Dados!$AI$5,Dados!$A$5:$AF$41,22,FALSE) | H13: produtos | I13: =VLOOKUP(Dados!$AI$5,Dados!$A$5:$AF$41,11,FALSE)
B14: bloqueado em garantia | C14: =VLOOKUP(Dados!$AI$5,Dados!$A$5:$AF$41,10,FALSE) | D14: vence em até 30 dias | E14: =VLOOKUP(Dados!$AI$5,Dados!$A$5:$AF$41,13,FALSE) | F14: vence em até 30 dias | G14: =VLOOKUP(Dados!$AI$5,Dados!$A$5:$AF$41,18,FALSE) | H14: materiais | I14: =VLOOKUP(Dados!$AI$5,Dados!$A$5:$AF$41,12,FALSE)
B17: Conferências
B18: Conferência | F18: Situação | G18: Valor | H18: Compara com | I18: Diferença
B19: Faturamento por cliente = faturamento do mês | F19: =IF(ABS(I19)<1,"OK","Verificar") | G19: =SUMIFS(Dados!$F$47:$F$4000,Dados!$C$47:$C$4000,"Cliente",Dados!$A$47:$A$4000,Dados!$AI$5) | H19: =VLOOKUP(Dados!$AI$5,Dados!$A$5:$AF$41,6,FALSE) | I19: =ROUND(G19-H19,2)
B20: Faturamento por estado = faturamento do mês | F20: =IF(ABS(I20)<1,"OK","Verificar") | G20: =SUMIFS(Dados!$F$47:$F$4000,Dados!$C$47:$C$4000,"Estado",Dados!$A$47:$A$4000,Dados!$AI$5) | H20: =VLOOKUP(Dados!$AI$5,Dados!$A$5:$AF$41,6,FALSE) | I20: =ROUND(G20-H20,2)
B21: Despesas por categoria = pago no mês | F21: =IF(ABS(I21)<1,"OK","Verificar") | G21: =SUMIFS(Dados!$F$47:$F$4000,Dados!$C$47:$C$4000,"Despesa",Dados!$A$47:$A$4000,Dados!$AI$5) | H21: =VLOOKUP(Dados!$AI$5,Dados!$A$5:$AF$41,5,FALSE) | I21: =ROUND(G21-H21,2)
B22: Ajuste ao extrato: caixa informado − calculado pelo ERP | F22: =IF(I22=0,"OK","Ajustado") | G22: =VLOOKUP(Dados!$AI$5,Dados!$A$5:$AF$41,7,FALSE) | H22: =VLOOKUP(Dados!$AI$5,Dados!$A$5:$AF$41,8,FALSE) | I22: =ROUND(G22-H22,2)
B23: Ponte do caixa: inicial + recebido − pago ± ajuste = final | F23: =IF(ABS(I23)<1,"OK","Verificar") | G23: =VLOOKUP(EOMONTH(Dados!$AI$5,-2)+1,Dados!$A$5:$AF$41,7,FALSE)+VLOOKUP(Dados!$AI$5,Dados!$A$5:$AF$41,4,FALSE)-VLOOKUP(Dados!$AI$5,Dados!$A$5:$AF$41,5,FALSE)+VLOOKUP(Dados!$AI$5,Dados!$A$5:$AF$41,9,FALSE) | H23: =VLOOKUP(Dados!$AI$5,Dados!$A$5:$AF$41,7,FALSE) | I23: =ROUND(G23-H23,2)
B24: Extrato do mês conciliado (linhas pendentes) | F24: =IF(G24=0,"OK","Verificar") | G24: =Dados!$AI$16
B25: Seguidores informados no mês (LinkedIn · Instagram) | F25: =IF(AND(ISNUMBER(G25),ISNUMBER(H25)),"OK","Verificar") | G25: =IF(ISNUMBER(VLOOKUP(Dados!$AI$5,Dados!$A$5:$AF$41,23,FALSE)),VLOOKUP(Dados!$AI$5,Dados!$A$5:$AF$41,23,FALSE),"sem dado") | H25: =IF(ISNUMBER(VLOOKUP(Dados!$AI$5,Dados!$A$5:$AF$41,24,FALSE)),VLOOKUP(Dados!$AI$5,Dados!$A$5:$AF$41,24,FALSE),"sem dado")
B27: Abas
B28: Resultado | C28: Recebido, pago e resultado de caixa, por mês, trimestre e ano, contra o ano anterior
B29: Faturamento | C29: Notas de saída em três anos, acumulado contra a meta e o limite do ano
B30: Caixa | C30: Ponte do caixa mês a mês (com rendimentos), bloqueado, disponível e meses de despesa cobertos
B31: Despesas | C31: Pagamentos por categoria e os maiores fornecedores do mês
B32: Clientes | C32: Faturamento por grupo econômico, participação, curva ABC e 1ª compra
B33: Estados | C33: Faturamento por estado e trimestre, contra o mesmo período do ano anterior
B34: Capital de giro | C34: A receber e a pagar por faixa de vencimento, nos últimos 12 meses
B35: Estoque | C35: Produtos e materiais em 24 meses e cobertura em meses de faturamento
B36: Sócios | C36: Retiradas do ano e resultado atribuído pela participação
B37: Redes | C37: Seguidores no LinkedIn e no Instagram, mês a mês
B38: Dados | C38: Base de todas as abas: um mês por linha e o detalhe do mês (com centavos)
B40: Valores em R$ sem centavos; negativos em vermelho e entre parênteses; "–" é zero. Os centavos estão na aba Dados.
B41: Regime de caixa: recebimentos e pagamentos do mês, sem transferências entre contas. Faturamento: notas de saída emitidas.

Sheet Resultado
B1: ="Resultado de caixa · "&Dados!$AI$7
B2: Regime de caixa: o que entrou e saiu das contas no mês, sem transferências entre contas · R$
B4: R$ | C4: jan | D4: fev | E4: mar | F4: abr | G4: mai | H4: jun | I4: jul | J4: ago | K4: set | L4: out | M4: nov | N4: dez | O4: 1º tri | P4: 2º tri | Q4: 3º tri | R4: 4º tri | S4: =Dados!$AI$7
B5: Recebido | C5: =IF(Dados!$C$30=1,Dados!$D$30,"") | D5: =IF(Dados!$C$31=1,Dados!$D$31,"") | E5: =IF(Dados!$C$32=1,Dados!$D$32,"") | F5: =IF(Dados!$C$33=1,Dados!$D$33,"") | G5: =IF(Dados!$C$34=1,Dados!$D$34,"") | H5: =IF(Dados!$C$35=1,Dados!$D$35,"") | I5: =IF(Dados!$C$36=1,Dados!$D$36,"") | J5: =IF(Dados!$C$37=1,Dados!$D$37,"") | K5: =IF(Dados!$C$38=1,Dados!$D$38,"") | L5: =IF(Dados!$C$39=1,Dados!$D$39,"") | M5: =IF(Dados!$C$40=1,Dados!$D$40,"") | N5: =IF(Dados!$C$41=1,Dados!$D$41,"") | O5: =SUM(C5:E5) | P5: =SUM(F5:H5) | Q5: =SUM(I5:K5) | R5: =SUM(L5:N5) | S5: =SUM(C5:N5)
B6: Pago | C6: =IF(Dados!$C$30=1,-Dados!$E$30,"") | D6: =IF(Dados!$C$31=1,-Dados!$E$31,"") | E6: =IF(Dados!$C$32=1,-Dados!$E$32,"") | F6: =IF(Dados!$C$33=1,-Dados!$E$33,"") | G6: =IF(Dados!$C$34=1,-Dados!$E$34,"") | H6: =IF(Dados!$C$35=1,-Dados!$E$35,"") | I6: =IF(Dados!$C$36=1,-Dados!$E$36,"") | J6: =IF(Dados!$C$37=1,-Dados!$E$37,"") | K6: =IF(Dados!$C$38=1,-Dados!$E$38,"") | L6: =IF(Dados!$C$39=1,-Dados!$E$39,"") | M6: =IF(Dados!$C$40=1,-Dados!$E$40,"") | N6: =IF(Dados!$C$41=1,-Dados!$E$41,"") | O6: =SUM(C6:E6) | P6: =SUM(F6:H6) | Q6: =SUM(I6:K6) | R6: =SUM(L6:N6) | S6: =SUM(C6:N6)
B7: Resultado de caixa | C7: =IF(C5="","",C5+C6) | D7: =IF(D5="","",D5+D6) | E7: =IF(E5="","",E5+E6) | F7: =IF(F5="","",F5+F6) | G7: =IF(G5="","",G5+G6) | H7: =IF(H5="","",H5+H6) | I7: =IF(I5="","",I5+I6) | J7: =IF(J5="","",J5+J6) | ... N7: =IF(N5="","",N5+N6) | O7: =SUM(C7:E7) | P7: =SUM(F7:H7) | Q7: =SUM(I7:K7) | R7: =SUM(L7:N7) | S7: =SUM(C7:N7)
B8: Resultado acumulado no ano | C8: =IF(C7="","",C7) | D8: =IF(D7="","",N(C8)+D7) | E8: =IF(E7="","",N(D8)+E7) | F8: =IF(F7="","",N(E8)+F7) | G8: =IF(G7="","",N(F8)+G7) | H8: =IF(H7="","",N(G8)+H7) | I8: =IF(I7="","",N(H8)+I7) | J8: =IF(J7="","",N(I8)+J7) | K8: =IF(K7="","",N(J8)+K7) | ... N8: =IF(N7="","",N(M8)+N7)
B9: Margem de caixa | C9: =IF(C5="","",IFERROR(C7/C5,"")) | D9: =IF(D5="","",IFERROR(D7/D5,"")) | E9: =IF(E5="","",IFERROR(E7/E5,"")) | F9: =IF(F5="","",IFERROR(F7/F5,"")) | G9: =IF(G5="","",IFERROR(G7/G5,"")) | H9: =IF(H5="","",IFERROR(H7/H5,"")) | I9: =IF(I5="","",IFERROR(I7/I5,"")) | J9: =IF(J5="","",IFERROR(J7/J5,"")) | ... N9: =IF(N5="","",IFERROR(N7/N5,"")) | O9: =IFERROR(O7/O5,"") | P9: =IFERROR(P7/P5,"") | Q9: =IFERROR(Q7/Q5,"") | R9: =IFERROR(R7/R5,"") | S9: =IFERROR(S7/S5,"")
B11: ="Ano anterior · "&(Dados!$AI$7-1)
B12: Recebido | C12: =IF(Dados!$C$18=1,Dados!$D$18,"") | D12: =IF(Dados!$C$19=1,Dados!$D$19,"") | E12: =IF(Dados!$C$20=1,Dados!$D$20,"") | F12: =IF(Dados!$C$21=1,Dados!$D$21,"") | G12: =IF(Dados!$C$22=1,Dados!$D$22,"") | H12: =IF(Dados!$C$23=1,Dados!$D$23,"") | I12: =IF(Dados!$C$24=1,Dados!$D$24,"") | J12: =IF(Dados!$C$25=1,Dados!$D$25,"") | K12: =IF(Dados!$C$26=1,Dados!$D$26,"") | L12: =IF(Dados!$C$27=1,Dados!$D$27,"") | M12: =IF(Dados!$C$28=1,Dados!$D$28,"") | N12: =IF(Dados!$C$29=1,Dados!$D$29,"") | O12: =SUM(C12:E12) | P12: =SUM(F12:H12) | Q12: =SUM(I12:K12) | R12: =SUM(L12:N12) | S12: =SUM(C12:N12)
B13: Pago | C13: =IF(Dados!$C$18=1,-Dados!$E$18,"") | D13: =IF(Dados!$C$19=1,-Dados!$E$19,"") | E13: =IF(Dados!$C$20=1,-Dados!$E$20,"") | F13: =IF(Dados!$C$21=1,-Dados!$E$21,"") | G13: =IF(Dados!$C$22=1,-Dados!$E$22,"") | H13: =IF(Dados!$C$23=1,-Dados!$E$23,"") | I13: =IF(Dados!$C$24=1,-Dados!$E$24,"") | J13: =IF(Dados!$C$25=1,-Dados!$E$25,"") | K13: =IF(Dados!$C$26=1,-Dados!$E$26,"") | L13: =IF(Dados!$C$27=1,-Dados!$E$27,"") | M13: =IF(Dados!$C$28=1,-Dados!$E$28,"") | N13: =IF(Dados!$C$29=1,-Dados!$E$29,"") | O13: =SUM(C13:E13) | P13: =SUM(F13:H13) | Q13: =SUM(I13:K13) | R13: =SUM(L13:N13) | S13: =SUM(C13:N13)
B14: Resultado de caixa | C14: =IF(C12="","",C12+C13) | D14: =IF(D12="","",D12+D13) | E14: =IF(E12="","",E12+E13) | F14: =IF(F12="","",F12+F13) | G14: =IF(G12="","",G12+G13) | H14: =IF(H12="","",H12+H13) | I14: =IF(I12="","",I12+I13) | J14: =IF(J12="","",J12+J13) | ... N14: =IF(N12="","",N12+N13) | O14: =SUM(C14:E14) | P14: =SUM(F14:H14) | Q14: =SUM(I14:K14) | R14: =SUM(L14:N14) | S14: =SUM(C14:N14)
B15: Diferença do resultado vs ano anterior | C15: =IF(C7="","",C7-C14) | D15: =IF(D7="","",D7-D14) | E15: =IF(E7="","",E7-E14) | F15: =IF(F7="","",F7-F14) | G15: =IF(G7="","",G7-G14) | H15: =IF(H7="","",H7-H14) | I15: =IF(I7="","",I7-I14) | J15: =IF(J7="","",J7-J14) | ... N15: =IF(N7="","",N7-N14) | O15: =SUM(C15:E15) | P15: =SUM(F15:H15) | Q15: =SUM(I15:K15) | R15: =SUM(L15:N15) | S15: =SUM(C15:N15)
B16: Trimestres e ano somam só os meses fechados. Meses futuros ficam vazios.
B90: Auxiliar do gráfico (linha 8) | C90: =IF(ISNUMBER(C8),C8,NA()) | D90: =IF(ISNUMBER(D8),D8,NA()) | E90: =IF(ISNUMBER(E8),E8,NA()) | F90: =IF(ISNUMBER(F8),F8,NA()) | G90: =IF(ISNUMBER(G8),G8,NA()) | H90: =IF(ISNUMBER(H8),H8,NA()) | I90: =IF(ISNUMBER(I8),I8,NA()) | J90: =IF(ISNUMBER(J8),J8,NA()) | ... N90: =IF(ISNUMBER(N8),N8,NA())

Sheet Faturamento
B1: ="Faturamento · "&Dados!$AI$7
B2: Notas fiscais de saída emitidas no mês · coluna Ano: variação contra o mesmo período do ano anterior · R$
B4: R$ | C4: jan | D4: fev | E4: mar | F4: abr | G4: mai | H4: jun | I4: jul | J4: ago | K4: set | L4: out | M4: nov | N4: dez | O4: Ano
B5: =Dados!$AI$7-2 | C5: =IF(Dados!$C$6=1,Dados!$F$6,"") | D5: =IF(Dados!$C$7=1,Dados!$F$7,"") | E5: =IF(Dados!$C$8=1,Dados!$F$8,"") | F5: =IF(Dados!$C$9=1,Dados!$F$9,"") | G5: =IF(Dados!$C$10=1,Dados!$F$10,"") | H5: =IF(Dados!$C$11=1,Dados!$F$11,"") | I5: =IF(Dados!$C$12=1,Dados!$F$12,"") | J5: =IF(Dados!$C$13=1,Dados!$F$13,"") | K5: =IF(Dados!$C$14=1,Dados!$F$14,"") | L5: =IF(Dados!$C$15=1,Dados!$F$15,"") | M5: =IF(Dados!$C$16=1,Dados!$F$16,"") | N5: =IF(Dados!$C$17=1,Dados!$F$17,"") | O5: =SUM(C5:N5)
B6: =Dados!$AI$7-1 | C6: =IF(Dados!$C$18=1,Dados!$F$18,"") | D6: =IF(Dados!$C$19=1,Dados!$F$19,"") | E6: =IF(Dados!$C$20=1,Dados!$F$20,"") | F6: =IF(Dados!$C$21=1,Dados!$F$21,"") | G6: =IF(Dados!$C$22=1,Dados!$F$22,"") | H6: =IF(Dados!$C$23=1,Dados!$F$23,"") | I6: =IF(Dados!$C$24=1,Dados!$F$24,"") | J6: =IF(Dados!$C$25=1,Dados!$F$25,"") | K6: =IF(Dados!$C$26=1,Dados!$F$26,"") | L6: =IF(Dados!$C$27=1,Dados!$F$27,"") | M6: =IF(Dados!$C$28=1,Dados!$F$28,"") | N6: =IF(Dados!$C$29=1,Dados!$F$29,"") | O6: =SUM(C6:N6)
B7: =Dados!$AI$7 | C7: =IF(Dados!$C$30=1,Dados!$F$30,"") | D7: =IF(Dados!$C$31=1,Dados!$F$31,"") | E7: =IF(Dados!$C$32=1,Dados!$F$32,"") | F7: =IF(Dados!$C$33=1,Dados!$F$33,"") | G7: =IF(Dados!$C$34=1,Dados!$F$34,"") | H7: =IF(Dados!$C$35=1,Dados!$F$35,"") | I7: =IF(Dados!$C$36=1,Dados!$F$36,"") | J7: =IF(Dados!$C$37=1,Dados!$F$37,"") | K7: =IF(Dados!$C$38=1,Dados!$F$38,"") | L7: =IF(Dados!$C$39=1,Dados!$F$39,"") | M7: =IF(Dados!$C$40=1,Dados!$F$40,"") | N7: =IF(Dados!$C$41=1,Dados!$F$41,"") | O7: =SUM(C7:N7)
B8: Variação vs ano anterior | C8: =IF(C7="","",IFERROR(C7/C6-1,"")) | D8: =IF(D7="","",IFERROR(D7/D6-1,"")) | E8: =IF(E7="","",IFERROR(E7/E6-1,"")) | F8: =IF(F7="","",IFERROR(F7/F6-1,"")) | G8: =IF(G7="","",IFERROR(G7/G6-1,"")) | H8: =IF(H7="","",IFERROR(H7/H6-1,"")) | I8: =IF(I7="","",IFERROR(I7/I6-1,"")) | J8: =IF(J7="","",IFERROR(J7/J6-1,"")) | ... N8: =IF(N7="","",IFERROR(N7/N6-1,"")) | O8: =IFERROR(O7/SUMIFS(Dados!$F$18:$F$29,Dados!$A$18:$A$29,"<="&EOMONTH(Dados!$AI$5,-12))-1,"")
B10: Acumulado, meta e limite
B11: Acumulado no ano | C11: =IF(C7="","",C7) | D11: =IF(D7="","",N(C11)+D7) | E11: =IF(E7="","",N(D11)+E7) | F11: =IF(F7="","",N(E11)+F7) | G11: =IF(G7="","",N(F11)+G7) | H11: =IF(H7="","",N(G11)+H7) | I11: =IF(I7="","",N(H11)+I7) | J11: =IF(J7="","",N(I11)+J7) | K11: =IF(K7="","",N(J11)+K7) | ... N11: =IF(N7="","",N(M11)+N7) | O11: =N(O7)
B12: Acumulado do ano anterior | C12: =N(C6) | D12: =C12+N(D6) | E12: =D12+N(E6) | F12: =E12+N(F6) | G12: =F12+N(G6) | H12: =G12+N(H6) | I12: =H12+N(I6) | J12: =I12+N(J6) | K12: =J12+N(K6) | ... N12: =M12+N(N6) | O12: =O6
B13: Meta acumulada | C13: =C12*(1+Dados!$AI$11) | D13: =D12*(1+Dados!$AI$11) | E13: =E12*(1+Dados!$AI$11) | F13: =F12*(1+Dados!$AI$11) | G13: =G12*(1+Dados!$AI$11) | H13: =H12*(1+Dados!$AI$11) | I13: =I12*(1+Dados!$AI$11) | J13: =J12*(1+Dados!$AI$11) | ... O13: =O12*(1+Dados!$AI$11)
B14: Realizado / meta | C14: =IF(C11="","",IFERROR(C11/C13,"")) | D14: =IF(D11="","",IFERROR(D11/D13,"")) | E14: =IF(E11="","",IFERROR(E11/E13,"")) | F14: =IF(F11="","",IFERROR(F11/F13,"")) | G14: =IF(G11="","",IFERROR(G11/G13,"")) | H14: =IF(H11="","",IFERROR(H11/H13,"")) | I14: =IF(I11="","",IFERROR(I11/I13,"")) | J14: =IF(J11="","",IFERROR(J11/J13,"")) | ... N14: =IF(N11="","",IFERROR(N11/N13,"")) | O14: =IFERROR(O11/O13,"")
B15: Limite de faturamento do ano | C15: =Dados!$AI$15 | D15: =Dados!$AI$15 | E15: =Dados!$AI$15 | F15: =Dados!$AI$15 | G15: =Dados!$AI$15 | H15: =Dados!$AI$15 | I15: =Dados!$AI$15 | J15: =Dados!$AI$15 | ... O15: =Dados!$AI$15
B16: Uso do limite | C16: =IF(C11="","",IFERROR(C11/C15,"")) | D16: =IF(D11="","",IFERROR(D11/D15,"")) | E16: =IF(E11="","",IFERROR(E11/E15,"")) | F16: =IF(F11="","",IFERROR(F11/F15,"")) | G16: =IF(G11="","",IFERROR(G11/G15,"")) | H16: =IF(H11="","",IFERROR(H11/H15,"")) | I16: =IF(I11="","",IFERROR(I11/I15,"")) | J16: =IF(J11="","",IFERROR(J11/J15,"")) | ... N16: =IF(N11="","",IFERROR(N11/N15,"")) | O16: =IFERROR(O11/O15,"")
B17: Meta: faturamento do ano anterior acrescido da meta de crescimento (aba Dados, parâmetros). Limite: teto de faturamento do ano.
B90: Auxiliar do gráfico (linha 11) | C90: =IF(ISNUMBER(C11),C11,NA()) | D90: =IF(ISNUMBER(D11),D11,NA()) | E90: =IF(ISNUMBER(E11),E11,NA()) | F90: =IF(ISNUMBER(F11),F11,NA()) | G90: =IF(ISNUMBER(G11),G11,NA()) | H90: =IF(ISNUMBER(H11),H11,NA()) | I90: =IF(ISNUMBER(I11),I11,NA()) | J90: =IF(ISNUMBER(J11),J11,NA()) | ... N90: =IF(ISNUMBER(N11),N11,NA())

Sheet Caixa
B1: ="Caixa · "&Dados!$AI$7
B2: Do caixa inicial ao final; o ajuste ao extrato (informado − calculado pelo ERP) fica numa linha própria · R$
B4: R$ | C4: jan | D4: fev | E4: mar | F4: abr | G4: mai | H4: jun | I4: jul | J4: ago | K4: set | L4: out | M4: nov | N4: dez
B5: Caixa inicial | C5: =IF(Dados!$C$30=1,Dados!$G$29,"") | D5: =IF(Dados!$C$31=1,Dados!$G$30,"") | E5: =IF(Dados!$C$32=1,Dados!$G$31,"") | F5: =IF(Dados!$C$33=1,Dados!$G$32,"") | G5: =IF(Dados!$C$34=1,Dados!$G$33,"") | H5: =IF(Dados!$C$35=1,Dados!$G$34,"") | I5: =IF(Dados!$C$36=1,Dados!$G$35,"") | J5: =IF(Dados!$C$37=1,Dados!$G$36,"") | K5: =IF(Dados!$C$38=1,Dados!$G$37,"") | L5: =IF(Dados!$C$39=1,Dados!$G$38,"") | M5: =IF(Dados!$C$40=1,Dados!$G$39,"") | N5: =IF(Dados!$C$41=1,Dados!$G$40,"")
B6: + Recebimentos | C6: =IF(Dados!$C$30=1,Dados!$D$30-Dados!$AG$30,"") | D6: =IF(Dados!$C$31=1,Dados!$D$31-Dados!$AG$31,"") | E6: =IF(Dados!$C$32=1,Dados!$D$32-Dados!$AG$32,"") | F6: =IF(Dados!$C$33=1,Dados!$D$33-Dados!$AG$33,"") | G6: =IF(Dados!$C$34=1,Dados!$D$34-Dados!$AG$34,"") | H6: =IF(Dados!$C$35=1,Dados!$D$35-Dados!$AG$35,"") | I6: =IF(Dados!$C$36=1,Dados!$D$36-Dados!$AG$36,"") | J6: =IF(Dados!$C$37=1,Dados!$D$37-Dados!$AG$37,"") | K6: =IF(Dados!$C$38=1,Dados!$D$38-Dados!$AG$38,"") | L6: =IF(Dados!$C$39=1,Dados!$D$39-Dados!$AG$39,"") | M6: =IF(Dados!$C$40=1,Dados!$D$40-Dados!$AG$40,"") | N6: =IF(Dados!$C$41=1,Dados!$D$41-Dados!$AG$41,"")
B7: + Rendimentos de aplicações | C7: =IF(Dados!$C$30=1,Dados!$AG$30,"") | D7: =IF(Dados!$C$31=1,Dados!$AG$31,"") | E7: =IF(Dados!$C$32=1,Dados!$AG$32,"") | F7: =IF(Dados!$C$33=1,Dados!$AG$33,"") | G7: =IF(Dados!$C$34=1,Dados!$AG$34,"") | H7: =IF(Dados!$C$35=1,Dados!$AG$35,"") | I7: =IF(Dados!$C$36=1,Dados!$AG$36,"") | J7: =IF(Dados!$C$37=1,Dados!$AG$37,"") | K7: =IF(Dados!$C$38=1,Dados!$AG$38,"") | L7: =IF(Dados!$C$39=1,Dados!$AG$39,"") | M7: =IF(Dados!$C$40=1,Dados!$AG$40,"") | N7: =IF(Dados!$C$41=1,Dados!$AG$41,"")
B8: − Pago | C8: =IF(Dados!$C$30=1,-Dados!$E$30,"") | D8: =IF(Dados!$C$31=1,-Dados!$E$31,"") | E8: =IF(Dados!$C$32=1,-Dados!$E$32,"") | F8: =IF(Dados!$C$33=1,-Dados!$E$33,"") | G8: =IF(Dados!$C$34=1,-Dados!$E$34,"") | H8: =IF(Dados!$C$35=1,-Dados!$E$35,"") | I8: =IF(Dados!$C$36=1,-Dados!$E$36,"") | J8: =IF(Dados!$C$37=1,-Dados!$E$37,"") | K8: =IF(Dados!$C$38=1,-Dados!$E$38,"") | L8: =IF(Dados!$C$39=1,-Dados!$E$39,"") | M8: =IF(Dados!$C$40=1,-Dados!$E$40,"") | N8: =IF(Dados!$C$41=1,-Dados!$E$41,"")
B9: ± Ajuste ao extrato | C9: =IF(Dados!$C$30=1,Dados!$I$30,"") | D9: =IF(Dados!$C$31=1,Dados!$I$31,"") | E9: =IF(Dados!$C$32=1,Dados!$I$32,"") | F9: =IF(Dados!$C$33=1,Dados!$I$33,"") | G9: =IF(Dados!$C$34=1,Dados!$I$34,"") | H9: =IF(Dados!$C$35=1,Dados!$I$35,"") | I9: =IF(Dados!$C$36=1,Dados!$I$36,"") | J9: =IF(Dados!$C$37=1,Dados!$I$37,"") | K9: =IF(Dados!$C$38=1,Dados!$I$38,"") | L9: =IF(Dados!$C$39=1,Dados!$I$39,"") | M9: =IF(Dados!$C$40=1,Dados!$I$40,"") | N9: =IF(Dados!$C$41=1,Dados!$I$41,"")
B10: Caixa final | C10: =IF(Dados!$C$30=1,Dados!$G$30,"") | D10: =IF(Dados!$C$31=1,Dados!$G$31,"") | E10: =IF(Dados!$C$32=1,Dados!$G$32,"") | F10: =IF(Dados!$C$33=1,Dados!$G$33,"") | G10: =IF(Dados!$C$34=1,Dados!$G$34,"") | H10: =IF(Dados!$C$35=1,Dados!$G$35,"") | I10: =IF(Dados!$C$36=1,Dados!$G$36,"") | J10: =IF(Dados!$C$37=1,Dados!$G$37,"") | K10: =IF(Dados!$C$38=1,Dados!$G$38,"") | L10: =IF(Dados!$C$39=1,Dados!$G$39,"") | M10: =IF(Dados!$C$40=1,Dados!$G$40,"") | N10: =IF(Dados!$C$41=1,Dados!$G$41,"")
B11: bloqueado em garantia | C11: =IF(Dados!$C$30=1,Dados!$J$30,"") | D11: =IF(Dados!$C$31=1,Dados!$J$31,"") | E11: =IF(Dados!$C$32=1,Dados!$J$32,"") | F11: =IF(Dados!$C$33=1,Dados!$J$33,"") | G11: =IF(Dados!$C$34=1,Dados!$J$34,"") | H11: =IF(Dados!$C$35=1,Dados!$J$35,"") | I11: =IF(Dados!$C$36=1,Dados!$J$36,"") | J11: =IF(Dados!$C$37=1,Dados!$J$37,"") | K11: =IF(Dados!$C$38=1,Dados!$J$38,"") | L11: =IF(Dados!$C$39=1,Dados!$J$39,"") | M11: =IF(Dados!$C$40=1,Dados!$J$40,"") | N11: =IF(Dados!$C$41=1,Dados!$J$41,"")
B12: disponível | C12: =IF(Dados!$C$30=1,Dados!$G$30-Dados!$J$30,"") | D12: =IF(Dados!$C$31=1,Dados!$G$31-Dados!$J$31,"") | E12: =IF(Dados!$C$32=1,Dados!$G$32-Dados!$J$32,"") | F12: =IF(Dados!$C$33=1,Dados!$G$33-Dados!$J$33,"") | G12: =IF(Dados!$C$34=1,Dados!$G$34-Dados!$J$34,"") | H12: =IF(Dados!$C$35=1,Dados!$G$35-Dados!$J$35,"") | I12: =IF(Dados!$C$36=1,Dados!$G$36-Dados!$J$36,"") | J12: =IF(Dados!$C$37=1,Dados!$G$37-Dados!$J$37,"") | K12: =IF(Dados!$C$38=1,Dados!$G$38-Dados!$J$38,"") | L12: =IF(Dados!$C$39=1,Dados!$G$39-Dados!$J$39,"") | M12: =IF(Dados!$C$40=1,Dados!$G$40-Dados!$J$40,"") | N12: =IF(Dados!$C$41=1,Dados!$G$41-Dados!$J$41,"")
B13: Meses de despesa cobertos | C13: =IF(Dados!$C$30=1,IFERROR(C12/AVERAGE(Dados!$E$28:$E$30),""),"") | D13: =IF(Dados!$C$31=1,IFERROR(D12/AVERAGE(Dados!$E$29:$E$31),""),"") | E13: =IF(Dados!$C$32=1,IFERROR(E12/AVERAGE(Dados!$E$30:$E$32),""),"") | F13: =IF(Dados!$C$33=1,IFERROR(F12/AVERAGE(Dados!$E$31:$E$33),""),"") | G13: =IF(Dados!$C$34=1,IFERROR(G12/AVERAGE(Dados!$E$32:$E$34),""),"") | H13: =IF(Dados!$C$35=1,IFERROR(H12/AVERAGE(Dados!$E$33:$E$35),""),"") | I13: =IF(Dados!$C$36=1,IFERROR(I12/AVERAGE(Dados!$E$34:$E$36),""),"") | J13: =IF(Dados!$C$37=1,IFERROR(J12/AVERAGE(Dados!$E$35:$E$37),""),"") | K13: =IF(Dados!$C$38=1,IFERROR(K12/AVERAGE(Dados!$E$36:$E$38),""),"") | L13: =IF(Dados!$C$39=1,IFERROR(L12/AVERAGE(Dados!$E$37:$E$39),""),"") | M13: =IF(Dados!$C$40=1,IFERROR(M12/AVERAGE(Dados!$E$38:$E$40),""),"") | N13: =IF(Dados!$C$41=1,IFERROR(N12/AVERAGE(Dados!$E$39:$E$41),""),"")
B14: Caixa final do ano anterior | C14: =IF(Dados!$C$18=1,Dados!$G$18,"") | D14: =IF(Dados!$C$19=1,Dados!$G$19,"") | E14: =IF(Dados!$C$20=1,Dados!$G$20,"") | F14: =IF(Dados!$C$21=1,Dados!$G$21,"") | G14: =IF(Dados!$C$22=1,Dados!$G$22,"") | H14: =IF(Dados!$C$23=1,Dados!$G$23,"") | I14: =IF(Dados!$C$24=1,Dados!$G$24,"") | J14: =IF(Dados!$C$25=1,Dados!$G$25,"") | K14: =IF(Dados!$C$26=1,Dados!$G$26,"") | L14: =IF(Dados!$C$27=1,Dados!$G$27,"") | M14: =IF(Dados!$C$28=1,Dados!$G$28,"") | N14: =IF(Dados!$C$29=1,Dados!$G$29,"")
B15: Diferença na ponte (deve ser zero) | C15: =IF(C10="","",ROUND(C5+C6+C7+C8+C9-C10,2)) | D15: =IF(D10="","",ROUND(D5+D6+D7+D8+D9-D10,2)) | E15: =IF(E10="","",ROUND(E5+E6+E7+E8+E9-E10,2)) | F15: =IF(F10="","",ROUND(F5+F6+F7+F8+F9-F10,2)) | G15: =IF(G10="","",ROUND(G5+G6+G7+G8+G9-G10,2)) | H15: =IF(H10="","",ROUND(H5+H6+H7+H8+H9-H10,2)) | I15: =IF(I10="","",ROUND(I5+I6+I7+I8+I9-I10,2)) | J15: =IF(J10="","",ROUND(J5+J6+J7+J8+J9-J10,2)) | ... N15: =IF(N10="","",ROUND(N5+N6+N7+N8+N9-N10,2))
B16: Meses de despesa cobertos: caixa disponível ÷ média do pago nos últimos 3 meses. Rendimentos: CDB, reserva remunerada e CDI informados no fechamento.

Sheet Despesas
B1: ="Despesas por categoria · "&Dados!$AI$7
B2: Pagamentos do mês por categoria (mesma base do pago em Resultado) e os maiores fornecedores pagos no mês · R$
B4: Categoria | C4: jan | D4: fev | E4: mar | F4: abr | G4: mai | H4: jun | I4: jul | J4: ago | K4: set | L4: out | M4: nov | N4: dez | O4: Ano | P4: % do ano | Q4: ="Em "&(Dados!$AI$7-1)
B5: =IF(Dados!$AQ$5="","",Dados!$AQ$5) | C5: =IF($B5="","",IF(Dados!$C$30=1,SUMIFS(Dados!$F$47:$F$4000,Dados!$C$47:$C$4000,"Despesa",Dados!$D$47:$D$4000,$B5,Dados!$A$47:$A$4000,Dados!$A$30),"")) | D5: =IF($B5="","",IF(Dados!$C$31=1,SUMIFS(Dados!$F$47:$F$4000,Dados!$C$47:$C$4000,"Despesa",Dados!$D$47:$D$4000,$B5,Dados!$A$47:$A$4000,Dados!$A$31),"")) | E5: =IF($B5="","",IF(Dados!$C$32=1,SUMIFS(Dados!$F$47:$F$4000,Dados!$C$47:$C$4000,"Despesa",Dados!$D$47:$D$4000,$B5,Dados!$A$47:$A$4000,Dados!$A$32),"")) | F5: =IF($B5="","",IF(Dados!$C$33=1,SUMIFS(Dados!$F$47:$F$4000,Dados!$C$47:$C$4000,"Despesa",Dados!$D$47:$D$4000,$B5,Dados!$A$47:$A$4000,Dados!$A$33),"")) | G5: =IF($B5="","",IF(Dados!$C$34=1,SUMIFS(Dados!$F$47:$F$4000,Dados!$C$47:$C$4000,"Despesa",Dados!$D$47:$D$4000,$B5,Dados!$A$47:$A$4000,Dados!$A$34),"")) | H5: =IF($B5="","",IF(Dados!$C$35=1,SUMIFS(Dados!$F$47:$F$4000,Dados!$C$47:$C$4000,"Despesa",Dados!$D$47:$D$4000,$B5,Dados!$A$47:$A$4000,Dados!$A$35),"")) | I5: =IF($B5="","",IF(Dados!$C$36=1,SUMIFS(Dados!$F$47:$F$4000,Dados!$C$47:$C$4000,"Despesa",Dados!$D$47:$D$4000,$B5,Dados!$A$47:$A$4000,Dados!$A$36),"")) | J5: =IF($B5="","",IF(Dados!$C$37=1,SUMIFS(Dados!$F$47:$F$4000,Dados!$C$47:$C$4000,"Despesa",Dados!$D$47:$D$4000,$B5,Dados!$A$47:$A$4000,Dados!$A$37),"")) | K5: =IF($B5="","",IF(Dados!$C$38=1,SUMIFS(Dados!$F$47:$F$4000,Dados!$C$47:$C$4000,"Despesa",Dados!$D$47:$D$4000,$B5,Dados!$A$47:$A$4000,Dados!$A$38),"")) | L5: =IF($B5="","",IF(Dados!$C$39=1,SUMIFS(Dados!$F$47:$F$4000,Dados!$C$47:$C$4000,"Despesa",Dados!$D$47:$D$4000,$B5,Dados!$A$47:$A$4000,Dados!$A$39),"")) | M5: =IF($B5="","",IF(Dados!$C$40=1,SUMIFS(Dados!$F$47:$F$4000,Dados!$C$47:$C$4000,"Despesa",Dados!$D$47:$D$4000,$B5,Dados!$A$47:$A$4000,Dados!$A$40),"")) | N5: =IF($B5="","",IF(Dados!$C$41=1,SUMIFS(Dados!$F$47:$F$4000,Dados!$C$47:$C$4000,"Despesa",Dados!$D$47:$D$4000,$B5,Dados!$A$47:$A$4000,Dados!$A$41),"")) | O5: =IF($B5="","",SUM(C5:N5)) | P5: =IF($B5="","",IFERROR(O5/$O$30,"")) | Q5: =IF($B5="","",SUMIFS(Dados!$F$47:$F$4000,Dados!$C$47:$C$4000,"Despesa",Dados!$D$47:$D$4000,$B5,Dados!$A$47:$A$4000,">="&Dados!$A$18,Dados!$A$47:$A$4000,"<="&Dados!$A$29))
B6: =IF(Dados!$AQ$6="","",Dados!$AQ$6) | C6: =IF($B6="","",IF(Dados!$C$30=1,SUMIFS(Dados!$F$47:$F$4000,Dados!$C$47:$C$4000,"Despesa",Dados!$D$47:$D$4000,$B6,Dados!$A$47:$A$4000,Dados!$A$30),"")) | D6: =IF($B6="","",IF(Dados!$C$31=1,SUMIFS(Dados!$F$47:$F$4000,Dados!$C$47:$C$4000,"Despesa",Dados!$D$47:$D$4000,$B6,Dados!$A$47:$A$4000,Dados!$A$31),"")) | E6: =IF($B6="","",IF(Dados!$C$32=1,SUMIFS(Dados!$F$47:$F$4000,Dados!$C$47:$C$4000,"Despesa",Dados!$D$47:$D$4000,$B6,Dados!$A$47:$A$4000,Dados!$A$32),"")) | F6: =IF($B6="","",IF(Dados!$C$33=1,SUMIFS(Dados!$F$47:$F$4000,Dados!$C$47:$C$4000,"Despesa",Dados!$D$47:$D$4000,$B6,Dados!$A$47:$A$4000,Dados!$A$33),"")) | G6: =IF($B6="","",IF(Dados!$C$34=1,SUMIFS(Dados!$F$47:$F$4000,Dados!$C$47:$C$4000,"Despesa",Dados!$D$47:$D$4000,$B6,Dados!$A$47:$A$4000,Dados!$A$34),"")) | H6: =IF($B6="","",IF(Dados!$C$35=1,SUMIFS(Dados!$F$47:$F$4000,Dados!$C$47:$C$4000,"Despesa",Dados!$D$47:$D$4000,$B6,Dados!$A$47:$A$4000,Dados!$A$35),"")) | I6: =IF($B6="","",IF(Dados!$C$36=1,SUMIFS(Dados!$F$47:$F$4000,Dados!$C$47:$C$4000,"Despesa",Dados!$D$47:$D$4000,$B6,Dados!$A$47:$A$4000,Dados!$A$36),"")) | J6: =IF($B6="","",IF(Dados!$C$37=1,SUMIFS(Dados!$F$47:$F$4000,Dados!$C$47:$C$4000,"Despesa",Dados!$D$47:$D$4000,$B6,Dados!$A$47:$A$4000,Dados!$A$37),"")) | K6: =IF($B6="","",IF(Dados!$C$38=1,SUMIFS(Dados!$F$47:$F$4000,Dados!$C$47:$C$4000,"Despesa",Dados!$D$47:$D$4000,$B6,Dados!$A$47:$A$4000,Dados!$A$38),"")) | L6: =IF($B6="","",IF(Dados!$C$39=1,SUMIFS(Dados!$F$47:$F$4000,Dados!$C$47:$C$4000,"Despesa",Dados!$D$47:$D$4000,$B6,Dados!$A$47:$A$4000,Dados!$A$39),"")) | M6: =IF($B6="","",IF(Dados!$C$40=1,SUMIFS(Dados!$F$47:$F$4000,Dados!$C$47:$C$4000,"Despesa",Dados!$D$47:$D$4000,$B6,Dados!$A$47:$A$4000,Dados!$A$40),"")) | N6: =IF($B6="","",IF(Dados!$C$41=1,SUMIFS(Dados!$F$47:$F$4000,Dados!$C$47:$C$4000,"Despesa",Dados!$D$47:$D$4000,$B6,Dados!$A$47:$A$4000,Dados!$A$41),"")) | O6: =IF($B6="","",SUM(C6:N6)) | P6: =IF($B6="","",IFERROR(O6/$O$30,"")) | Q6: =IF($B6="","",SUMIFS(Dados!$F$47:$F$4000,Dados!$C$47:$C$4000,"Despesa",Dados!$D$47:$D$4000,$B6,Dados!$A$47:$A$4000,">="&Dados!$A$18,Dados!$A$47:$A$4000,"<="&Dados!$A$29))
B7: =IF(Dados!$AQ$7="","",Dados!$AQ$7) | C7: =IF($B7="","",IF(Dados!$C$30=1,SUMIFS(Dados!$F$47:$F$4000,Dados!$C$47:$C$4000,"Despesa",Dados!$D$47:$D$4000,$B7,Dados!$A$47:$A$4000,Dados!$A$30),"")) | D7: =IF($B7="","",IF(Dados!$C$31=1,SUMIFS(Dados!$F$47:$F$4000,Dados!$C$47:$C$4000,"Despesa",Dados!$D$47:$D$4000,$B7,Dados!$A$47:$A$4000,Dados!$A$31),"")) | E7: =IF($B7="","",IF(Dados!$C$32=1,SUMIFS(Dados!$F$47:$F$4000,Dados!$C$47:$C$4000,"Despesa",Dados!$D$47:$D$4000,$B7,Dados!$A$47:$A$4000,Dados!$A$32),"")) | F7: =IF($B7="","",IF(Dados!$C$33=1,SUMIFS(Dados!$F$47:$F$4000,Dados!$C$47:$C$4000,"Despesa",Dados!$D$47:$D$4000,$B7,Dados!$A$47:$A$4000,Dados!$A$33),"")) | G7: =IF($B7="","",IF(Dados!$C$34=1,SUMIFS(Dados!$F$47:$F$4000,Dados!$C$47:$C$4000,"Despesa",Dados!$D$47:$D$4000,$B7,Dados!$A$47:$A$4000,Dados!$A$34),"")) | H7: =IF($B7="","",IF(Dados!$C$35=1,SUMIFS(Dados!$F$47:$F$4000,Dados!$C$47:$C$4000,"Despesa",Dados!$D$47:$D$4000,$B7,Dados!$A$47:$A$4000,Dados!$A$35),"")) | I7: =IF($B7="","",IF(Dados!$C$36=1,SUMIFS(Dados!$F$47:$F$4000,Dados!$C$47:$C$4000,"Despesa",Dados!$D$47:$D$4000,$B7,Dados!$A$47:$A$4000,Dados!$A$36),"")) | J7: =IF($B7="","",IF(Dados!$C$37=1,SUMIFS(Dados!$F$47:$F$4000,Dados!$C$47:$C$4000,"Despesa",Dados!$D$47:$D$4000,$B7,Dados!$A$47:$A$4000,Dados!$A$37),"")) | K7: =IF($B7="","",IF(Dados!$C$38=1,SUMIFS(Dados!$F$47:$F$4000,Dados!$C$47:$C$4000,"Despesa",Dados!$D$47:$D$4000,$B7,Dados!$A$47:$A$4000,Dados!$A$38),"")) | L7: =IF($B7="","",IF(Dados!$C$39=1,SUMIFS(Dados!$F$47:$F$4000,Dados!$C$47:$C$4000,"Despesa",Dados!$D$47:$D$4000,$B7,Dados!$A$47:$A$4000,Dados!$A$39),"")) | M7: =IF($B7="","",IF(Dados!$C$40=1,SUMIFS(Dados!$F$47:$F$4000,Dados!$C$47:$C$4000,"Despesa",Dados!$D$47:$D$4000,$B7,Dados!$A$47:$A$4000,Dados!$A$40),"")) | N7: =IF($B7="","",IF(Dados!$C$41=1,SUMIFS(Dados!$F$47:$F$4000,Dados!$C$47:$C$4000,"Despesa",Dados!$D$47:$D$4000,$B7,Dados!$A$47:$A$4000,Dados!$A$41),"")) | O7: =IF($B7="","",SUM(C7:N7)) | P7: =IF($B7="","",IFERROR(O7/$O$30,"")) | Q7: =IF($B7="","",SUMIFS(Dados!$F$47:$F$4000,Dados!$C$47:$C$4000,"Despesa",Dados!$D$47:$D$4000,$B7,Dados!$A$47:$A$4000,">="&Dados!$A$18,Dados!$A$47:$A$4000,"<="&Dados!$A$29))
B8: =IF(Dados!$AQ$8="","",Dados!$AQ$8) | C8: =IF($B8="","",IF(Dados!$C$30=1,SUMIFS(Dados!$F$47:$F$4000,Dados!$C$47:$C$4000,"Despesa",Dados!$D$47:$D$4000,$B8,Dados!$A$47:$A$4000,Dados!$A$30),"")) | D8: =IF($B8="","",IF(Dados!$C$31=1,SUMIFS(Dados!$F$47:$F$4000,Dados!$C$47:$C$4000,"Despesa",Dados!$D$47:$D$4000,$B8,Dados!$A$47:$A$4000,Dados!$A$31),"")) | E8: =IF($B8="","",IF(Dados!$C$32=1,SUMIFS(Dados!$F$47:$F$4000,Dados!$C$47:$C$4000,"Despesa",Dados!$D$47:$D$4000,$B8,Dados!$A$47:$A$4000,Dados!$A$32),"")) | F8: =IF($B8="","",IF(Dados!$C$33=1,SUMIFS(Dados!$F$47:$F$4000,Dados!$C$47:$C$4000,"Despesa",Dados!$D$47:$D$4000,$B8,Dados!$A$47:$A$4000,Dados!$A$33),"")) | G8: =IF($B8="","",IF(Dados!$C$34=1,SUMIFS(Dados!$F$47:$F$4000,Dados!$C$47:$C$4000,"Despesa",Dados!$D$47:$D$4000,$B8,Dados!$A$47:$A$4000,Dados!$A$34),"")) | H8: =IF($B8="","",IF(Dados!$C$35=1,SUMIFS(Dados!$F$47:$F$4000,Dados!$C$47:$C$4000,"Despesa",Dados!$D$47:$D$4000,$B8,Dados!$A$47:$A$4000,Dados!$A$35),"")) | I8: =IF($B8="","",IF(Dados!$C$36=1,SUMIFS(Dados!$F$47:$F$4000,Dados!$C$47:$C$4000,"Despesa",Dados!$D$47:$D$4000,$B8,Dados!$A$47:$A$4000,Dados!$A$36),"")) | J8: =IF($B8="","",IF(Dados!$C$37=1,SUMIFS(Dados!$F$47:$F$4000,Dados!$C$47:$C$4000,"Despesa",Dados!$D$47:$D$4000,$B8,Dados!$A$47:$A$4000,Dados!$A$37),"")) | K8: =IF($B8="","",IF(Dados!$C$38=1,SUMIFS(Dados!$F$47:$F$4000,Dados!$C$47:$C$4000,"Despesa",Dados!$D$47:$D$4000,$B8,Dados!$A$47:$A$4000,Dados!$A$38),"")) | L8: =IF($B8="","",IF(Dados!$C$39=1,SUMIFS(Dados!$F$47:$F$4000,Dados!$C$47:$C$4000,"Despesa",Dados!$D$47:$D$4000,$B8,Dados!$A$47:$A$4000,Dados!$A$39),"")) | M8: =IF($B8="","",IF(Dados!$C$40=1,SUMIFS(Dados!$F$47:$F$4000,Dados!$C$47:$C$4000,"Despesa",Dados!$D$47:$D$4000,$B8,Dados!$A$47:$A$4000,Dados!$A$40),"")) | N8: =IF($B8="","",IF(Dados!$C$41=1,SUMIFS(Dados!$F$47:$F$4000,Dados!$C$47:$C$4000,"Despesa",Dados!$D$47:$D$4000,$B8,Dados!$A$47:$A$4000,Dados!$A$41),"")) | O8: =IF($B8="","",SUM(C8:N8)) | P8: =IF($B8="","",IFERROR(O8/$O$30,"")) | Q8: =IF($B8="","",SUMIFS(Dados!$F$47:$F$4000,Dados!$C$47:$C$4000,"Despesa",Dados!$D$47:$D$4000,$B8,Dados!$A$47:$A$4000,">="&Dados!$A$18,Dados!$A$47:$A$4000,"<="&Dados!$A$29))
B9: =IF(Dados!$AQ$9="","",Dados!$AQ$9) | C9: =IF($B9="","",IF(Dados!$C$30=1,SUMIFS(Dados!$F$47:$F$4000,Dados!$C$47:$C$4000,"Despesa",Dados!$D$47:$D$4000,$B9,Dados!$A$47:$A$4000,Dados!$A$30),"")) | D9: =IF($B9="","",IF(Dados!$C$31=1,SUMIFS(Dados!$F$47:$F$4000,Dados!$C$47:$C$4000,"Despesa",Dados!$D$47:$D$4000,$B9,Dados!$A$47:$A$4000,Dados!$A$31),"")) | E9: =IF($B9="","",IF(Dados!$C$32=1,SUMIFS(Dados!$F$47:$F$4000,Dados!$C$47:$C$4000,"Despesa",Dados!$D$47:$D$4000,$B9,Dados!$A$47:$A$4000,Dados!$A$32),"")) | F9: =IF($B9="","",IF(Dados!$C$33=1,SUMIFS(Dados!$F$47:$F$4000,Dados!$C$47:$C$4000,"Despesa",Dados!$D$47:$D$4000,$B9,Dados!$A$47:$A$4000,Dados!$A$33),"")) | G9: =IF($B9="","",IF(Dados!$C$34=1,SUMIFS(Dados!$F$47:$F$4000,Dados!$C$47:$C$4000,"Despesa",Dados!$D$47:$D$4000,$B9,Dados!$A$47:$A$4000,Dados!$A$34),"")) | H9: =IF($B9="","",IF(Dados!$C$35=1,SUMIFS(Dados!$F$47:$F$4000,Dados!$C$47:$C$4000,"Despesa",Dados!$D$47:$D$4000,$B9,Dados!$A$47:$A$4000,Dados!$A$35),"")) | I9: =IF($B9="","",IF(Dados!$C$36=1,SUMIFS(Dados!$F$47:$F$4000,Dados!$C$47:$C$4000,"Despesa",Dados!$D$47:$D$4000,$B9,Dados!$A$47:$A$4000,Dados!$A$36),"")) | J9: =IF($B9="","",IF(Dados!$C$37=1,SUMIFS(Dados!$F$47:$F$4000,Dados!$C$47:$C$4000,"Despesa",Dados!$D$47:$D$4000,$B9,Dados!$A$47:$A$4000,Dados!$A$37),"")) | K9: =IF($B9="","",IF(Dados!$C$38=1,SUMIFS(Dados!$F$47:$F$4000,Dados!$C$47:$C$4000,"Despesa",Dados!$D$47:$D$4000,$B9,Dados!$A$47:$A$4000,Dados!$A$38),"")) | L9: =IF($B9="","",IF(Dados!$C$39=1,SUMIFS(Dados!$F$47:$F$4000,Dados!$C$47:$C$4000,"Despesa",Dados!$D$47:$D$4000,$B9,Dados!$A$47:$A$4000,Dados!$A$39),"")) | M9: =IF($B9="","",IF(Dados!$C$40=1,SUMIFS(Dados!$F$47:$F$4000,Dados!$C$47:$C$4000,"Despesa",Dados!$D$47:$D$4000,$B9,Dados!$A$47:$A$4000,Dados!$A$40),"")) | N9: =IF($B9="","",IF(Dados!$C$41=1,SUMIFS(Dados!$F$47:$F$4000,Dados!$C$47:$C$4000,"Despesa",Dados!$D$47:$D$4000,$B9,Dados!$A$47:$A$4000,Dados!$A$41),"")) | O9: =IF($B9="","",SUM(C9:N9)) | P9: =IF($B9="","",IFERROR(O9/$O$30,"")) | Q9: =IF($B9="","",SUMIFS(Dados!$F$47:$F$4000,Dados!$C$47:$C$4000,"Despesa",Dados!$D$47:$D$4000,$B9,Dados!$A$47:$A$4000,">="&Dados!$A$18,Dados!$A$47:$A$4000,"<="&Dados!$A$29))
B10: =IF(Dados!$AQ$10="","",Dados!$AQ$10) | C10: =IF($B10="","",IF(Dados!$C$30=1,SUMIFS(Dados!$F$47:$F$4000,Dados!$C$47:$C$4000,"Despesa",Dados!$D$47:$D$4000,$B10,Dados!$A$47:$A$4000,Dados!$A$30),"")) | D10: =IF($B10="","",IF(Dados!$C$31=1,SUMIFS(Dados!$F$47:$F$4000,Dados!$C$47:$C$4000,"Despesa",Dados!$D$47:$D$4000,$B10,Dados!$A$47:$A$4000,Dados!$A$31),"")) | E10: =IF($B10="","",IF(Dados!$C$32=1,SUMIFS(Dados!$F$47:$F$4000,Dados!$C$47:$C$4000,"Despesa",Dados!$D$47:$D$4000,$B10,Dados!$A$47:$A$4000,Dados!$A$32),"")) | F10: =IF($B10="","",IF(Dados!$C$33=1,SUMIFS(Dados!$F$47:$F$4000,Dados!$C$47:$C$4000,"Despesa",Dados!$D$47:$D$4000,$B10,Dados!$A$47:$A$4000,Dados!$A$33),"")) | G10: =IF($B10="","",IF(Dados!$C$34=1,SUMIFS(Dados!$F$47:$F$4000,Dados!$C$47:$C$4000,"Despesa",Dados!$D$47:$D$4000,$B10,Dados!$A$47:$A$4000,Dados!$A$34),"")) | H10: =IF($B10="","",IF(Dados!$C$35=1,SUMIFS(Dados!$F$47:$F$4000,Dados!$C$47:$C$4000,"Despesa",Dados!$D$47:$D$4000,$B10,Dados!$A$47:$A$4000,Dados!$A$35),"")) | I10: =IF($B10="","",IF(Dados!$C$36=1,SUMIFS(Dados!$F$47:$F$4000,Dados!$C$47:$C$4000,"Despesa",Dados!$D$47:$D$4000,$B10,Dados!$A$47:$A$4000,Dados!$A$36),"")) | J10: =IF($B10="","",IF(Dados!$C$37=1,SUMIFS(Dados!$F$47:$F$4000,Dados!$C$47:$C$4000,"Despesa",Dados!$D$47:$D$4000,$B10,Dados!$A$47:$A$4000,Dados!$A$37),"")) | K10: =IF($B10="","",IF(Dados!$C$38=1,SUMIFS(Dados!$F$47:$F$4000,Dados!$C$47:$C$4000,"Despesa",Dados!$D$47:$D$4000,$B10,Dados!$A$47:$A$4000,Dados!$A$38),"")) | L10: =IF($B10="","",IF(Dados!$C$39=1,SUMIFS(Dados!$F$47:$F$4000,Dados!$C$47:$C$4000,"Despesa",Dados!$D$47:$D$4000,$B10,Dados!$A$47:$A$4000,Dados!$A$39),"")) | M10: =IF($B10="","",IF(Dados!$C$40=1,SUMIFS(Dados!$F$47:$F$4000,Dados!$C$47:$C$4000,"Despesa",Dados!$D$47:$D$4000,$B10,Dados!$A$47:$A$4000,Dados!$A$40),"")) | N10: =IF($B10="","",IF(Dados!$C$41=1,SUMIFS(Dados!$F$47:$F$4000,Dados!$C$47:$C$4000,"Despesa",Dados!$D$47:$D$4000,$B10,Dados!$A$47:$A$4000,Dados!$A$41),"")) | O10: =IF($B10="","",SUM(C10:N10)) | P10: =IF($B10="","",IFERROR(O10/$O$30,"")) | Q10: =IF($B10="","",SUMIFS(Dados!$F$47:$F$4000,Dados!$C$47:$C$4000,"Despesa",Dados!$D$47:$D$4000,$B10,Dados!$A$47:$A$4000,">="&Dados!$A$18,Dados!$A$47:$A$4000,"<="&Dados!$A$29))
B11: =IF(Dados!$AQ$11="","",Dados!$AQ$11) | C11: =IF($B11="","",IF(Dados!$C$30=1,SUMIFS(Dados!$F$47:$F$4000,Dados!$C$47:$C$4000,"Despesa",Dados!$D$47:$D$4000,$B11,Dados!$A$47:$A$4000,Dados!$A$30),"")) | D11: =IF($B11="","",IF(Dados!$C$31=1,SUMIFS(Dados!$F$47:$F$4000,Dados!$C$47:$C$4000,"Despesa",Dados!$D$47:$D$4000,$B11,Dados!$A$47:$A$4000,Dados!$A$31),"")) | E11: =IF($B11="","",IF(Dados!$C$32=1,SUMIFS(Dados!$F$47:$F$4000,Dados!$C$47:$C$4000,"Despesa",Dados!$D$47:$D$4000,$B11,Dados!$A$47:$A$4000,Dados!$A$32),"")) | F11: =IF($B11="","",IF(Dados!$C$33=1,SUMIFS(Dados!$F$47:$F$4000,Dados!$C$47:$C$4000,"Despesa",Dados!$D$47:$D$4000,$B11,Dados!$A$47:$A$4000,Dados!$A$33),"")) | G11: =IF($B11="","",IF(Dados!$C$34=1,SUMIFS(Dados!$F$47:$F$4000,Dados!$C$47:$C$4000,"Despesa",Dados!$D$47:$D$4000,$B11,Dados!$A$47:$A$4000,Dados!$A$34),"")) | H11: =IF($B11="","",IF(Dados!$C$35=1,SUMIFS(Dados!$F$47:$F$4000,Dados!$C$47:$C$4000,"Despesa",Dados!$D$47:$D$4000,$B11,Dados!$A$47:$A$4000,Dados!$A$35),"")) | I11: =IF($B11="","",IF(Dados!$C$36=1,SUMIFS(Dados!$F$47:$F$4000,Dados!$C$47:$C$4000,"Despesa",Dados!$D$47:$D$4000,$B11,Dados!$A$47:$A$4000,Dados!$A$36),"")) | J11: =IF($B11="","",IF(Dados!$C$37=1,SUMIFS(Dados!$F$47:$F$4000,Dados!$C$47:$C$4000,"Despesa",Dados!$D$47:$D$4000,$B11,Dados!$A$47:$A$4000,Dados!$A$37),"")) | K11: =IF($B11="","",IF(Dados!$C$38=1,SUMIFS(Dados!$F$47:$F$4000,Dados!$C$47:$C$4000,"Despesa",Dados!$D$47:$D$4000,$B11,Dados!$A$47:$A$4000,Dados!$A$38),"")) | L11: =IF($B11="","",IF(Dados!$C$39=1,SUMIFS(Dados!$F$47:$F$4000,Dados!$C$47:$C$4000,"Despesa",Dados!$D$47:$D$4000,$B11,Dados!$A$47:$A$4000,Dados!$A$39),"")) | M11: =IF($B11="","",IF(Dados!$C$40=1,SUMIFS(Dados!$F$47:$F$4000,Dados!$C$47:$C$4000,"Despesa",Dados!$D$47:$D$4000,$B11,Dados!$A$47:$A$4000,Dados!$A$40),"")) | N11: =IF($B11="","",IF(Dados!$C$41=1,SUMIFS(Dados!$F$47:$F$4000,Dados!$C$47:$C$4000,"Despesa",Dados!$D$47:$D$4000,$B11,Dados!$A$47:$A$4000,Dados!$A$41),"")) | O11: =IF($B11="","",SUM(C11:N11)) | P11: =IF($B11="","",IFERROR(O11/$O$30,"")) | Q11: =IF($B11="","",SUMIFS(Dados!$F$47:$F$4000,Dados!$C$47:$C$4000,"Despesa",Dados!$D$47:$D$4000,$B11,Dados!$A$47:$A$4000,">="&Dados!$A$18,Dados!$A$47:$A$4000,"<="&Dados!$A$29))
B12: =IF(Dados!$AQ$12="","",Dados!$AQ$12) | C12: =IF($B12="","",IF(Dados!$C$30=1,SUMIFS(Dados!$F$47:$F$4000,Dados!$C$47:$C$4000,"Despesa",Dados!$D$47:$D$4000,$B12,Dados!$A$47:$A$4000,Dados!$A$30),"")) | D12: =IF($B12="","",IF(Dados!$C$31=1,SUMIFS(Dados!$F$47:$F$4000,Dados!$C$47:$C$4000,"Despesa",Dados!$D$47:$D$4000,$B12,Dados!$A$47:$A$4000,Dados!$A$31),"")) | E12: =IF($B12="","",IF(Dados!$C$32=1,SUMIFS(Dados!$F$47:$F$4000,Dados!$C$47:$C$4000,"Despesa",Dados!$D$47:$D$4000,$B12,Dados!$A$47:$A$4000,Dados!$A$32),"")) | F12: =IF($B12="","",IF(Dados!$C$33=1,SUMIFS(Dados!$F$47:$F$4000,Dados!$C$47:$C$4000,"Despesa",Dados!$D$47:$D$4000,$B12,Dados!$A$47:$A$4000,Dados!$A$33),"")) | G12: =IF($B12="","",IF(Dados!$C$34=1,SUMIFS(Dados!$F$47:$F$4000,Dados!$C$47:$C$4000,"Despesa",Dados!$D$47:$D$4000,$B12,Dados!$A$47:$A$4000,Dados!$A$34),"")) | H12: =IF($B12="","",IF(Dados!$C$35=1,SUMIFS(Dados!$F$47:$F$4000,Dados!$C$47:$C$4000,"Despesa",Dados!$D$47:$D$4000,$B12,Dados!$A$47:$A$4000,Dados!$A$35),"")) | I12: =IF($B12="","",IF(Dados!$C$36=1,SUMIFS(Dados!$F$47:$F$4000,Dados!$C$47:$C$4000,"Despesa",Dados!$D$47:$D$4000,$B12,Dados!$A$47:$A$4000,Dados!$A$36),"")) | J12: =IF($B12="","",IF(Dados!$C$37=1,SUMIFS(Dados!$F$47:$F$4000,Dados!$C$47:$C$4000,"Despesa",Dados!$D$47:$D$4000,$B12,Dados!$A$47:$A$4000,Dados!$A$37),"")) | K12: =IF($B12="","",IF(Dados!$C$38=1,SUMIFS(Dados!$F$47:$F$4000,Dados!$C$47:$C$4000,"Despesa",Dados!$D$47:$D$4000,$B12,Dados!$A$47:$A$4000,Dados!$A$38),"")) | L12: =IF($B12="","",IF(Dados!$C$39=1,SUMIFS(Dados!$F$47:$F$4000,Dados!$C$47:$C$4000,"Despesa",Dados!$D$47:$D$4000,$B12,Dados!$A$47:$A$4000,Dados!$A$39),"")) | M12: =IF($B12="","",IF(Dados!$C$40=1,SUMIFS(Dados!$F$47:$F$4000,Dados!$C$47:$C$4000,"Despesa",Dados!$D$47:$D$4000,$B12,Dados!$A$47:$A$4000,Dados!$A$40),"")) | N12: =IF($B12="","",IF(Dados!$C$41=1,SUMIFS(Dados!$F$47:$F$4000,Dados!$C$47:$C$4000,"Despesa",Dados!$D$47:$D$4000,$B12,Dados!$A$47:$A$4000,Dados!$A$41),"")) | O12: =IF($B12="","",SUM(C12:N12)) | P12: =IF($B12="","",IFERROR(O12/$O$30,"")) | Q12: =IF($B12="","",SUMIFS(Dados!$F$47:$F$4000,Dados!$C$47:$C$4000,"Despesa",Dados!$D$47:$D$4000,$B12,Dados!$A$47:$A$4000,">="&Dados!$A$18,Dados!$A$47:$A$4000,"<="&Dados!$A$29))
B13: =IF(Dados!$AQ$13="","",Dados!$AQ$13) | C13: =IF($B13="","",IF(Dados!$C$30=1,SUMIFS(Dados!$F$47:$F$4000,Dados!$C$47:$C$4000,"Despesa",Dados!$D$47:$D$4000,$B13,Dados!$A$47:$A$4000,Dados!$A$30),"")) | D13: =IF($B13="","",IF(Dados!$C$31=1,SUMIFS(Dados!$F$47:$F$4000,Dados!$C$47:$C$4000,"Despesa",Dados!$D$47:$D$4000,$B13,Dados!$A$47:$A$4000,Dados!$A$31),"")) | E13: =IF($B13="","",IF(Dados!$C$32=1,SUMIFS(Dados!$F$47:$F$4000,Dados!$C$47:$C$4000,"Despesa",Dados!$D$47:$D$4000,$B13,Dados!$A$47:$A$4000,Dados!$A$32),"")) | F13: =IF($B13="","",IF(Dados!$C$33=1,SUMIFS(Dados!$F$47:$F$4000,Dados!$C$47:$C$4000,"Despesa",Dados!$D$47:$D$4000,$B13,Dados!$A$47:$A$4000,Dados!$A$33),"")) | G13: =IF($B13="","",IF(Dados!$C$34=1,SUMIFS(Dados!$F$47:$F$4000,Dados!$C$47:$C$4000,"Despesa",Dados!$D$47:$D$4000,$B13,Dados!$A$47:$A$4000,Dados!$A$34),"")) | H13: =IF($B13="","",IF(Dados!$C$35=1,SUMIFS(Dados!$F$47:$F$4000,Dados!$C$47:$C$4000,"Despesa",Dados!$D$47:$D$4000,$B13,Dados!$A$47:$A$4000,Dados!$A$35),"")) | I13: =IF($B13="","",IF(Dados!$C$36=1,SUMIFS(Dados!$F$47:$F$4000,Dados!$C$47:$C$4000,"Despesa",Dados!$D$47:$D$4000,$B13,Dados!$A$47:$A$4000,Dados!$A$36),"")) | J13: =IF($B13="","",IF(Dados!$C$37=1,SUMIFS(Dados!$F$47:$F$4000,Dados!$C$47:$C$4000,"Despesa",Dados!$D$47:$D$4000,$B13,Dados!$A$47:$A$4000,Dados!$A$37),"")) | K13: =IF($B13="","",IF(Dados!$C$38=1,SUMIFS(Dados!$F$47:$F$4000,Dados!$C$47:$C$4000,"Despesa",Dados!$D$47:$D$4000,$B13,Dados!$A$47:$A$4000,Dados!$A$38),"")) | L13: =IF($B13="","",IF(Dados!$C$39=1,SUMIFS(Dados!$F$47:$F$4000,Dados!$C$47:$C$4000,"Despesa",Dados!$D$47:$D$4000,$B13,Dados!$A$47:$A$4000,Dados!$A$39),"")) | M13: =IF($B13="","",IF(Dados!$C$40=1,SUMIFS(Dados!$F$47:$F$4000,Dados!$C$47:$C$4000,"Despesa",Dados!$D$47:$D$4000,$B13,Dados!$A$47:$A$4000,Dados!$A$40),"")) | N13: =IF($B13="","",IF(Dados!$C$41=1,SUMIFS(Dados!$F$47:$F$4000,Dados!$C$47:$C$4000,"Despesa",Dados!$D$47:$D$4000,$B13,Dados!$A$47:$A$4000,Dados!$A$41),"")) | O13: =IF($B13="","",SUM(C13:N13)) | P13: =IF($B13="","",IFERROR(O13/$O$30,"")) | Q13: =IF($B13="","",SUMIFS(Dados!$F$47:$F$4000,Dados!$C$47:$C$4000,"Despesa",Dados!$D$47:$D$4000,$B13,Dados!$A$47:$A$4000,">="&Dados!$A$18,Dados!$A$47:$A$4000,"<="&Dados!$A$29))
B14: =IF(Dados!$AQ$14="","",Dados!$AQ$14) | C14: =IF($B14="","",IF(Dados!$C$30=1,SUMIFS(Dados!$F$47:$F$4000,Dados!$C$47:$C$4000,"Despesa",Dados!$D$47:$D$4000,$B14,Dados!$A$47:$A$4000,Dados!$A$30),"")) | D14: =IF($B14="","",IF(Dados!$C$31=1,SUMIFS(Dados!$F$47:$F$4000,Dados!$C$47:$C$4000,"Despesa",Dados!$D$47:$D$4000,$B14,Dados!$A$47:$A$4000,Dados!$A$31),"")) | E14: =IF($B14="","",IF(Dados!$C$32=1,SUMIFS(Dados!$F$47:$F$4000,Dados!$C$47:$C$4000,"Despesa",Dados!$D$47:$D$4000,$B14,Dados!$A$47:$A$4000,Dados!$A$32),"")) | F14: =IF($B14="","",IF(Dados!$C$33=1,SUMIFS(Dados!$F$47:$F$4000,Dados!$C$47:$C$4000,"Despesa",Dados!$D$47:$D$4000,$B14,Dados!$A$47:$A$4000,Dados!$A$33),"")) | G14: =IF($B14="","",IF(Dados!$C$34=1,SUMIFS(Dados!$F$47:$F$4000,Dados!$C$47:$C$4000,"Despesa",Dados!$D$47:$D$4000,$B14,Dados!$A$47:$A$4000,Dados!$A$34),"")) | H14: =IF($B14="","",IF(Dados!$C$35=1,SUMIFS(Dados!$F$47:$F$4000,Dados!$C$47:$C$4000,"Despesa",Dados!$D$47:$D$4000,$B14,Dados!$A$47:$A$4000,Dados!$A$35),"")) | I14: =IF($B14="","",IF(Dados!$C$36=1,SUMIFS(Dados!$F$47:$F$4000,Dados!$C$47:$C$4000,"Despesa",Dados!$D$47:$D$4000,$B14,Dados!$A$47:$A$4000,Dados!$A$36),"")) | J14: =IF($B14="","",IF(Dados!$C$37=1,SUMIFS(Dados!$F$47:$F$4000,Dados!$C$47:$C$4000,"Despesa",Dados!$D$47:$D$4000,$B14,Dados!$A$47:$A$4000,Dados!$A$37),"")) | K14: =IF($B14="","",IF(Dados!$C$38=1,SUMIFS(Dados!$F$47:$F$4000,Dados!$C$47:$C$4000,"Despesa",Dados!$D$47:$D$4000,$B14,Dados!$A$47:$A$4000,Dados!$A$38),"")) | L14: =IF($B14="","",IF(Dados!$C$39=1,SUMIFS(Dados!$F$47:$F$4000,Dados!$C$47:$C$4000,"Despesa",Dados!$D$47:$D$4000,$B14,Dados!$A$47:$A$4000,Dados!$A$39),"")) | M14: =IF($B14="","",IF(Dados!$C$40=1,SUMIFS(Dados!$F$47:$F$4000,Dados!$C$47:$C$4000,"Despesa",Dados!$D$47:$D$4000,$B14,Dados!$A$47:$A$4000,Dados!$A$40),"")) | N14: =IF($B14="","",IF(Dados!$C$41=1,SUMIFS(Dados!$F$47:$F$4000,Dados!$C$47:$C$4000,"Despesa",Dados!$D$47:$D$4000,$B14,Dados!$A$47:$A$4000,Dados!$A$41),"")) | O14: =IF($B14="","",SUM(C14:N14)) | P14: =IF($B14="","",IFERROR(O14/$O$30,"")) | Q14: =IF($B14="","",SUMIFS(Dados!$F$47:$F$4000,Dados!$C$47:$C$4000,"Despesa",Dados!$D$47:$D$4000,$B14,Dados!$A$47:$A$4000,">="&Dados!$A$18,Dados!$A$47:$A$4000,"<="&Dados!$A$29))
B15: =IF(Dados!$AQ$15="","",Dados!$AQ$15) | C15: =IF($B15="","",IF(Dados!$C$30=1,SUMIFS(Dados!$F$47:$F$4000,Dados!$C$47:$C$4000,"Despesa",Dados!$D$47:$D$4000,$B15,Dados!$A$47:$A$4000,Dados!$A$30),"")) | D15: =IF($B15="","",IF(Dados!$C$31=1,SUMIFS(Dados!$F$47:$F$4000,Dados!$C$47:$C$4000,"Despesa",Dados!$D$47:$D$4000,$B15,Dados!$A$47:$A$4000,Dados!$A$31),"")) | E15: =IF($B15="","",IF(Dados!$C$32=1,SUMIFS(Dados!$F$47:$F$4000,Dados!$C$47:$C$4000,"Despesa",Dados!$D$47:$D$4000,$B15,Dados!$A$47:$A$4000,Dados!$A$32),"")) | F15: =IF($B15="","",IF(Dados!$C$33=1,SUMIFS(Dados!$F$47:$F$4000,Dados!$C$47:$C$4000,"Despesa",Dados!$D$47:$D$4000,$B15,Dados!$A$47:$A$4000,Dados!$A$33),"")) | G15: =IF($B15="","",IF(Dados!$C$34=1,SUMIFS(Dados!$F$47:$F$4000,Dados!$C$47:$C$4000,"Despesa",Dados!$D$47:$D$4000,$B15,Dados!$A$47:$A$4000,Dados!$A$34),"")) | H15: =IF($B15="","",IF(Dados!$C$35=1,SUMIFS(Dados!$F$47:$F$4000,Dados!$C$47:$C$4000,"Despesa",Dados!$D$47:$D$4000,$B15,Dados!$A$47:$A$4000,Dados!$A$35),"")) | I15: =IF($B15="","",IF(Dados!$C$36=1,SUMIFS(Dados!$F$47:$F$4000,Dados!$C$47:$C$4000,"Despesa",Dados!$D$47:$D$4000,$B15,Dados!$A$47:$A$4000,Dados!$A$36),"")) | J15: =IF($B15="","",IF(Dados!$C$37=1,SUMIFS(Dados!$F$47:$F$4000,Dados!$C$47:$C$4000,"Despesa",Dados!$D$47:$D$4000,$B15,Dados!$A$47:$A$4000,Dados!$A$37),"")) | K15: =IF($B15="","",IF(Dados!$C$38=1,SUMIFS(Dados!$F$47:$F$4000,Dados!$C$47:$C$4000,"Despesa",Dados!$D$47:$D$4000,$B15,Dados!$A$47:$A$4000,Dados!$A$38),"")) | L15: =IF($B15="","",IF(Dados!$C$39=1,SUMIFS(Dados!$F$47:$F$4000,Dados!$C$47:$C$4000,"Despesa",Dados!$D$47:$D$4000,$B15,Dados!$A$47:$A$4000,Dados!$A$39),"")) | M15: =IF($B15="","",IF(Dados!$C$40=1,SUMIFS(Dados!$F$47:$F$4000,Dados!$C$47:$C$4000,"Despesa",Dados!$D$47:$D$4000,$B15,Dados!$A$47:$A$4000,Dados!$A$40),"")) | N15: =IF($B15="","",IF(Dados!$C$41=1,SUMIFS(Dados!$F$47:$F$4000,Dados!$C$47:$C$4000,"Despesa",Dados!$D$47:$D$4000,$B15,Dados!$A$47:$A$4000,Dados!$A$41),"")) | O15: =IF($B15="","",SUM(C15:N15)) | P15: =IF($B15="","",IFERROR(O15/$O$30,"")) | Q15: =IF($B15="","",SUMIFS(Dados!$F$47:$F$4000,Dados!$C$47:$C$4000,"Despesa",Dados!$D$47:$D$4000,$B15,Dados!$A$47:$A$4000,">="&Dados!$A$18,Dados!$A$47:$A$4000,"<="&Dados!$A$29))
B16: =IF(Dados!$AQ$16="","",Dados!$AQ$16) | C16: =IF($B16="","",IF(Dados!$C$30=1,SUMIFS(Dados!$F$47:$F$4000,Dados!$C$47:$C$4000,"Despesa",Dados!$D$47:$D$4000,$B16,Dados!$A$47:$A$4000,Dados!$A$30),"")) | D16: =IF($B16="","",IF(Dados!$C$31=1,SUMIFS(Dados!$F$47:$F$4000,Dados!$C$47:$C$4000,"Despesa",Dados!$D$47:$D$4000,$B16,Dados!$A$47:$A$4000,Dados!$A$31),"")) | E16: =IF($B16="","",IF(Dados!$C$32=1,SUMIFS(Dados!$F$47:$F$4000,Dados!$C$47:$C$4000,"Despesa",Dados!$D$47:$D$4000,$B16,Dados!$A$47:$A$4000,Dados!$A$32),"")) | F16: =IF($B16="","",IF(Dados!$C$33=1,SUMIFS(Dados!$F$47:$F$4000,Dados!$C$47:$C$4000,"Despesa",Dados!$D$47:$D$4000,$B16,Dados!$A$47:$A$4000,Dados!$A$33),"")) | G16: =IF($B16="","",IF(Dados!$C$34=1,SUMIFS(Dados!$F$47:$F$4000,Dados!$C$47:$C$4000,"Despesa",Dados!$D$47:$D$4000,$B16,Dados!$A$47:$A$4000,Dados!$A$34),"")) | H16: =IF($B16="","",IF(Dados!$C$35=1,SUMIFS(Dados!$F$47:$F$4000,Dados!$C$47:$C$4000,"Despesa",Dados!$D$47:$D$4000,$B16,Dados!$A$47:$A$4000,Dados!$A$35),"")) | I16: =IF($B16="","",IF(Dados!$C$36=1,SUMIFS(Dados!$F$47:$F$4000,Dados!$C$47:$C$4000,"Despesa",Dados!$D$47:$D$4000,$B16,Dados!$A$47:$A$4000,Dados!$A$36),"")) | J16: =IF($B16="","",IF(Dados!$C$37=1,SUMIFS(Dados!$F$47:$F$4000,Dados!$C$47:$C$4000,"Despesa",Dados!$D$47:$D$4000,$B16,Dados!$A$47:$A$4000,Dados!$A$37),"")) | K16: =IF($B16="","",IF(Dados!$C$38=1,SUMIFS(Dados!$F$47:$F$4000,Dados!$C$47:$C$4000,"Despesa",Dados!$D$47:$D$4000,$B16,Dados!$A$47:$A$4000,Dados!$A$38),"")) | L16: =IF($B16="","",IF(Dados!$C$39=1,SUMIFS(Dados!$F$47:$F$4000,Dados!$C$47:$C$4000,"Despesa",Dados!$D$47:$D$4000,$B16,Dados!$A$47:$A$4000,Dados!$A$39),"")) | M16: =IF($B16="","",IF(Dados!$C$40=1,SUMIFS(Dados!$F$47:$F$4000,Dados!$C$47:$C$4000,"Despesa",Dados!$D$47:$D$4000,$B16,Dados!$A$47:$A$4000,Dados!$A$40),"")) | N16: =IF($B16="","",IF(Dados!$C$41=1,SUMIFS(Dados!$F$47:$F$4000,Dados!$C$47:$C$4000,"Despesa",Dados!$D$47:$D$4000,$B16,Dados!$A$47:$A$4000,Dados!$A$41),"")) | O16: =IF($B16="","",SUM(C16:N16)) | P16: =IF($B16="","",IFERROR(O16/$O$30,"")) | Q16: =IF($B16="","",SUMIFS(Dados!$F$47:$F$4000,Dados!$C$47:$C$4000,"Despesa",Dados!$D$47:$D$4000,$B16,Dados!$A$47:$A$4000,">="&Dados!$A$18,Dados!$A$47:$A$4000,"<="&Dados!$A$29))
B17: =IF(Dados!$AQ$17="","",Dados!$AQ$17) | C17: =IF($B17="","",IF(Dados!$C$30=1,SUMIFS(Dados!$F$47:$F$4000,Dados!$C$47:$C$4000,"Despesa",Dados!$D$47:$D$4000,$B17,Dados!$A$47:$A$4000,Dados!$A$30),"")) | D17: =IF($B17="","",IF(Dados!$C$31=1,SUMIFS(Dados!$F$47:$F$4000,Dados!$C$47:$C$4000,"Despesa",Dados!$D$47:$D$4000,$B17,Dados!$A$47:$A$4000,Dados!$A$31),"")) | E17: =IF($B17="","",IF(Dados!$C$32=1,SUMIFS(Dados!$F$47:$F$4000,Dados!$C$47:$C$4000,"Despesa",Dados!$D$47:$D$4000,$B17,Dados!$A$47:$A$4000,Dados!$A$32),"")) | F17: =IF($B17="","",IF(Dados!$C$33=1,SUMIFS(Dados!$F$47:$F$4000,Dados!$C$47:$C$4000,"Despesa",Dados!$D$47:$D$4000,$B17,Dados!$A$47:$A$4000,Dados!$A$33),"")) | G17: =IF($B17="","",IF(Dados!$C$34=1,SUMIFS(Dados!$F$47:$F$4000,Dados!$C$47:$C$4000,"Despesa",Dados!$D$47:$D$4000,$B17,Dados!$A$47:$A$4000,Dados!$A$34),"")) | H17: =IF($B17="","",IF(Dados!$C$35=1,SUMIFS(Dados!$F$47:$F$4000,Dados!$C$47:$C$4000,"Despesa",Dados!$D$47:$D$4000,$B17,Dados!$A$47:$A$4000,Dados!$A$35),"")) | I17: =IF($B17="","",IF(Dados!$C$36=1,SUMIFS(Dados!$F$47:$F$4000,Dados!$C$47:$C$4000,"Despesa",Dados!$D$47:$D$4000,$B17,Dados!$A$47:$A$4000,Dados!$A$36),"")) | J17: =IF($B17="","",IF(Dados!$C$37=1,SUMIFS(Dados!$F$47:$F$4000,Dados!$C$47:$C$4000,"Despesa",Dados!$D$47:$D$4000,$B17,Dados!$A$47:$A$4000,Dados!$A$37),"")) | K17: =IF($B17="","",IF(Dados!$C$38=1,SUMIFS(Dados!$F$47:$F$4000,Dados!$C$47:$C$4000,"Despesa",Dados!$D$47:$D$4000,$B17,Dados!$A$47:$A$4000,Dados!$A$38),"")) | L17: =IF($B17="","",IF(Dados!$C$39=1,SUMIFS(Dados!$F$47:$F$4000,Dados!$C$47:$C$4000,"Despesa",Dados!$D$47:$D$4000,$B17,Dados!$A$47:$A$4000,Dados!$A$39),"")) | M17: =IF($B17="","",IF(Dados!$C$40=1,SUMIFS(Dados!$F$47:$F$4000,Dados!$C$47:$C$4000,"Despesa",Dados!$D$47:$D$4000,$B17,Dados!$A$47:$A$4000,Dados!$A$40),"")) | N17: =IF($B17="","",IF(Dados!$C$41=1,SUMIFS(Dados!$F$47:$F$4000,Dados!$C$47:$C$4000,"Despesa",Dados!$D$47:$D$4000,$B17,Dados!$A$47:$A$4000,Dados!$A$41),"")) | O17: =IF($B17="","",SUM(C17:N17)) | P17: =IF($B17="","",IFERROR(O17/$O$30,"")) | Q17: =IF($B17="","",SUMIFS(Dados!$F$47:$F$4000,Dados!$C$47:$C$4000,"Despesa",Dados!$D$47:$D$4000,$B17,Dados!$A$47:$A$4000,">="&Dados!$A$18,Dados!$A$47:$A$4000,"<="&Dados!$A$29))
B18: =IF(Dados!$AQ$18="","",Dados!$AQ$18) | C18: =IF($B18="","",IF(Dados!$C$30=1,SUMIFS(Dados!$F$47:$F$4000,Dados!$C$47:$C$4000,"Despesa",Dados!$D$47:$D$4000,$B18,Dados!$A$47:$A$4000,Dados!$A$30),"")) | D18: =IF($B18="","",IF(Dados!$C$31=1,SUMIFS(Dados!$F$47:$F$4000,Dados!$C$47:$C$4000,"Despesa",Dados!$D$47:$D$4000,$B18,Dados!$A$47:$A$4000,Dados!$A$31),"")) | E18: =IF($B18="","",IF(Dados!$C$32=1,SUMIFS(Dados!$F$47:$F$4000,Dados!$C$47:$C$4000,"Despesa",Dados!$D$47:$D$4000,$B18,Dados!$A$47:$A$4000,Dados!$A$32),"")) | F18: =IF($B18="","",IF(Dados!$C$33=1,SUMIFS(Dados!$F$47:$F$4000,Dados!$C$47:$C$4000,"Despesa",Dados!$D$47:$D$4000,$B18,Dados!$A$47:$A$4000,Dados!$A$33),"")) | G18: =IF($B18="","",IF(Dados!$C$34=1,SUMIFS(Dados!$F$47:$F$4000,Dados!$C$47:$C$4000,"Despesa",Dados!$D$47:$D$4000,$B18,Dados!$A$47:$A$4000,Dados!$A$34),"")) | H18: =IF($B18="","",IF(Dados!$C$35=1,SUMIFS(Dados!$F$47:$F$4000,Dados!$C$47:$C$4000,"Despesa",Dados!$D$47:$D$4000,$B18,Dados!$A$47:$A$4000,Dados!$A$35),"")) | I18: =IF($B18="","",IF(Dados!$C$36=1,SUMIFS(Dados!$F$47:$F$4000,Dados!$C$47:$C$4000,"Despesa",Dados!$D$47:$D$4000,$B18,Dados!$A$47:$A$4000,Dados!$A$36),"")) | J18: =IF($B18="","",IF(Dados!$C$37=1,SUMIFS(Dados!$F$47:$F$4000,Dados!$C$47:$C$4000,"Despesa",Dados!$D$47:$D$4000,$B18,Dados!$A$47:$A$4000,Dados!$A$37),"")) | K18: =IF($B18="","",IF(Dados!$C$38=1,SUMIFS(Dados!$F$47:$F$4000,Dados!$C$47:$C$4000,"Despesa",Dados!$D$47:$D$4000,$B18,Dados!$A$47:$A$4000,Dados!$A$38),"")) | L18: =IF($B18="","",IF(Dados!$C$39=1,SUMIFS(Dados!$F$47:$F$4000,Dados!$C$47:$C$4000,"Despesa",Dados!$D$47:$D$4000,$B18,Dados!$A$47:$A$4000,Dados!$A$39),"")) | M18: =IF($B18="","",IF(Dados!$C$40=1,SUMIFS(Dados!$F$47:$F$4000,Dados!$C$47:$C$4000,"Despesa",Dados!$D$47:$D$4000,$B18,Dados!$A$47:$A$4000,Dados!$A$40),"")) | N18: =IF($B18="","",IF(Dados!$C$41=1,SUMIFS(Dados!$F$47:$F$4000,Dados!$C$47:$C$4000,"Despesa",Dados!$D$47:$D$4000,$B18,Dados!$A$47:$A$4000,Dados!$A$41),"")) | O18: =IF($B18="","",SUM(C18:N18)) | P18: =IF($B18="","",IFERROR(O18/$O$30,"")) | Q18: =IF($B18="","",SUMIFS(Dados!$F$47:$F$4000,Dados!$C$47:$C$4000,"Despesa",Dados!$D$47:$D$4000,$B18,Dados!$A$47:$A$4000,">="&Dados!$A$18,Dados!$A$47:$A$4000,"<="&Dados!$A$29))
B19: =IF(Dados!$AQ$19="","",Dados!$AQ$19) | C19: =IF($B19="","",IF(Dados!$C$30=1,SUMIFS(Dados!$F$47:$F$4000,Dados!$C$47:$C$4000,"Despesa",Dados!$D$47:$D$4000,$B19,Dados!$A$47:$A$4000,Dados!$A$30),"")) | D19: =IF($B19="","",IF(Dados!$C$31=1,SUMIFS(Dados!$F$47:$F$4000,Dados!$C$47:$C$4000,"Despesa",Dados!$D$47:$D$4000,$B19,Dados!$A$47:$A$4000,Dados!$A$31),"")) | E19: =IF($B19="","",IF(Dados!$C$32=1,SUMIFS(Dados!$F$47:$F$4000,Dados!$C$47:$C$4000,"Despesa",Dados!$D$47:$D$4000,$B19,Dados!$A$47:$A$4000,Dados!$A$32),"")) | F19: =IF($B19="","",IF(Dados!$C$33=1,SUMIFS(Dados!$F$47:$F$4000,Dados!$C$47:$C$4000,"Despesa",Dados!$D$47:$D$4000,$B19,Dados!$A$47:$A$4000,Dados!$A$33),"")) | G19: =IF($B19="","",IF(Dados!$C$34=1,SUMIFS(Dados!$F$47:$F$4000,Dados!$C$47:$C$4000,"Despesa",Dados!$D$47:$D$4000,$B19,Dados!$A$47:$A$4000,Dados!$A$34),"")) | H19: =IF($B19="","",IF(Dados!$C$35=1,SUMIFS(Dados!$F$47:$F$4000,Dados!$C$47:$C$4000,"Despesa",Dados!$D$47:$D$4000,$B19,Dados!$A$47:$A$4000,Dados!$A$35),"")) | I19: =IF($B19="","",IF(Dados!$C$36=1,SUMIFS(Dados!$F$47:$F$4000,Dados!$C$47:$C$4000,"Despesa",Dados!$D$47:$D$4000,$B19,Dados!$A$47:$A$4000,Dados!$A$36),"")) | J19: =IF($B19="","",IF(Dados!$C$37=1,SUMIFS(Dados!$F$47:$F$4000,Dados!$C$47:$C$4000,"Despesa",Dados!$D$47:$D$4000,$B19,Dados!$A$47:$A$4000,Dados!$A$37),"")) | K19: =IF($B19="","",IF(Dados!$C$38=1,SUMIFS(Dados!$F$47:$F$4000,Dados!$C$47:$C$4000,"Despesa",Dados!$D$47:$D$4000,$B19,Dados!$A$47:$A$4000,Dados!$A$38),"")) | L19: =IF($B19="","",IF(Dados!$C$39=1,SUMIFS(Dados!$F$47:$F$4000,Dados!$C$47:$C$4000,"Despesa",Dados!$D$47:$D$4000,$B19,Dados!$A$47:$A$4000,Dados!$A$39),"")) | M19: =IF($B19="","",IF(Dados!$C$40=1,SUMIFS(Dados!$F$47:$F$4000,Dados!$C$47:$C$4000,"Despesa",Dados!$D$47:$D$4000,$B19,Dados!$A$47:$A$4000,Dados!$A$40),"")) | N19: =IF($B19="","",IF(Dados!$C$41=1,SUMIFS(Dados!$F$47:$F$4000,Dados!$C$47:$C$4000,"Despesa",Dados!$D$47:$D$4000,$B19,Dados!$A$47:$A$4000,Dados!$A$41),"")) | O19: =IF($B19="","",SUM(C19:N19)) | P19: =IF($B19="","",IFERROR(O19/$O$30,"")) | Q19: =IF($B19="","",SUMIFS(Dados!$F$47:$F$4000,Dados!$C$47:$C$4000,"Despesa",Dados!$D$47:$D$4000,$B19,Dados!$A$47:$A$4000,">="&Dados!$A$18,Dados!$A$47:$A$4000,"<="&Dados!$A$29))
B20: =IF(Dados!$AQ$20="","",Dados!$AQ$20) | C20: =IF($B20="","",IF(Dados!$C$30=1,SUMIFS(Dados!$F$47:$F$4000,Dados!$C$47:$C$4000,"Despesa",Dados!$D$47:$D$4000,$B20,Dados!$A$47:$A$4000,Dados!$A$30),"")) | D20: =IF($B20="","",IF(Dados!$C$31=1,SUMIFS(Dados!$F$47:$F$4000,Dados!$C$47:$C$4000,"Despesa",Dados!$D$47:$D$4000,$B20,Dados!$A$47:$A$4000,Dados!$A$31),"")) | E20: =IF($B20="","",IF(Dados!$C$32=1,SUMIFS(Dados!$F$47:$F$4000,Dados!$C$47:$C$4000,"Despesa",Dados!$D$47:$D$4000,$B20,Dados!$A$47:$A$4000,Dados!$A$32),"")) | F20: =IF($B20="","",IF(Dados!$C$33=1,SUMIFS(Dados!$F$47:$F$4000,Dados!$C$47:$C$4000,"Despesa",Dados!$D$47:$D$4000,$B20,Dados!$A$47:$A$4000,Dados!$A$33),"")) | G20: =IF($B20="","",IF(Dados!$C$34=1,SUMIFS(Dados!$F$47:$F$4000,Dados!$C$47:$C$4000,"Despesa",Dados!$D$47:$D$4000,$B20,Dados!$A$47:$A$4000,Dados!$A$34),"")) | H20: =IF($B20="","",IF(Dados!$C$35=1,SUMIFS(Dados!$F$47:$F$4000,Dados!$C$47:$C$4000,"Despesa",Dados!$D$47:$D$4000,$B20,Dados!$A$47:$A$4000,Dados!$A$35),"")) | I20: =IF($B20="","",IF(Dados!$C$36=1,SUMIFS(Dados!$F$47:$F$4000,Dados!$C$47:$C$4000,"Despesa",Dados!$D$47:$D$4000,$B20,Dados!$A$47:$A$4000,Dados!$A$36),"")) | J20: =IF($B20="","",IF(Dados!$C$37=1,SUMIFS(Dados!$F$47:$F$4000,Dados!$C$47:$C$4000,"Despesa",Dados!$D$47:$D$4000,$B20,Dados!$A$47:$A$4000,Dados!$A$37),"")) | K20: =IF($B20="","",IF(Dados!$C$38=1,SUMIFS(Dados!$F$47:$F$4000,Dados!$C$47:$C$4000,"Despesa",Dados!$D$47:$D$4000,$B20,Dados!$A$47:$A$4000,Dados!$A$38),"")) | L20: =IF($B20="","",IF(Dados!$C$39=1,SUMIFS(Dados!$F$47:$F$4000,Dados!$C$47:$C$4000,"Despesa",Dados!$D$47:$D$4000,$B20,Dados!$A$47:$A$4000,Dados!$A$39),"")) | M20: =IF($B20="","",IF(Dados!$C$40=1,SUMIFS(Dados!$F$47:$F$4000,Dados!$C$47:$C$4000,"Despesa",Dados!$D$47:$D$4000,$B20,Dados!$A$47:$A$4000,Dados!$A$40),"")) | N20: =IF($B20="","",IF(Dados!$C$41=1,SUMIFS(Dados!$F$47:$F$4000,Dados!$C$47:$C$4000,"Despesa",Dados!$D$47:$D$4000,$B20,Dados!$A$47:$A$4000,Dados!$A$41),"")) | O20: =IF($B20="","",SUM(C20:N20)) | P20: =IF($B20="","",IFERROR(O20/$O$30,"")) | Q20: =IF($B20="","",SUMIFS(Dados!$F$47:$F$4000,Dados!$C$47:$C$4000,"Despesa",Dados!$D$47:$D$4000,$B20,Dados!$A$47:$A$4000,">="&Dados!$A$18,Dados!$A$47:$A$4000,"<="&Dados!$A$29))
